Workbook
Name ProjectStage: 'Dropdowns'!$A$7:INDEX('Dropdowns'!$A$7:$A$106,COUNTA('Dropdowns'!$A$7:$A$106))
Name LeadStatus: 'Dropdowns'!$B$7:INDEX('Dropdowns'!$B$7:$B$106,COUNTA('Dropdowns'!$B$7:$B$106))
Name EndUserType: 'Dropdowns'!$C$7:INDEX('Dropdowns'!$C$7:$C$106,COUNTA('Dropdowns'!$C$7:$C$106))
Name DecisionInfluencer: 'Dropdowns'!$D$7:INDEX('Dropdowns'!$D$7:$D$106,COUNTA('Dropdowns'!$D$7:$D$106))
Name Market: 'Dropdowns'!$E$7:INDEX('Dropdowns'!$E$7:$E$106,COUNTA('Dropdowns'!$E$7:$E$106))
Name Segment: 'Dropdowns'!$F$7:INDEX('Dropdowns'!$F$7:$F$106,COUNTA('Dropdowns'!$F$7:$F$106))
Name Application: 'Dropdowns'!$G$7:INDEX('Dropdowns'!$G$7:$G$106,COUNTA('Dropdowns'!$G$7:$G$106))
Name DemandDriver: 'Dropdowns'!$H$7:INDEX('Dropdowns'!$H$7:$H$106,COUNTA('Dropdowns'!$H$7:$H$106))
Name OEMCategory: 'Dropdowns'!$I$7:INDEX('Dropdowns'!$I$7:$I$106,COUNTA('Dropdowns'!$I$7:$I$106))
Name SiteType: 'Dropdowns'!$J$7:INDEX('Dropdowns'!$J$7:$J$106,COUNTA('Dropdowns'!$J$7:$J$106))
Name PowerNeeds: 'Dropdowns'!$K$7:INDEX('Dropdowns'!$K$7:$K$106,COUNTA('Dropdowns'!$K$7:$K$106))
Name EnergySource: 'Dropdowns'!$L$7:INDEX('Dropdowns'!$L$7:$L$106,COUNTA('Dropdowns'!$L$7:$L$106))
Name AIFacility: 'Dropdowns'!$M$7:INDEX('Dropdowns'!$M$7:$M$106,COUNTA('Dropdowns'!$M$7:$M$106))
Name YesNo: 'Dropdowns'!$N$7:INDEX('Dropdowns'!$N$7:$N$106,COUNTA('Dropdowns'!$N$7:$N$106))
Name Occupation: 'Dropdowns'!$O$7:INDEX('Dropdowns'!$O$7:$O$106,COUNTA('Dropdowns'!$O$7:$O$106))
Name Industry: 'Dropdowns'!$P$7:INDEX('Dropdowns'!$P$7:$P$106,COUNTA('Dropdowns'!$P$7:$P$106))
Name LeadSource: 'Dropdowns'!$Q$7:INDEX('Dropdowns'!$Q$7:$Q$106,COUNTA('Dropdowns'!$Q$7:$Q$106))
Name Country: 'Dropdowns'!$R$7:INDEX('Dropdowns'!$R$7:$R$106,COUNTA('Dropdowns'!$R$7:$R$106))
Name Salutation: 'Dropdowns'!$S$7:INDEX('Dropdowns'!$S$7:$S$106,COUNTA('Dropdowns'!$S$7:$S$106))
Name WinLoss: 'Dropdowns'!$T$7:INDEX('Dropdowns'!$T$7:$T$106,COUNTA('Dropdowns'!$T$7:$T$106))
Name Solutions: 'Dropdowns'!$U$7:INDEX('Dropdowns'!$U$7:$U$106,COUNTA('Dropdowns'!$U$7:$U$106))
Name CanadaProvince: 'Dropdowns'!$V$7:INDEX('Dropdowns'!$V$7:$V$106,COUNTA('Dropdowns'!$V$7:$V$106))
Name CanadianRegion: 'Dropdowns'!$W$7:INDEX('Dropdowns'!$W$7:$W$106,COUNTA('Dropdowns'!$W$7:$W$106))
Name Products: 'Dropdowns'!$X$7:INDEX('Dropdowns'!$X$7:$X$106,COUNTA('Dropdowns'!$X$7:$X$106))
Name ProjectNames: 'Projects'!$A$7:$A$206

Sheet Projects
A1: Stephan Hardt | Power Generation
A2: Projects template
A3: One project per row. Select multiple products on Project Products.
A4: Amber cells = dropdowns. * = required in the recording. Blank rows are ready for entry. See Guide for source limits.
A5: Key Details | R5: Date + Location | Z5: Market + Application | AJ5: Sales Updates | AO5: Additional Project Details | AS5: Project Metadata
A6: Project Name * | B6: End User | C6: Stage | D6: Other Project Aliases | E6: End User Type | F6: End User Contact | G6: Site Owner | H6: Site Owner Contact | I6: Main Decision Influencer | J6: Solutions | K6: Construction Status | L6: Win/Loss Reason | M6: Amount ($) | N6: Project Pipeline Amount | O6: Estimated Lbs | P6: Estimated Power Capacity (MW) | Q6: Estimated Voltage (KV) | R6: City | S6: County | T6: State | U6: Country | V6: Canada Province/Territory | W6: Est. Commission Date | X6: Est. Close Date * | Y6: Est. Award Date | Z6: Market | AA6: Segment | AB6: Application | AC6: Demand Driver | AD6: OEM Category | AE6: Proposed Project Application | AF6: Brownfield/Greenfield | AG6: Power Needs | AH6: Primary Energy Source | AI6: AI Facility | AJ6: Sales Comments | AK6: Top Next Steps | AL6: Project Description | AM6: Internal NDA Active | AN6: Customer NDA Required | AO6: Total Transmission Line Miles | AP6: Transmission Line Endpoint 1 | AQ6: Transmission Line Endpoint 2 | AR6: Data Center Building Name | AS6: External Project ID | AT6: Building ID (Data Centers Only) | AU6: End User ID | AV6: Site Owner ID | AW6: RTO/ISO/Regional Group ID
A7: Forest Junction Energy Center | B7: Invenergy | C7: Open | D7: Forest Junction Energy Center Project (Yes Energy); Forest Junction Energy Center LLC; MISO J4014; paired w/ Union Depot Energy Center (750 MW CC) | E7: IPP | F7: Daniel Birmingham, Lead Developer | G7: Invenergy (private land lease) | I7: Developer | K7: Advanced Development - pre-CPCN application (WI PSC REF#606657) | M7: =P7*1000*Guide!$B$81 | P7: 1203 | Q7: 345 | R7: Brillion (Town of) | S7: Calumet | T7: WI | U7: United States | W7: 48213 | X7: 48395 | Y7: 47483 | Z7: Power Generation | AA7: Generation | AB7: New Capacity/New Build | AC7: New Load Growth | AD7: Generation | AE7: Natural gas generation - electrical BoP (MV/LV power, tray/control & instrumentation cable, substation) | AF7: Greenfield | AG7: Traditional | AH7: Natural Gas | AI7: No | AJ7: *RPBD* AWARD (PO) DATE BASIS: CPCN filing expected fall 2026 (PSC docket 5-CE-162), construction start Q4 2027, COD Dec 2031 -> BOP cable likely released in phases Q4 2028-Q2 2030 (award date set to COD-24 mo). EPC not named (Invenergy has used Kiewit elsewhere - unconfirmed). We Energies (Brendan Conway, spokesperson) may acquire; precedent: PSC approved Invenergy Red Oak Ridge/Foundry Ridge for We Energies Oct 15, 2026. Yes Energy shows 2030 COD; public sources Dec 2031. | AK7: Build relationship with Daniel Birmingham (Invenergy); watch PSC 5-CE-162 CPCN for EPC; get on EPC approved-vendor list in 2027. | AL7: *RPBD* OVERVIEW: Proposed ~1,203 MW natural-gas simple-cycle PEAKING plant by Invenergy, planned alongside the 750 MW Union Depot Energy Center combined cycle on an adjacent site (~1.95 GW total campus). Alternate site identified in Town of Woodville. TECHNOLOGY & EQUIPMENT: 5x GE 7F.05 combustion turbines with GE H35 generators, each with generator step-up transformer; designed for continuous duty but expected to run mainly at peak. SITE: GREENFIELD - privately owned agricultural land east of WI-57, north of US-10, Town of Brillion, Calumet County (acreage not yet published; see PSC engineering plan). INTERCONNECTION: three 345 kV overhead gen-tie lines to ATC's Forest Junction 345 kV substation (ATC also expanding 345 kV lines south to new Sheboygan River substation). OWNERSHIP/STATUS: Developer Invenergy; We Energies listed it in rate-case planning (possible acquirer, needs PSC approval). Engineering plan filed Aug 2026; CPCN application expected fall 2026 (PSC docket 5-CE-162); construction start targeted Q4 2027; COD ~Dec 2031. EPC not yet selected. INVESTMENT: Total project investment Not disclosed; est. W&C value $9,624,000 ($8/kW). W&C NEEDS (simple-cycle peaker): MV power cable (5-35 kV) for auxiliary transformers, MV switchgear, fuel-gas compressors and black-start/aux systems; 600V power & TC-ER tray cable for turbine packages, MCCs, fuel oil forwarding (if dual fuel) and SCR/ammonia systems; shielded instrumentation & control cable; bare copper grounding grid per unit and switchyard; switchyard control/relay cable; building wire for control/admin buildings. Less cable per MW than a CC (no HRSG/steam cycle). Plus overhead conductor for 3x 345 kV gen-ties; large opportunity if bundled with Union Depot CC. Ref: https://dailyreporter.com/2026/08/31/invenergy-proposes-two-natural-gas-plants-calumet-county/ | https://fox11online.com/news/local/calumet-county-power-plant-proposed-energy-centers-town-of-brillion-power-megawatts-gigawatts-we-energies-invenergy-town-of-woodville-forest-junction-union-depot | https://forestjunctionenergycenter.invenergy.com/ | https://www.nbc26.com/lakeshore/neighbors-push-back-against-proposed-natural-gas-facility-in-town-of-brillion | AO7: 1.2 | AP7: Forest Junction Energy Center | AQ7: ATC Forest Junction 345 kV Substation | AS7: 10019673557
A8: Orange County Advanced Power Station (OCAPS) | B8: Entergy Texas | C8: Closed | D8: Orange County Advanced Power Station Project (Yes Energy); OCAPS; Sabine Power Plant site; PUCT Docket 52487 | E8: IOU | F8: Keith Pollock, Project Director, OCAPS | G8: Entergy Texas | I8: EPC | K8: In service ~Oct 14, 2026 (was Under Construction in Yes Energy) | M8: =P8*1000*Guide!$B$81 | P8: 1215 | R8: Bridge City | S8: Orange | T8: TX | U8: United States | W8: 46309 | X8: 46491 | Y8: 45944 | Z8: Power Generation | AA8: Generation | AB8: New Capacity/New Build | AC8: New Load Growth | AD8: Generation | AE8: Natural gas generation - electrical BoP (MV/LV power, tray/control & instrumentation cable, substation) | AF8: Brownfield | AG8: Traditional | AH8: Natural Gas | AI8: No | AJ8: *RPBD* In service Oct 14, 2026 - new-build window passed (~2023-24). New-build award passed; aftermarket/MRO opportunity (first spring outage ~Apr 2027 - estimate, not sourced). Other contacts: David Borde (CEO, Entergy Texas); James Malone (Dir. Business Development, Sargent & Lundy). | AK8: Aftermarket/spares with Keith Pollock and Entergy fossil ops supply chain; use TIC/S&L relationship for Entergy program plants. | AL8: *RPBD* OVERVIEW: 1,215 MW natural-gas COMBINED-CYCLE plant, Entergy Texas' newest unit; entered commercial service Oct 14, 2026; serves ~230,000 homes in industrial Southeast Texas. TECHNOLOGY & EQUIPMENT: Mitsubishi Power powertrain - 2x M501JAC gas turbines, HRSGs and steam turbine (2x1 configuration); dual-fuel, hydrogen-capable (30% H2 at start, designed for up to 100%). SITE: BROWNFIELD - ~26.2-acre footprint inside/adjacent to Entergy Texas' existing Sabine Power Plant in Bridge City, Orange County (existing gas plant with transmission and water infrastructure). OWNERSHIP/EPC: Entergy Texas; EPC consortium Mitsubishi Power (powertrain), Sargent & Lundy (engineer of record), TIC - The Industrial Company (constructor). STATUS: Construction Apr 2023-2026, first fire Apr 2026, in service Oct 2026. INVESTMENT: Total project investment ~$1.2B (power-eng.com); Yes Energy $555M not confirmed; est. W&C value $9,720,000 ($8/kW). W&C NEEDS: New-build cable scope complete. Remaining: MRO/spares (MV, 600V, tray & instrumentation cable), outage and warranty/punch-list work; reference project for the same TIC/S&L/Mitsubishi team now building Entergy's LA/MS/AR plants. Ref: https://www.click2houston.com/news/local/2026/10/14/entergy-texas-orange-county-advanced-power-station-now-delivering-power-to-southeast-texas/ | https://www.power-eng.com/gas/turbines/entergy-texas-1-2-gw-ccgt-plant-is-now-online/ | https://www.sargentlundy.com/projects/orange-county-advanced-power-station/ | AS8: 10017200239
A9: Vast Sands Power I (Vistra Permian Basin expansion) | B9: Vistra Corp (Luminant) | C9: Open | D9: Vast Sands Power I (TEF - Due Diligence) (Yes Energy); ERCOT 28INR0105 (+ Vast Sands II 28INR0109); Permian Power I & II; Permian Power I LLC | E9: IPP | F9: Jim Burke, President & CEO | G9: Vistra / Luminant Generation Co | I9: IPP | K9: Advanced Development - FID Sep 2025; TEF loan Jun 2026 | M9: =P9*1000*Guide!$B$81 | P9: 440 | R9: Monahans | S9: Ward | T9: TX | U9: United States | W9: 46874 | X9: 47058 | Y9: 46418 | Z9: Power Generation | AA9: Generation | AB9: New Capacity/New Build | AC9: New Load Growth | AD9: Generation | AE9: Natural gas generation - electrical BoP (MV/LV power, tray/control & instrumentation cable, substation) | AF9: Brownfield | AG9: Traditional | AH9: Natural Gas | AI9: No | AJ9: *RPBD* AWARD (PO) DATE BASIS: FID Sep 2025; $583M TEF loan (Jun 2026) with $172M drawn by 6/30/26 = heavy early spend; COD May/Jun 2028 -> cable window Dec 2026-Jun 2027, early packages may already be placed. EPC/OEM not public. No project-level contact public - Jim Burke is exec-level only (quoted in releases). TCEQ NAPD for permit 178462 should list applicant contact (Luminant Generation Co). | AK9: URGENT: identify EPC via TCEQ 178462 NAPD / Industrial Info; find Luminant project contact; quote both units (880 MW). | AL9: *RPBD* OVERVIEW: Vistra/Luminant expansion of the existing Permian Basin Power Plant in Monahans - two new large natural-gas SIMPLE-CYCLE units totaling 860 MW (ERCOT queue: Vast Sands Power I 28INR0105 and II 28INR0109, ~440 MW each), taking the site from 325 MW to 1,185 MW. Driven by Permian oil & gas load growth. TECHNOLOGY & EQUIPMENT: 2x dual-fuel (gas/oil) advanced-class combustion turbine generators with SCR and oxidation catalyst (TCEQ permit 178462); ~440 MW per unit implies H/J-class frames (OEM not published). SITE: BROWNFIELD - existing operating gas plant at 600 N Yucca Dr, Monahans, Ward County (existing 5x 65 MW CTs, gas supply and ERCOT interconnection in place); acreage not published. OWNERSHIP/STATUS: Permian Power I LLC (Vistra). FID Sep 29, 2025; $583M Texas Energy Fund loan Jun 2026 ($172M drawn by Jun 30, 2026); COD May/Jun 2028. EPC not public. INVESTMENT: Total project investment Not disclosed; financed in part by $583M Texas Energy Fund loan (3.0%, Jun 2026); est. W&C value $3,520,000 ($8/kW). W&C NEEDS (simple-cycle peaker): MV power cable (5-35 kV) for auxiliary transformers, MV switchgear, fuel-gas compressors and black-start/aux systems; 600V power & TC-ER tray cable for turbine packages, MCCs, fuel oil forwarding (if dual fuel) and SCR/ammonia systems; shielded instrumentation & control cable; bare copper grounding grid per unit and switchyard; switchyard control/relay cable; building wire for control/admin buildings. Less cable per MW than a CC (no HRSG/steam cycle). Dual-fuel adds fuel-oil system cabling. Ref: https://gov.texas.gov/news/post/governor-abbott-announces-texas-energy-fund-loan-for-860-mw-of-new-power-in-west-texas | https://investor.vistracorp.com/2025-09-29-Vistra-Announces-Plans-to-Build-New-Gas-Fueled-Dispatchable-Power-Units-in-the-Permian-Basin | https://www.gem.wiki/Permian_Power_power_station | https://www.tceq.texas.gov/downloads/permitting/air/bilingual/pending-permit-notices/178462-pls-english.pdf | AS9: 10018470514
A10: Plant Yates Unit 9 (Yates CT Units 8-10) | B10: Georgia Power (Southern Company) | C10: In Progress | D10: Plant Yates Project (June 2027) (Yes Energy); Yates CT Units 8, 9, 10 | E10: IOU | F10: Rick Anderson, SVP & Senior Production Officer | G10: Georgia Power | I10: EPC | K10: Under Construction - Unit 9 equipment on site Dec 2025 | M10: =P10*1000*Guide!$B$81 | P10: 482.8 | R10: Newnan | S10: Coweta | T10: GA | U10: United States | W10: 46568 | X10: 46751 | Y10: 46203 | Z10: Power Generation | AA10: Generation | AB10: New Capacity/New Build | AC10: New Load Growth | AD10: Generation | AE10: Natural gas generation - electrical BoP (MV/LV power, tray/control & instrumentation cable, substation) | AF10: Brownfield | AG10: Traditional | AH10: Natural Gas | AI10: No | AJ10: *RPBD* LOW PROBABILITY: Unit 8 COD Q4 2026, Unit 9 Q2 2027, Unit 10 Q3 2027 (Southern Q2 2026 10-Q). Bulk cable likely bought 2024-25 by Mitsubishi/B&V consortium (award date set to COD-12 mo; already passed). Remaining: Unit 10 top-ups, change orders, spares. Other contacts: Cheryl Boddiford (SVP Mfg & Supply Chain, Mitsubishi Power); Rick Janik (B&V PM on Plant Barry Unit 8 - same EPC pairing, not confirmed for Yates). GA PSC docket 55931. | AK10: Relationship/spares play via B&V site procurement; position with Mitsubishi/B&V for next Georgia Power CT/CC builds. | AL10: *RPBD* OVERVIEW: Georgia Power's first new gas turbines in a decade - three simple-cycle PEAKING units (~1,300 MW total, ~442-463 MW each) at Plant Yates; this record is Unit 9 (COD Q2 2027). Unit 8 Q4 2026, Unit 10 Q3 2027. ~600 construction jobs. Driven by Georgia load growth (data centers/industrial). TECHNOLOGY & EQUIPMENT: 3x Mitsubishi Power M501JAC air-cooled combustion turbines with Mitsubishi Electric VP-X generators (assembled in Savannah, GA); dual-fuel gas/oil; ~30-minute start; hydrogen-capable with modifications. SITE: BROWNFIELD - existing Plant Yates generating site (former coal/gas station on the Chattahoochee River), Newnan, Coweta County, with existing transmission yard. OWNERSHIP/EPC: Georgia Power (Southern Company); EPC consortium Mitsubishi Power Americas + Black & Veatch Construction (contract Jan 12, 2024). Cost not public (PSC staff ~$1B for 3 units). GA PSC monitoring docket 55931. INVESTMENT: Total project investment Not public; PSC staff ~$1B for 3 units; est. W&C value $3,862,400 ($8/kW). W&C NEEDS (simple-cycle peaker): MV power cable (5-35 kV) for auxiliary transformers, MV switchgear, fuel-gas compressors and black-start/aux systems; 600V power & TC-ER tray cable for turbine packages, MCCs, fuel oil forwarding (if dual fuel) and SCR/ammonia systems; shielded instrumentation & control cable; bare copper grounding grid per unit and switchyard; switchyard control/relay cable; building wire for control/admin buildings. Less cable per MW than a CC (no HRSG/steam cycle). Window: bulk cable for all 3 units most likely purchased 2024-25; remaining top-ups, change orders, spares. Ref: https://www.georgiapower.com/news-hub/press-releases/turbine-generator-unit-9-plant-yates.html | https://www.energy.gov/sites/default/files/2026-07/20260622_EnvReview_Completion_Yates.pdf | https://www.modernpowersystems.com/news/progress-at-1-3-gw-plant-yates-gas-fired-plant/ | AS10: 10018823691
A11: Ironwood Power Station | B11: Entergy Arkansas | C11: In Progress | D11: Ironwood Power Station 1A Project (Yes Energy); Lake Catherine 5 (LC5); EIA 69750 | E11: IOU | F11: Carlos Ruiz, VP, Power Development - New Generation | G11: Entergy Arkansas | I11: EPC | K11: Under Construction - groundbreaking Aug 20, 2026 | M11: =P11*1000*Guide!$B$81 | P11: 446 | R11: Jones Mill (Malvern) | S11: Hot Spring | T11: AR | U11: United States | W11: 47118 | X11: 47299 | Y11: 46477 | Z11: Power Generation | AA11: Generation | AB11: New Capacity/New Build | AC11: Replacement / End-of-Life | AD11: Generation | AE11: Natural gas generation - electrical BoP (MV/LV power, tray/control & instrumentation cable, substation) | AF11: Brownfield | AG11: Traditional | AH11: Natural Gas | AI11: No | AJ11: *RPBD* AWARD (PO) DATE BASIS: site construction Q2 2026-Q2 2028, groundbreaking Aug 20 2026, COD Q4 2028 -> bulk cable after underground/foundations ~Q1-Q2 2027. Best new-buy opportunity. TSL procures in its own name; S&L writes cable specs/BOMs. TSL address: 8900 Renner Blvd, Lenexa KS 66219. Other contacts: Laura Landreaux (CEO, Entergy AR); Louise Duncan (VP Power Plant Ops, Entergy AR); Jason Rees (Dir. Procurement, Entergy - LinkedIn, verify). Entergy supplier registration: esupplier@entergy.com. | AK11: Get on TSL Power Partners bidder list (Kiewit/TIC Lenexa) and S&L approved-manufacturer list; register with Entergy supplier program. | AL11: *RPBD* OVERVIEW: 446 MW natural-gas SIMPLE-CYCLE combustion turbine (Entergy Arkansas 'Next Generation Arkansas'), replacing the 50+ year-old Lake Catherine Unit 4 (retiring end-2027). Formerly 'Lake Catherine 5'. ~260 peak construction jobs; Entergy prioritizing Arkansas contractors (vendor fair Mar 18, 2026). TECHNOLOGY & EQUIPMENT: single advanced-class combustion turbine generator, hydrogen-capable (30% co-fire, future 100% conversion); Mitsubishi implied by the TSL/Mitsubishi Entergy program. SITE: BROWNFIELD - ~20 acres within the existing Lake Catherine Power Generation site, Jones Mill near Malvern, Hot Spring County; reuses existing gas, water and transmission infrastructure. OWNERSHIP/EPC: Entergy Arkansas; EPC TSL Power Partners (TIC/Kiewit + Sargent & Lundy) with Mitsubishi Power Americas (per TIC Entergy Program page). APSC CCN approved Apr 2025; site construction Q2 2026-Q2 2028; groundbreaking Aug 20, 2026; COD Q4 2028. Cost recovered via GAJA rider (not disclosed). INVESTMENT: Total project investment Not disclosed (GAJA rider); est. W&C value $3,568,000 ($8/kW). W&C NEEDS (simple-cycle peaker): MV power cable (5-35 kV) for auxiliary transformers, MV switchgear, fuel-gas compressors and black-start/aux systems; 600V power & TC-ER tray cable for turbine packages, MCCs, fuel oil forwarding (if dual fuel) and SCR/ammonia systems; shielded instrumentation & control cable; bare copper grounding grid per unit and switchyard; switchyard control/relay cable; building wire for control/admin buildings. Less cable per MW than a CC (no HRSG/steam cycle). Ref: https://www.entergy.com/news/entergy-arkansas-breaks-ground-on-ironwood-power-station | https://www.modernpowersystems.com/news/entergy-arkansas-starts-construction-on-446-mw-ironwood-power-station/ | https://www.entergy.com/news/ironwood-power-plant-vendor-fair-for-arkansas-contractors-announced | AS11: 10019705142
A12: Person County Combined Cycle 1 (CC1) | B12: Duke Energy Progress | C12: In Progress | D12: Person County Advanced CC1 (Yes Energy); Person County Energy Complex (Roxboro site); NCUC E-2 Sub 1318; sister CC2 E-2 Sub 1349 | E12: IOU | F12: John Robert Smith Jr., General Manager, New Gas Generation Development | G12: Duke Energy Progress / NCEMC (co-owner ~225 MW) | I12: EPC | K12: Under Construction - groundbreaking Feb 2026; GTs arriving 2026 | M12: =P12*1000*Guide!$B$81 | P12: 1360 | R12: Semora (Roxboro) | S12: Person | T12: NC | U12: United States | W12: 47118 | X12: 47299 | Y12: 46416 | Z12: Power Generation | AA12: Generation | AB12: New Capacity/New Build | AC12: New Load Growth | AD12: Generation | AE12: Natural gas generation - electrical BoP (MV/LV power, tray/control & instrumentation cable, substation) | AF12: Brownfield | AG12: Traditional | AH12: Natural Gas | AI12: No | AJ12: *RPBD* AWARD (PO) DATE BASIS: Zachry EPC Aug 2025, groundbreaking Feb 13 2026, first GE Vernova GT on site Jul 23 2026, Zachry craft hiring from Jul 2026; COD Q4 2028 (SC ORS) -> bulk MV/600V/tray bid likely now; act immediately. CC2 (Q4 2029, likely Zachry) -> separate close ~12/15/2027. Other contacts: Ralph Biediger (EPC Group President, Zachry); Bill Norton (Duke spokesperson). Utility is Duke Energy Progress (not DEC). | AK12: Engage Zachry procurement now for CC1 (+CC2 combined buy); contact John Robert Smith Jr. (Duke PM&C). | AL12: *RPBD* OVERVIEW: 1,360 MW natural-gas COMBINED-CYCLE block (first of two identical blocks, 2,720 MW total) at Duke's 'Person County Energy Complex' (Roxboro plant), enabling retirement of Roxboro coal units 1 & 4. NCEMC co-owns ~225 MW. Nearby Microsoft-owned Person County Mega Park (~1,350 acres). TECHNOLOGY & EQUIPMENT: 2x1 advanced-class, hydrogen-capable CC - 2x GE Vernova gas turbines, 2x HRSGs, 1x GE Vernova steam turbine generator (~450 tons); first GT on site Jul 23, 2026. SITE: BROWNFIELD - ~50 acres of undeveloped land within the existing Roxboro coal plant property, Semora Road side, Semora/Roxboro, Person County. OWNERSHIP/EPC: Duke Energy Progress (majority) + NCEMC; full EPC Zachry Group (awarded Aug 2025). NCUC CPCN Oct 2025; groundbreaking Feb 13, 2026; COD Q4 2028 (CC2 Q4 2029). Cost ~$2.13B (CC1). Two new tie lines from the site. INVESTMENT: Total project investment ~$2.13B (CC1, DEP Class 3 estimate); est. W&C value $10,880,000 ($8/kW). W&C NEEDS (combined cycle): MV power cable (5-35 kV) from unit auxiliary/station service transformers to plant MV switchgear and large motors (boiler feed pumps, condensate & circulating water pumps, cooling tower/ACC fans, gas compressors); 600V power & TC-ER tray cable for MCCs, HRSG/steam-turbine auxiliaries, BOP and water treatment; shielded instrumentation & control cable (DCS, turbine controls, CEMS); bare copper grounding grid; switchyard control/relay cable; lighting, building wire and fire-alarm in admin/warehouse/control buildings. CC2 doubles the scope ~1 year later with the same EPC. Ref: https://zachrygroup.com/press-releases/Duke_Energy_Awards_EPC_Contract_for_the_first_Person_County_Combined_Cycle_Project_to_Zachry_Group.html | https://www.duke-energy.com/info/person | https://www.theassemblync.com/news/business/person-county-microsoft-data-center-nondisclosure-agreements/ | AP12: Person County CC1 | AQ12: Duke Energy Progress grid (two new tie lines) | AS12: 10017400436
A13: Delta Blues Advanced Power Station | B13: Entergy Mississippi | C13: In Progress | D13: Delta Blues Power Project (May 2028) (Yes Energy); EIA 67914; Superpower Mississippi; replaces Gerald Andrus plant | E13: IOU | F13: Ernest Rufus, Senior Manager, Capital Projects (Delta Blues & Vicksburg) | G13: Entergy Mississippi | I13: EPC | K13: Under Construction - HRSG erection underway | M13: =P13*1000*Guide!$B$81 | P13: 754 | R13: Greenville | S13: Washington | T13: MS | U13: United States | W13: 46874 | X13: 47058 | Y13: 46356 | Z13: Power Generation | AA13: Generation | AB13: New Capacity/New Build | AC13: Replacement / End-of-Life | AD13: Generation | AE13: Natural gas generation - electrical BoP (MV/LV power, tray/control & instrumentation cable, substation) | AF13: Brownfield | AG13: Traditional | AH13: Natural Gas | AI13: No | AJ13: *RPBD* MAIN WINDOW LIKELY PASSED: HRSG erection May 2026 ("anchor bolts up"), COD May 2028 -> bulk cable likely bought; remaining late releases, change orders, I&C top-ups. EPC TSL Power Partners (Kiewit/TIC), Kiewit 200+ on site. Use as entry to TSL Entergy program buy for sister plants. Yes Energy 879 MW/$651M vs Entergy 754 MW/$1.2B. | AK13: Contact Ernest Rufus and TSL/TIC procurement now - target program buy for Vicksburg/Ironwood/Waterford. | AL13: *RPBD* OVERVIEW: 754 MW natural-gas COMBINED-CYCLE plant ('Superpower Mississippi'), replacing the aging Gerald Andrus Steam Electric Station; serves ~385,000 homes across Entergy Mississippi's 45 counties. TECHNOLOGY & EQUIPMENT: 1x1 combined cycle - Mitsubishi Power M501JAC gas turbine (per GEM), HRSG (modules being lifted May 2026), steam turbine; dual-fuel, hydrogen-blend capable. SITE: BROWNFIELD-ADJACENT - new footprint within ~1 mile of the Andrus plant, 85 Stokes King Road, Greenville, Washington County; reuses Andrus transmission and gas infrastructure (acreage not published). INTERCONNECTION: ~1.5 miles of new transmission line to the existing substation next to Andrus; new Delta Blues substation. OWNERSHIP/EPC: Entergy Mississippi; EPC TSL Power Partners (Kiewit Power Constructors / TIC; Kiewit 200+ on site). Groundbreaking Nov 2024; COD May 2028; ~$1.2B. INVESTMENT: Total project investment ~$1.2B (Entergy); Yes Energy $651M not confirmed; est. W&C value $6,032,000 ($8/kW). W&C NEEDS (combined cycle): MV power cable (5-35 kV) from unit auxiliary/station service transformers to plant MV switchgear and large motors (boiler feed pumps, condensate & circulating water pumps, cooling tower/ACC fans, gas compressors); 600V power & TC-ER tray cable for MCCs, HRSG/steam-turbine auxiliaries, BOP and water treatment; shielded instrumentation & control cable (DCS, turbine controls, CEMS); bare copper grounding grid; switchyard control/relay cable; lighting, building wire and fire-alarm in admin/warehouse/control buildings. Plus ~1.5 mi transmission line conductor and substation cable. Status: above-ground erection since May 2026 - bulk cable likely ordered. Ref: https://www.power-eng.com/gas/combined-cycle/entergy-mississippi-breaks-ground-on-754-mw-combined-cycle-plant/ | https://www.entergy.com/blog/delta-blues-reaches-important-milestone-in-construction | https://www.gem.wiki/Delta_Blues_Advanced_Power_Station | https://opcgis.deq.state.ms.us/ensearchonline/ai_info.aspx?ai=86260 | AO13: 1.5 | AP13: Delta Blues Advanced Power Station | AQ13: Existing substation at Gerald Andrus station | AS13: 10018299981
A14: Vicksburg Advanced Power Station | B14: Entergy Mississippi | C14: In Progress | D14: Vicksburg Advanced Power Project (Aug 2028) (Yes Energy); EIA 69223; former Baxter Wilson site; Superpower Mississippi | E14: IOU | F14: Ernest Rufus, Senior Manager, Capital Projects (Vicksburg role to confirm) | G14: Entergy Mississippi | I14: EPC | K14: Under Construction - groundbreaking Oct 2025 | M14: =P14*1000*Guide!$B$81 | P14: 754 | R14: Vicksburg | S14: Warren | T14: MS | U14: United States | W14: 46966 | X14: 47150 | Y14: 46371 | Z14: Power Generation | AA14: Generation | AB14: New Capacity/New Build | AC14: New Load Growth | AD14: Generation | AE14: Natural gas generation - electrical BoP (MV/LV power, tray/control & instrumentation cable, substation) | AF14: Brownfield | AG14: Traditional | AH14: Natural Gas | AI14: No | AJ14: *RPBD* URGENT: groundbreaking Oct 21 2025, Baxter Wilson demolition Dec 2025, COD Aug 2028 -> cable window now through ~Feb 2027; may be partly placed if TSL bought with Delta Blues. Linked contextually to AWS $3B Vicksburg campus. Entergy MS media line 769-262-0745. | AK14: Engage TSL/TIC procurement now; confirm Ernest Rufus covers Vicksburg (confirmed on Delta Blues only) and ask for the named project buyer. | AL14: *RPBD* OVERVIEW: 754 MW natural-gas COMBINED-CYCLE plant, next phase of 'Superpower Mississippi'; ~560 construction jobs, 21 permanent. Contextually linked to Amazon/AWS's $3B Vicksburg data-center campus (AWS covers its service-extension costs). TECHNOLOGY & EQUIPMENT: combined cycle (gas turbine + HRSG + steam turbine), hydrogen-blend capable and carbon-capture enabled; turbine OEM not confirmed (Mitsubishi likely via TSL/Mitsubishi Entergy program). SITE: BROWNFIELD - former Baxter Wilson Steam Electric Station (1960s gas/oil plant, retired 2022; large structures demolished Dec 17, 2025), 770 Kemp Bottom Rd, Vicksburg, Warren County, on the Mississippi River; existing transmission/gas corridors (acreage not published). OWNERSHIP/EPC: Entergy Mississippi; EPC TSL Power Partners (TIC/Kiewit + Sargent & Lundy) with Mitsubishi Power Americas (per TIC Entergy Program page). Groundbreaking Oct 21, 2025; COD Aug 2028; ~$1.2B. INVESTMENT: Total project investment ~$1.2B (Entergy); Yes Energy $700M not confirmed; est. W&C value $6,032,000 ($8/kW). W&C NEEDS (combined cycle): MV power cable (5-35 kV) from unit auxiliary/station service transformers to plant MV switchgear and large motors (boiler feed pumps, condensate & circulating water pumps, cooling tower/ACC fans, gas compressors); 600V power & TC-ER tray cable for MCCs, HRSG/steam-turbine auxiliaries, BOP and water treatment; shielded instrumentation & control cable (DCS, turbine controls, CEMS); bare copper grounding grid; switchyard control/relay cable; lighting, building wire and fire-alarm in admin/warehouse/control buildings. Ref: https://www.entergymississippi.com/generation/vicksburg | https://www.powermag.com/entergy-mississippi-adding-third-gas-fired-power-plant-to-superpower-strategy/ | https://www.datacenterdynamics.com/en/news/amazon-to-build-3bn-data-center-campus-in-vicksburg-mississippi/ | AS14: 10019088992
A15: Sycamore Riverside Energy Center | B15: Indiana Michigan Power (AEP) | C15: Open | D15: Sullivan Generating Station (May 2027) (Yes Energy); Sullivan Generating Station 1 & 2 (PJM AB1-087/AB1-088); IURC Cause 46389 | E15: IOU | F15: John E. Niland, VP, New Technology & Thermal Development | G15: Invenergy (to be acquired by I&M at COD) | I15: Developer | K15: Advanced Development - IURC CPCN order expected end-2026 | M15: =P15*1000*Guide!$B$81 | P15: 918 | Q15: 345 | R15: Fairbanks Township | S15: Sullivan | T15: IN | U15: United States | W15: 47208 | X15: 47391 | Y15: 46568 | Z15: Power Generation | AA15: Generation | AB15: New Capacity/New Build | AC15: New Load Growth | AD15: Generation | AE15: Natural gas generation - electrical BoP (MV/LV power, tray/control & instrumentation cable, substation) | AF15: Brownfield | AG15: Traditional | AH15: Natural Gas | AI15: No | AJ15: *RPBD* AWARD (PO) DATE BASIS: Boldt lists construction Sep 2026-Feb 2029 (built at risk before IURC order expected end-2026); COD Mar 31 2029 -> cable window Q1-Q3 2027; Invenergy/Boldt buy, not I&M. Other contacts: Daniel Runyan (SVP Development, Invenergy); Steve Baker (President & COO, I&M); Timothy B. Gaul (Dir. Regulated Infrastructure Development, AEPSC); Timothy C. Kerns (Sterling Industrial - owner's engineer witness). PJM (not MISO), 918 MW SC (not 1,150 MW CC). Existing Salesforce opportunity (CRM: 930 MW combined cycle, award 10/1/2026) - update CRM to 918 MW simple cycle; merge Sullivan Generating Station 1 & 2 duplicates. | AK15: Engage Boldt procurement and Invenergy thermal construction now (Q4 2026-Q1 2027) for MV/600V/tray bid lists. | AL15: *RPBD* OVERVIEW: ~918-935 MW natural-gas SIMPLE-CYCLE PEAKING plant developed by Invenergy and to be acquired by Indiana Michigan Power (AEP) at COD (Mar 31, 2029) to meet data-center-driven load growth (AWS, Google, Microsoft). Formerly queued as Sullivan Generating Station 1 & 2 (1,150 MW CC concept). TECHNOLOGY & EQUIPMENT: 4x GE Vernova 7F.05 combustion turbines (~232 MW each), dual-fuel natural gas with ultra-low-sulfur distillate backup; gas via ~5.5-mile 24-inch ONEOK lateral. SITE: BROWNFIELD-ADJACENT - next to I&M's retired, demolished Breed coal plant, CR 925N, Fairbanks Township, Sullivan County; ~64-acre plant footprint within ~356-acre parcel (local meeting summary - verify). Invenergy holds land under purchase option. INTERCONNECTION: AEP/I&M Sullivan 345 kV station (new 345 kV breakers), PJM. OWNERSHIP/STATUS: Invenergy (developer) -> I&M; IURC Cause 46389 order expected end-2026; constructor The Boldt Company lists construction Sep 2026-Feb 2029; ~$500M capital (Invenergy). INVESTMENT: Total project investment ~$500M capital investment (Invenergy); est. W&C value $7,344,000 ($8/kW). W&C NEEDS (simple-cycle peaker): MV power cable (5-35 kV) for auxiliary transformers, MV switchgear, fuel-gas compressors and black-start/aux systems; 600V power & TC-ER tray cable for turbine packages, MCCs, fuel oil forwarding (if dual fuel) and SCR/ammonia systems; shielded instrumentation & control cable; bare copper grounding grid per unit and switchyard; switchyard control/relay cable; building wire for control/admin buildings. Less cable per MW than a CC (no HRSG/steam cycle). Dual-fuel adds fuel-oil system cabling. Ref: https://www.aep.com/news/stories/view/11850/ | https://sycamoreriverside.invenergy.com/about-project | https://www.pjm.com/pub/planning/project-queues/facilities/ab1087_fac.pdf | https://www.gem.wiki/Sycamore_Riverside_Energy_Center | AS15: 10019254864
A16: Franklin Farms Power Station (Units 1 & 2) | B16: Entergy Louisiana | C16: In Progress | D16: Titanium Advanced Power Station CCCT Project (Yes Energy / air permit); EIA 68214; MISO E0014; LPSC U-37425 | E16: IOU | F16: Nicholas D. Pressler, Director, Power Development | G16: Entergy Louisiana (state-owned Franklin Farms site) | I16: EPC | K16: Under Construction - groundbreaking Dec 1, 2025 | M16: =P16*1000*Guide!$B$81 | P16: 1508 | Q16: 500 | R16: Holly Ridge | S16: Richland Parish | T16: LA | U16: United States | W16: 47088 | X16: 47270 | Y16: 46416 | Z16: Power Generation | AA16: Generation | AB16: New Capacity/New Build | AC16: Load Interconnection | AD16: Generation | AE16: Natural gas generation - electrical BoP (MV/LV power, tray/control & instrumentation cable, substation) | AF16: Greenfield | AG16: Traditional | AH16: Natural Gas | AI16: Yes | AJ16: *RPBD* AWARD (PO) DATE BASIS: groundbreaking Dec 1 2025, COD Dec 2028; IMI valve order Sep 2026 says detailed engineering still active -> cable window Dec 2026-Jun 2027, early MV/grounding packages possibly Q4 2026. EPC TSL Power Partners/Kiewit + Mitsubishi. Other contacts: Phillip May (CEO, Entergy LA); Carlos Ruiz (VP Power Development, Entergy); Jim Niemiec (VP & Chief Supply Chain Officer, Entergy); media Brandon Scardigli 504-576-4132. Separate 500 kV transmission opportunity. | AK16: Engage TSL/TIC procurement now; contact Nicholas Pressler; open separate 500 kV transmission opportunity. | AL16: *RPBD* OVERVIEW: ~1,508 MW natural-gas COMBINED-CYCLE station (two units) built to power Meta's Hyperion AI data-center campus; Meta pays the plants' full revenue requirement for 15 years. Air permit name 'Titanium Advanced Power Station'. ~7 more Hyperion plants (~5.2 GW) proposed, LPSC vote Dec 2026. TECHNOLOGY & EQUIPMENT: 2x 1x1 combined-cycle blocks - Mitsubishi Power M501JAC gas turbines, HRSGs, steam turbines (~754-780 MW each); hydrogen-capable (30% co-fire), carbon-capture ready; IMI valve package (Sep 2026). SITE: GREENFIELD - former agricultural land on the state-owned Franklin Farms megasite (~1,400-2,250 acres total incl. Meta campus) along LA Hwy 183 near Holly Ridge, Richland Parish. INTERCONNECTION: Entergy 500 kV system - ~100 miles of new 500 kV lines (~$1.2B), eight new 230 kV lines, Sterlington 500 kV upgrades. OWNERSHIP/EPC: Entergy Louisiana; EPC TSL Power Partners (TIC/Kiewit + Sargent & Lundy) with Mitsubishi Power. LPSC approval Aug 2025; groundbreaking Dec 1, 2025; COD Dec 2028; ~$2.39B for both units. INVESTMENT: Total project investment ~$2.39B (Franklin Farms 1 & 2, LPSC testimony); est. W&C value $12,064,000 ($8/kW). W&C NEEDS (combined cycle): MV power cable (5-35 kV) from unit auxiliary/station service transformers to plant MV switchgear and large motors (boiler feed pumps, condensate & circulating water pumps, cooling tower/ACC fans, gas compressors); 600V power & TC-ER tray cable for MCCs, HRSG/steam-turbine auxiliaries, BOP and water treatment; shielded instrumentation & control cable (DCS, turbine controls, CEMS); bare copper grounding grid; switchyard control/relay cable; lighting, building wire and fire-alarm in admin/warehouse/control buildings. Separate opportunity: HV/500 kV transmission conductor and substation cable. Ref: https://www.entergy.com/news/entergy-louisiana-breaks-ground-on-new-state-of-the-art-generation-facilities-to-power-reliability-growth-and-innovation | https://www.ticus.com/entergy-program/ | https://www.gem.wiki/Franklin_Farms_power_station | https://www.datacenterdynamics.com/en/news/entergy-breaks-ground-on-two-natural-gas-plants-for-metas-2gw-data-center-in-richland-parish-louisiana/ | AS16: 10019228423
A17: Waterford 5 Power Station | B17: Entergy Louisiana | C17: Open | D17: Waterford 5 Project (June 2029) (Yes Energy); EIA 69184; MISO E0029; Waterford 5 & 6 | E17: IOU | F17: Nicholas D. Pressler, Director, Power Development | G17: Entergy Louisiana | I17: EPC | K17: Advanced Development - site prep since Nov 2025; construction late 2026 | M17: =P17*1000*Guide!$B$81 | P17: 754 | Q17: 500 | R17: Killona / Taft | S17: St. Charles Parish | T17: LA | U17: United States | W17: 47270 | X17: 47453 | Y17: 46660 | Z17: Power Generation | AA17: Generation | AB17: New Capacity/New Build | AC17: Load Interconnection | AD17: Generation | AE17: Natural gas generation - electrical BoP (MV/LV power, tray/control & instrumentation cable, substation) | AF17: Brownfield | AG17: Traditional | AH17: Natural Gas | AI17: Yes | AJ17: *RPBD* AWARD (PO) DATE BASIS: site prep since Nov 2025, main construction late 2026, COD 2029 -> cable window mid-2027-mid-2028. Waterford 6 (754 MW, ~Jul 2030, LPSC vote Dec 16 2026, same EPC) - pitch combined WF5+6 buy (~$3.75B program). Other contact: Michelle Berg (Entergy, parish council briefing - secondary source). | AK17: Pitch combined Waterford 5+6 cable package to TSL; contact Nicholas Pressler. | AL17: *RPBD* OVERVIEW: ~754-820 MW natural-gas COMBINED-CYCLE unit approved with Franklin Farms to support Meta's Hyperion load; paired with proposed Waterford 6 (754 MW, ~Jul 2030, LPSC vote Dec 16, 2026) - ~$3.75B WF5+6 program, 700+ construction jobs 2026-2030. TECHNOLOGY & EQUIPMENT: 1x1 combined cycle - Mitsubishi Power M501JAC gas turbine, HRSG, steam turbine (EIA: 2 generators, 820 MW nameplate). SITE: BROWNFIELD - existing Entergy Waterford generating complex at Killona/Taft, St. Charles Parish, on the Mississippi River (home to Waterford 1 & 2 gas/oil units and Waterford 3 nuclear); soft soils require ~100,000 truckloads of surcharge fill (site prep since Nov 2025). INTERCONNECTION: Waterford 500 kV substation via ~0.25-mile 500 kV gen-tie (MISO E0029). OWNERSHIP/EPC: Entergy Louisiana; EPC TSL Power Partners (TIC + Sargent & Lundy) per LPSC Waterford 6 filing. Main construction late 2026; COD 2029. Cost ~ $1.2B implied. INVESTMENT: Total project investment ~$1.2B implied (similar to each Franklin Farms unit); Yes Energy $1.75B not confirmed; est. W&C value $6,032,000 ($8/kW). W&C NEEDS (combined cycle): MV power cable (5-35 kV) from unit auxiliary/station service transformers to plant MV switchgear and large motors (boiler feed pumps, condensate & circulating water pumps, cooling tower/ACC fans, gas compressors); 600V power & TC-ER tray cable for MCCs, HRSG/steam-turbine auxiliaries, BOP and water treatment; shielded instrumentation & control cable (DCS, turbine controls, CEMS); bare copper grounding grid; switchyard control/relay cable; lighting, building wire and fire-alarm in admin/warehouse/control buildings. Plus 500 kV gen-tie; bundle Waterford 5 + 6 as one cable package. Ref: https://www.entergylouisiana.com/waterford5-6 | https://www.interconnection.fyi/project/miso-e0029 | https://www.entergy.com/blog/the-dirt-on-dirt-from-digging-soil-to-boosting-louisianas-economy | AO17: 0.25 | AP17: Waterford 5 Power Station | AQ17: Waterford 500 kV Substation | AS17: 10019089005
A18: AES Petersburg Unit 4 Repowered | B18: AES Indiana | C18: In Progress | D18: Petersburg Generating Station Unit 4 coal-to-gas conversion; IURC Cause 46022 (Units 3 & 4) | E18: IOU | F18: Brandi Davis-Handy, President | G18: AES Indiana | I18: EPC | K18: Under Construction - Unit 4 conversion outage 2026 | M18: =P18*1000*Guide!$B$81 | P18: 526 | R18: Petersburg | S18: Pike | T18: IN | U18: United States | W18: 46387 | X18: 46568 | Y18: 45930 | Z18: Power Generation | AA18: Generation | AB18: New Capacity/New Build | AC18: Regulatory / Policy | AD18: Generation | AE18: Natural gas generation - electrical BoP (MV/LV power, tray/control & instrumentation cable, substation) | AF18: Brownfield | AG18: Traditional | AH18: Natural Gas | AI18: No | AJ18: AWARD (PO) DATE BASIS: B&W full NTP Nov 2024, CDM Smith BOP NTP Aug 2025; Unit 4 outage Jun-Oct 2026, COD end-2026 (B&W: Q1 2027) -> BOP cable likely bought Q3-Q4 2025; window passed. Remaining: Unit 4 punch-list/change orders. MW (526) from CRM - unverified. Other contacts: Chris Riker (SVP, B&W Thermal); Todd Hillman (SVP, AES Indiana). | AK18: Chase remaining Unit 4 fill-in orders via B&W Construction / CDM Smith; leverage for future B&W coal-to-gas conversions. | AL18: OVERVIEW: Coal-to-natural-gas repowering of AES Indiana's Petersburg Unit 4 (with Unit 3), ending coal at the plant; IURC approved 5-0 Nov 2024 within AES's ~$1.1B Pike County package (incl. nearby 250 MW solar + 180 MWh storage). TECHNOLOGY & EQUIPMENT: boiler fuel switch on existing 1986 coal unit (not new CTs) - new B&W gas burners, ignitors and controls; gas heaters, flue-gas recirculation for NOx, process piping; new 1-mile Midwestern Gas Transmission lateral. SITE: BROWNFIELD - existing Petersburg coal generating station on the White River, Petersburg, Pike County. INTERCONNECTION: existing unit interconnection (no new gen-tie), MISO. OWNERSHIP/STATUS: AES Indiana; EPC Babcock & Wilcox (B&W Construction Co.), BOP by CDM Smith; Unit 3 outage Feb-May 2026, Unit 4 outage Jun-Oct 2026, COD end-2026/Q1 2027. INVESTMENT: ~$293M (excl. AFUDC). W&C NEEDS (coal-to-gas boiler conversion): MV power cable for new gas heaters, FGR fans and modified auxiliaries; 600V power & TC-ER tray cable for new burner management, ignitors, valves and BOP; shielded instrumentation & control cable for burner management system/DCS tie-ins; grounding for new gas yard. Retrofit scope - smaller than a new build, outage-driven buying. Ref: https://www.babcock.com/home/about/corporate/news/babcock-and-wilcox-receives-full-notice-to-proceed-on-246-million-contract-for-indiana-power-plant-coal-to-gas-fuel-switching-project | https://www.cdmsmith.com/en/projects/aes-coal-to-gas | https://aesindiana.com/press-release/aes-indiana-receives-approval-repower-remaining-petersburg-units-coal-natural-gas
A19: Trumbull Energy Center | B19: Clean Energy Future, LLC (KOSPO / KIND / Siemens Energy owners) | C19: Closed | D19: Trumbull Energy Center (adjacent to Lordstown Energy Center); Clean Energy Future-Trumbull; PJM AB1-105 | E19: IPP | F19: Logan Choi, President & CEO | G19: Trumbull Energy Center owners (KOSPO, KIND, Siemens Energy) | I19: EPC | K19: Operating - COD Jan 2026; completion ceremony Jun 24, 2026 | M19: =P19*1000*Guide!$B$81 | P19: 950 | Q19: 345 | R19: Lordstown | S19: Trumbull | T19: OH | U19: United States | W19: 46053 | X19: 46234 | Y19: 45322 | Z19: Power Generation | AA19: Generation | AB19: New Capacity/New Build | AC19: New Load Growth | AD19: Generation | AE19: Natural gas generation - electrical BoP (MV/LV power, tray/control & instrumentation cable, substation) | AF19: Greenfield | AG19: Traditional | AH19: Natural Gas | AI19: No | AJ19: Operating since Jan 2026 - new-build window passed (cable bought ~2023 after Nov 2022 NTP). Re-target as MRO/outage account (Hanwha/Siemens O&M) and use Gemma relationship for Argan pipeline (CPV Basin Ranch, Sandow Lakes). Developer is Clean Energy Future (William Siderewicz), not CPV. MW 940-977 by source. | AK19: Move to Closed/Operating; pursue MRO with plant team; leverage Gemma for current CCGT jobs. | AL19: OVERVIEW: ~940-953 MW (EIA 977 MW nameplate) baseload merchant combined-cycle plant next to the Lordstown Energy Center; commercial operation Jan 2026, completion celebrated Jun 24, 2026; framed around Midwest AI/data-center demand (no named offtaker). TECHNOLOGY & EQUIPMENT: dual-fuel 2x2x1 combined cycle - 2x Siemens Energy SGT6-8000H gas turbines, 2x HRSGs, 1x Siemens SST6-5000 steam turbine; 3x Hanwha fuel-gas compressors (9-yr maintenance contract). SITE: ~127 acres in Lordstown, Trumbull County (7733 Tod Ave SW, Warren OH 44481 - third-party). INTERCONNECTION: PJM AB1-105, Highland-Hanna 345 kV line (ATSI/FirstEnergy). OWNERSHIP/STATUS: owners KOSPO, KIND and Siemens Energy; developer Clean Energy Future LLC; EPC Gemma Power Systems (full NTP Nov 2022). INVESTMENT: ~$1.2B. W&C NEEDS: new-build scope complete; MRO/spares (MV, 600V, tray, instrumentation cable) for outages. Ref: https://www.tribtoday.com/news/local-news/2026/06/trumbull-energy-center-complete/ | https://www.gemmapower.com/our-work/combined-cycle/trumbull-energy-center/ | https://www.interconnection.fyi/project/pjm-ab1-105
A20: Socrates South Power Generation | B20: Will-Power OH, LLC (Williams) | C20: Closed | D20: Socrates South (Williams Power Innovation); OPSB 25-0185-EL-BLN | E20: IPP | F20: Chad Zamarin, President & CEO | G20: Will-Power OH, LLC | I20: Owner/End User | K20: Operating - placed in service late Jul 2026 | M20: =P20*1000*Guide!$B$81 | P20: 200 | R20: New Albany | S20: Licking | T20: OH | U20: United States | W20: 46234 | X20: 46418 | Y20: 45838 | Z20: Power Generation | AA20: Generation | AB20: New Capacity/New Build | AC20: Load Interconnection | AD20: Generation | AE20: Natural gas generation - electrical BoP (MV/LV power, tray/control & instrumentation cable, substation) | AF20: Greenfield | AG20: Traditional | AH20: Natural Gas | AI20: Yes | AJ20: Operating since late Jul 2026 (~14 months site-to-power) - window passed. Use as reference case to get on Williams approved-vendor list for its next Power Innovation behind-the-meter projects (Blackstone JV covers 5 projects). EPC not public (check OPSB dockets). | AK20: Mark Closed; pursue Williams Power Innovation follow-on sites; find EPC via OPSB 25-0185 docket. | AL20: OVERVIEW: 200 MW behind-the-meter gas generation plant dedicated to Meta (Sidecat LLC) at the New Albany data-center campus (Prometheus AI cluster) under a 10-yr fixed-price deal (+5-yr option); in service late Jul 2026, on time and on budget. TECHNOLOGY & EQUIPMENT: simple-cycle aeroderivative/industrial turbines + reciprocating engines - filed fleet 3x Solar Titan 250, 9x PGM 130, 3x Siemens SGT-400, 15x Caterpillar 3520 engines, 8x Cat C15 500 kW diesel backup (split between North/South not public). SITE: GREENFIELD - ~20 acres in New Albany International Business Park, Licking County; two 24-inch gas laterals. INTERCONNECTION: no grid connection (OPSB condition) - on-site switching/internal substations feed Meta's adjacent campus. OWNERSHIP/STATUS: Will-Power OH LLC (Williams); Blackstone holds 49% of Power Innovation JV. INVESTMENT: ~$1.6B (North + South + pipeline). W&C NEEDS (behind-the-meter / on-site generation): MV power cable (5-35 kV) collecting many turbine/engine units to on-site switching and plant substations and feeders to the data-center campus; 600V power & TC-ER tray cable for unit packages, MCCs, gas conditioning/compression, BESS and cooling; shielded instrumentation & control cable (unit controls, microgrid/SCADA); extensive bare copper grounding; switchgear/substation control cable; building wire for control and admin buildings. High unit count = high cable density per MW. Status: built - MRO and follow-on sites. Ref: https://www.sec.gov/Archives/edgar/data/0000107263/000010726326000026/wmb-20260630.htm | https://www.power-eng.com/onsite-power/onsite-gas-turbines-reciprocating-engines-to-power-meta-data-center/ | https://www.williams.com/wp-content/uploads/sites/14/2026/02/Socrates-North-and-South-Fact-Sheet-1.pdf
A21: Socrates North Power Generation | B21: Will-Power OH, LLC (Williams) | C21: In Progress | D21: Socrates North (Williams Power Innovation); OPSB 25-0188-EL-BGN | E21: IPP | F21: Chad Zamarin, President & CEO | G21: Will-Power OH, LLC | I21: Owner/End User | K21: Under Construction - in service expected Q4 2026 | M21: =P21*1000*Guide!$B$81 | P21: 200 | R21: New Albany | S21: Licking | T21: OH | U21: United States | W21: 46387 | X21: 46568 | Y21: 45961 | Z21: Power Generation | AA21: Generation | AB21: New Capacity/New Build | AC21: Load Interconnection | AD21: Generation | AE21: Natural gas generation - electrical BoP (MV/LV power, tray/control & instrumentation cable, substation) | AF21: Greenfield | AG21: Traditional | AH21: Natural Gas | AI21: Yes | AJ21: AWARD (PO) DATE BASIS: OPSB approval Sep 18, 2025 + ~14-month fast track -> main cable likely awarded Q3-Q4 2025; window passed. Only possible open scope: BESS amendment (check OPSB docket timing). Williams 10-Q gives 556 MW combined North+South. | AK21: Check OPSB 25-0188 BESS amendment for remaining cable; target Williams next Power Innovation sites. | AL21: OVERVIEW: second 200 MW behind-the-meter gas plant for Meta's New Albany campus (Phase 2), on track for Q4 2026 per Williams; BESS amendment pending. TECHNOLOGY & EQUIPMENT: simple-cycle aeroderivative/industrial gas turbines + reciprocating engines (same design as Socrates South) plus planned battery storage (~173 MW reported across project). SITE: GREENFIELD - ~20 acres, New Albany, Licking County. INTERCONNECTION: behind the meter, no grid connection; on-site substation. OWNERSHIP/STATUS: Will-Power OH LLC (Williams); OPSB approved Sep 18, 2025. INVESTMENT: part of ~$1.6B program. W&C NEEDS (behind-the-meter / on-site generation): MV power cable (5-35 kV) collecting many turbine/engine units to on-site switching and plant substations and feeders to the data-center campus; 600V power & TC-ER tray cable for unit packages, MCCs, gas conditioning/compression, BESS and cooling; shielded instrumentation & control cable (unit controls, microgrid/SCADA); extensive bare copper grounding; switchgear/substation control cable; building wire for control and admin buildings. High unit count = high cable density per MW. Plus BESS DC/AC collection cable if amendment proceeds. Ref: https://opsb.ohio.gov/cases/25-0188-el-bgn | https://investor.williams.com/news-releases/news-release-details/williams-delivers-strong-second-quarter-2026-results-announces
A22: Homer City Energy Campus | B22: Homer City Redevelopment (Homer City Generation, L.P.) | C22: In Progress | D22: Homer City Generation, L.P.; legacy Homer City Generating Station site | E22: IPP | F22: Corey Hessen, CEO | G22: Homer City Redevelopment (Knighthead Capital-led) | I22: EPC | K22: Under Construction - HRSGs installed, first GT set Oct 2026; 2,000+ workers | M22: =P22*1000*Guide!$B$81 | P22: 4400 | R22: Homer City | S22: Indiana | T22: PA | U22: United States | W22: 46752 | X22: 46934 | Y22: 46203 | Z22: Power Generation | AA22: Generation | AB22: New Capacity/New Build | AC22: Load Interconnection | AD22: Generation | AE22: Natural gas generation - electrical BoP (MV/LV power, tray/control & instrumentation cable, substation) | AF22: Brownfield | AG22: Traditional | AH22: Natural Gas | AI22: Yes | AJ22: AWARD (PO) DATE BASIS: Kiewit on site since Oct 2025, HRSG delivery Sep-Oct 2026, first GT set Oct 2026, first power late 2027/early 2028 -> main power-block cable POs very likely placed; remaining releases/change orders through Q1 2027. Bigger long-tail: Amazon 36-building data-center campus plan (construction from Dec 2026, build-out to 2036; tabled by county Sep 2026). Other contacts: Brian Reinhart (VP, Kiewit Power Constructors); Kiewit vendor inbox HomerCity.Info@Kiewit.com; press@homercityredevelopment.com. | AK22: Call Kiewit procurement for remaining power-block MV/LV/control releases; pivot to Amazon data-center phases. | AL22: OVERVIEW: ~4.4-4.5 GW natural-gas power plant + AI data-center campus - the largest gas-powered data-center campus in the U.S. - on the former Homer City coal station; Amazon Data Services has filed a preliminary plan for a 36-building data-center campus (phased Dec 2026-2036). TECHNOLOGY & EQUIPMENT: 7x GE Vernova 7HA.02 hydrogen-capable gas turbines in combined cycle with HRSGs (15 HRSG components delivered Sep-Oct 2026); GIS switchgear building (first steel Apr 2026); possible additional simple-cycle units (unverified). SITE: BROWNFIELD - ~3,200-acre former Homer City coal generating station, Indiana County; demolition/excavation completed Jun 2026; reuses legacy transmission lines and substations. INTERCONNECTION: PJM via new GIS switchyard (existing PJM/NYISO ties); supplies campus behind-the-meter and grid. OWNERSHIP/STATUS: Homer City Redevelopment (Knighthead Capital), EQT gas supply; EPC Kiewit Power Constructors (on site Oct 2025, 1,000 workers Mar 2026, 2,000+ Oct 2026); first power late 2027/early 2028. INVESTMENT: >$10B. W&C NEEDS (combined cycle, 7 blocks): MV power cable to aux transformers, MV switchgear and large motors; 600V power & TC-ER tray cable for HRSG/ST auxiliaries and BOP; shielded I&C cable; bare copper grounding; GIS/switchyard control cable; building wire - plus data-center campus MV distribution, building wire and grounding for 36 buildings (separate long-tail opportunity). Ref: https://www.businesswire.com/news/home/20260401716982/en/Homer-City-Redevelopment-Crosses-the-First-Steel-Threshold | https://www.gevernova.com/news/press-releases/homer-city-redevelopment-kiewit-announce-country-largest-natural-gas-powered-data-center-support-ai-hpc-demand | https://marcellusdrilling.com/2026/10/homer-city-update-first-turbine-set-amazon-plan-now-under-review/
A23: Sandow Lakes Energy Station | B23: Sandow Lakes Energy Company (SLEC) | C23: Open | D23: SL Energy Power Plant I, LLC; ERCOT/EIA 68504; Sandow Lakes CC (CRM Luminant Phase 1/2 duplicates) | E23: IPP | F23: Edward "Ned" Ross III, Executive Vice President | G23: SLEC / Xebec (project reportedly sold Apr 2026 - buyer not public) | I23: EPC | K23: EPC NTP Apr 2025; construction status unclear (sold Apr 2026 per Xebec bio) | M23: =P23*1000*Guide!$B$81 | P23: 1200 | Q23: 345 | R23: Rockdale | S23: Lee / Milam | T23: TX | U23: United States | W23: 47088 | X23: 47270 | Y23: 46477 | Z23: Power Generation | AA23: Generation | AB23: New Capacity/New Build | AC23: Load Interconnection | AD23: Generation | AE23: Natural gas generation - electrical BoP (MV/LV power, tray/control & instrumentation cable, substation) | AF23: Brownfield | AG23: Traditional | AH23: Natural Gas | AI23: Yes | AJ23: AWARD (PO) DATE BASIS: Gemma EPC Feb 2025, NTP Apr 2025, completion 2028 -> cable window Dec 2026-Dec 2027, target ~Q1 2027. RISK: Xebec bio says project sold Apr 2026 (buyer unknown) - confirm owner/schedule. Luminant link only historical (old Sandow coal plant) - merge CRM Luminant duplicates. Other contacts: Tommy Hodges (COO, SL Energy Power Plant I LLC - tommyh@slenergyco.com, TCEQ 2025 filing); Charles E. Collins IV (CEO, Gemma). | AK23: Ask Gemma Power Systems who owns the project now and current schedule; position for MV/LV/control packages Q1 2027. | AL23: OVERVIEW: 1,200 MW net natural-gas combined-cycle plant built mainly to serve private (likely data-center/industrial) customers in the 'Texas Triangle'; only ~80 MW temporary grid export in permits. TECHNOLOGY & EQUIPMENT: 2x Siemens Energy SGT6-9000HL H-class, hydrogen-adaptable gas turbines (two ~645 MW units / 1x1 blocks), NEM Energy HRSGs (Siemens Energy USA client), steam turbines. SITE: BROWNFIELD/industrial - former Alcoa Sandow aluminum smelter and Luminant Sandow coal plant area on the Sandow Lakes Ranch (~33,000 acres, ~28,800 after Apr 2026 sale), Rockdale area, Lee/Milam County. INTERCONNECTION: ERCOT; nearest 345 kV line ~12.2 miles (estimate); Oncor territory. OWNERSHIP/STATUS: SLEC (SL Energy Power Plant I LLC), Xebec affiliate - reportedly sold Apr 2026; EPC Gemma Power Systems (NTP Apr 2025); COD Dec 2028. INVESTMENT: ~$1.2B. W&C NEEDS (combined cycle): MV power cable to aux transformers, MV switchgear and large motors; 600V power & TC-ER tray cable for HRSG/ST auxiliaries and BOP; shielded I&C cable; bare copper grounding; switchyard control cable; private-customer MV feeders; possible 345 kV line. Ref: https://www.businesswire.com/news/home/20250206210188/en/Argan-Inc.s-Gemma-Power-Systems-Executes-EPC-Contract-for-a-1.2-GW-Power-Project-in-Texas | https://www.powermag.com/new-1-2-gw-natural-gas-fired-plant-announced-for-texas/ | https://interchange.puc.texas.gov/Documents/56455_62_1398423.PDF | AO23: 12.2 | AP23: Sandow Lakes Energy Station | AQ23: Nearest 345 kV line (~12.2 mi est.)
