Workbook

Sheet Read Me
A1: SK-3X1 Rev 14 gas power campus: cable schedule and cable bill of materials
A2: Conceptual, derived from the SK-3X1 3D model. Not engineered, not for construction or procurement.
A4: How it was built
A5: 1. Every powered item of the model (BTM data-centre option excluded) is matched to an equipment class that gives its power circuits (voltage, typical rating, source bus) and its field devices (motors, MOVs, analog and discrete instruments, solenoids, thermocouples, RTDs; typical counts for the class). Each device has its own cable to its MCC or to a local junction box; junction boxes home-run on 24-pair / 12-triad / 25-conductor cables. Device-to-JB cables are grouped per JB (Sets = number of device cables). Ratings are typical unless the drawing states one.
A6: 2. Lengths follow the model's electrical routes (trays, duct banks, buried / surface cable, trenches) as a graph: shortest path source to load, plus drops and vertical transitions. 230 kV circuits, overhead conductors and the ground grid are measured directly from the model.
A7: 3. Sizes: ampacity at 125 % of full-load current (NEC 310.16 75 C Cu for 600 V; typical ICEA values for MV-105), 3 % voltage drop at 480 V, parallel sets above 500 kcmil (LV) / 1000 kcmil (MV).
A8: 4. Products are typical Southwire families for each application; confirm constructions, sizes and listings against current Southwire specifications.
A10: 5. 0 of 5695 runs could not follow a modelled route (Route type 'Estimated'): L-shaped length between the items plus 40 ft.
A11: Inputs (blue, yellow cells; every length and quantity recalculates)
A12: Routing slack (training, sag, cutting) | B12: 0.1 | C12: Source: typical industry allowance (assumption)
A13: Termination allowance per run end (ft) | B13: 10 | C13: Source: typical (assumption)
A14: BOM waste / cut allowance | B14: 0.05 | C14: Source: typical (assumption)
A16: Sheets
A17: Cable Schedule: one row per cable run (from / to, service, product, size, sets, length)
A18: Cable BOM: totals per product and size, waste, order length, reels (SUMIFS on the schedule)
A19: Accessories: terminations, glands, lugs, splices (from the schedule)
A20: Summary: cable length by zone and voltage class
A21: Load List: the equipment, assumed ratings and sources behind the power circuits
A23: Excluded from the cable BOM (bus duct, by others)
A24: RICE PCM to MOD-EH bus tie: 13.8 kV, ~6,300 A
A25: MOD-EH to T-MOD-1 LV side: 13.8 kV, ~5,000 A
A26: MOD-EH to T-MOD-2 LV side: 13.8 kV, ~5,000 A
A27: Generator terminals to GSU / UAT / ET (isolated-phase bus): 21 kV, as modelled (IPB routes)
A28: T-R4-1..4 secondaries to the ACC VFD lineups: 480 V, ~4,500 A each

Sheet Audit
A1: Check | B1: Result | C1: Count | D1: Notes / examples
A2: Every powered item has a power circuit (VFD lineups: bus duct; BESS blocks: per container) | B2: PASS | C2: 0
A3: Every instrumented item has instrument cables | B3: PASS | C3: 0
A4: No lump feeder where motors are fed individually (double count) | B4: PASS | C4: 0
A5: Ampacity >= 125 % of full-load current (recomputed) | B5: PASS | C5: 0
A6: 480 V voltage drop <= 3 % (recomputed) | B6: CHECK | C6: 3 | D6: EDG-1 480 V output to EMCC 3.1%; EDG-2 480 V output to EMCC 3.3%; Fuel-cell AC cabinet to MOD-LV 5.7%
A7: Class I Div 2 loads on ARMOR-X / IS cable | B7: PASS | C7: 0
A8: Runs that follow a modelled route | B8: INFO | C8: 5695 | D8: 0 estimated (build-out bays D4-D6 and utilities without drawn trench / bank)
A9: Copper runs > 3,000 ft | B9: INFO | C9: 114 | D9: Control; Motor 1 of 6: control / local ; Motor 2 of 6: control / local ; Motor 3 of 6: control / local
A10: Feeders with >= 6 parallel sets (bus-duct candidates) | B10: INFO | C10: 15 | D10: EDG-1 480 V output to EMCC x13; EDG-2 480 V output to EMCC x13; Site / road lighting: 120 pole x120; Black-start genset output x10
A11: Excluded as bus duct | B11: INFO | C11: 5 | D11: RICE PCM to MOD-EH bus tie; MOD-EH to T-MOD-1 LV side; MOD-EH to T-MOD-2 LV side; Generator terminals to GSU / UAT / ET (isolated-phase bus); T-R4-1..4 secondaries to the ACC VFD lineups

Sheet Cable Schedule
A1: Cable No. | B1: Zone | C1: Area | D1: Service / circuit | E1: From (tag) | F1: From (description) | G1: To (tag) | H1: To (description) | I1: Class | J1: Product | K1: Product key | L1: Conductors | M1: Size (AWG/kcmil) | N1: Sets | O1: Cables / set | P1: Voltage (V) | Q1: Load (kW) | R1: Current (A) | S1: Route type | T1: Route (ft) | U1: Drops + vertical (ft) | V1: Run length (ft) | W1: Total cable (ft) | X1: MV term. kits | Y1: Glands / connectors | Z1: Notes | AA1: Cables (count)
A2: A-L-0001 | B2: A | C2: Power block | D2: Lighting, receptacles and small power branch circuits (allowance) | E2: CEMS-1 | F2: CEMS shelter, HRSG 1 | G2: CEMS-1 | H2: CEMS shelter, HRSG 1 | I2: Building wire | J2: SIMpull THHN/THWN-2 600 V 1/C Cu (lighting, receptacles, small power) | K2: THHN|1/C|12 | L2: 1/C | M2: 12 | N2: 1 | O2: 1 | P2: 277 | S2: Conduit | T2: 358 | U2: 0 | V2: =ROUNDUP((T2+U2+2*'Read Me'!$B$13)*(1+'Read Me'!$B$12),-1) | W2: =V2*N2*O2 | X2: =IF(LEFT(I2,2)="MV",2*N2*IF(L2="1/C",O2,1),0) | Y2: =IF(OR(LEFT(K2,4)="LVAX",LEFT(K2,6)="MV15AX",LEFT(K2,4)="CTAX",LEFT(K2,2)="W|"),2*N2*O2,0) | Z2: allowance: 1.6 ft of conductor per ft2 of floor | AA2: =N2*O2
A3: A-L-0002 | B3: A | C3: Power block | D3: Lighting, receptacles and small power branch circuits (allowance) | E3: CEMS-2 | F3: CEMS shelter, HRSG 2 | G3: CEMS-2 | H3: CEMS shelter, HRSG 2 | I3: Building wire | J3: SIMpull THHN/THWN-2 600 V 1/C Cu (lighting, receptacles, small power) | K3: THHN|1/C|12 | L3: 1/C | M3: 12 | N3: 1 | O3: 1 | P3: 277 | S3: Conduit | T3: 358 | U3: 0 | V3: =ROUNDUP((T3+U3+2*'Read Me'!$B$13)*(1+'Read Me'!$B$12),-1) | W3: =V3*N3*O3 | X3: =IF(LEFT(I3,2)="MV",2*N3*IF(L3="1/C",O3,1),0) | Y3: =IF(OR(LEFT(K3,4)="LVAX",LEFT(K3,6)="MV15AX",LEFT(K3,4)="CTAX",LEFT(K3,2)="W|"),2*N3*O3,0) | Z3: allowance: 1.6 ft of conductor per ft2 of floor | AA3: =N3*O3
A4: A-L-0003 | B4: A | C4: Power block | D4: Lighting, receptacles and small power branch circuits (allowance) | E4: CEMS-3 | F4: CEMS shelter, HRSG 3 | G4: CEMS-3 | H4: CEMS shelter, HRSG 3 | I4: Building wire | J4: SIMpull THHN/THWN-2 600 V 1/C Cu (lighting, receptacles, small power) | K4: THHN|1/C|12 | L4: 1/C | M4: 12 | N4: 1 | O4: 1 | P4: 277 | S4: Conduit | T4: 358 | U4: 0 | V4: =ROUNDUP((T4+U4+2*'Read Me'!$B$13)*(1+'Read Me'!$B$12),-1) | W4: =V4*N4*O4 | X4: =IF(LEFT(I4,2)="MV",2*N4*IF(L4="1/C",O4,1),0) | Y4: =IF(OR(LEFT(K4,4)="LVAX",LEFT(K4,6)="MV15AX",LEFT(K4,4)="CTAX",LEFT(K4,2)="W|"),2*N4*O4,0) | Z4: allowance: 1.6 ft of conductor per ft2 of floor | AA4: =N4*O4
A5: A-L-0004 | B5: A | C5: Power block | D5: Lighting, receptacles and small power branch circuits (allowance) | E5: FH-1 | F5: FH-1: GT inlet filter house on its own frame | G5: FH-1 | H5: FH-1: GT inlet filter house on its own frame | I5: Building wire | J5: SIMpull THHN/THWN-2 600 V 1/C Cu (lighting, receptacles, small power) | K5: THHN|1/C|12 | L5: 1/C | M5: 12 | N5: 1 | O5: 1 | P5: 277 | S5: Conduit | T5: 4973 | U5: 0 | V5: =ROUNDUP((T5+U5+2*'Read Me'!$B$13)*(1+'Read Me'!$B$12),-1) | W5: =V5*N5*O5 | X5: =IF(LEFT(I5,2)="MV",2*N5*IF(L5="1/C",O5,1),0) | Y5: =IF(OR(LEFT(K5,4)="LVAX",LEFT(K5,6)="MV15AX",LEFT(K5,4)="CTAX",LEFT(K5,2)="W|"),2*N5*O5,0) | Z5: allowance: 1.6 ft of conductor per ft2 of floor | AA5: =N5*O5
A6: A-L-0005 | B6: A | C6: Power block | D6: Lighting, receptacles and small power branch circuits (allowance) | E6: FH-2 | F6: FH-2: GT inlet filter house on its own frame | G6: FH-2 | H6: FH-2: GT inlet filter house on its own frame | I6: Building wire | J6: SIMpull THHN/THWN-2 600 V 1/C Cu (lighting, receptacles, small power) | K6: THHN|1/C|12 | L6: 1/C | M6: 12 | N6: 1 | O6: 1 | P6: 277 | S6: Conduit | T6: 4973 | U6: 0 | V6: =ROUNDUP((T6+U6+2*'Read Me'!$B$13)*(1+'Read Me'!$B$12),-1) | W6: =V6*N6*O6 | X6: =IF(LEFT(I6,2)="MV",2*N6*IF(L6="1/C",O6,1),0) | Y6: =IF(OR(LEFT(K6,4)="LVAX",LEFT(K6,6)="MV15AX",LEFT(K6,4)="CTAX",LEFT(K6,2)="W|"),2*N6*O6,0) | Z6: allowance: 1.6 ft of conductor per ft2 of floor | AA6: =N6*O6
A7: A-L-0006 | B7: A | C7: Power block | D7: Lighting, receptacles and small power branch circuits (allowance) | E7: FH-3 | F7: FH-3: GT inlet filter house on its own frame | G7: FH-3 | H7: FH-3: GT inlet filter house on its own frame | I7: Building wire | J7: SIMpull THHN/THWN-2 600 V 1/C Cu (lighting, receptacles, small power) | K7: THHN|1/C|12 | L7: 1/C | M7: 12 | N7: 1 | O7: 1 | P7: 277 | S7: Conduit | T7: 4973 | U7: 0 | V7: =ROUNDUP((T7+U7+2*'Read Me'!$B$13)*(1+'Read Me'!$B$12),-1) | W7: =V7*N7*O7 | X7: =IF(LEFT(I7,2)="MV",2*N7*IF(L7="1/C",O7,1),0) | Y7: =IF(OR(LEFT(K7,4)="LVAX",LEFT(K7,6)="MV15AX",LEFT(K7,4)="CTAX",LEFT(K7,2)="W|"),2*N7*O7,0) | Z7: allowance: 1.6 ft of conductor per ft2 of floor | AA7: =N7*O7
A8: A-L-0007 | B8: A | C8: Power block | D8: Lighting, receptacles and small power branch circuits (allowance) | E8: R1 | F8: R1: main electrical building (64 x 180 ft) | G8: R1 | H8: R1: main electrical building (64 x 180 ft) | I8: Building wire | J8: SIMpull THHN/THWN-2 600 V 1/C Cu (lighting, receptacles, small power) | K8: THHN|1/C|12 | L8: 1/C | M8: 12 | N8: 1 | O8: 1 | P8: 277 | S8: Conduit | T8: 18432 | U8: 0 | V8: =ROUNDUP((T8+U8+2*'Read Me'!$B$13)*(1+'Read Me'!$B$12),-1) | W8: =V8*N8*O8 | X8: =IF(LEFT(I8,2)="MV",2*N8*IF(L8="1/C",O8,1),0) | Y8: =IF(OR(LEFT(K8,4)="LVAX",LEFT(K8,6)="MV15AX",LEFT(K8,4)="CTAX",LEFT(K8,2)="W|"),2*N8*O8,0) | Z8: allowance: 1.6 ft of conductor per ft2 of floor | AA8: =N8*O8
A9: A-L-0008 | B9: A | C9: Power block | D9: Lighting, receptacles and small power branch circuits (allowance) | E9: R2A | F9: R2A: unit / HRSG electrical e-house (32 x 40 ft) | G9: R2A | H9: R2A: unit / HRSG electrical e-house (32 x 40 ft) | I9: Building wire | J9: SIMpull THHN/THWN-2 600 V 1/C Cu (lighting, receptacles, small power) | K9: THHN|1/C|12 | L9: 1/C | M9: 12 | N9: 1 | O9: 1 | P9: 277 | S9: Conduit | T9: 2048 | U9: 0 | V9: =ROUNDUP((T9+U9+2*'Read Me'!$B$13)*(1+'Read Me'!$B$12),-1) | W9: =V9*N9*O9 | X9: =IF(LEFT(I9,2)="MV",2*N9*IF(L9="1/C",O9,1),0) | Y9: =IF(OR(LEFT(K9,4)="LVAX",LEFT(K9,6)="MV15AX",LEFT(K9,4)="CTAX",LEFT(K9,2)="W|"),2*N9*O9,0) | Z9: allowance: 1.6 ft of conductor per ft2 of floor | AA9: =N9*O9
A10: A-L-0009 | B10: A | C10: Power block | D10: Lighting, receptacles and small power branch circuits (allowance) | E10: R2B | F10: R2B: unit / HRSG electrical e-house (32 x 40 ft) | G10: R2B | H10: R2B: unit / HRSG electrical e-house (32 x 40 ft) | I10: Building wire | J10: SIMpull THHN/THWN-2 600 V 1/C Cu (lighting, receptacles, small power) | K10: THHN|1/C|12 | L10: 1/C | M10: 12 | N10: 1 | O10: 1 | P10: 277 | S10: Conduit | T10: 2048 | U10: 0 | V10: =ROUNDUP((T10+U10+2*'Read Me'!$B$13)*(1+'Read Me'!$B$12),-1) | W10: =V10*N10*O10 | X10: =IF(LEFT(I10,2)="MV",2*N10*IF(L10="1/C",O10,1),0) | Y10: =IF(OR(LEFT(K10,4)="LVAX",LEFT(K10,6)="MV15AX",LEFT(K10,4)="CTAX",LEFT(K10,2)="W|"),2*N10*O10,0) | Z10: allowance: 1.6 ft of conductor per ft2 of floor | AA10: =N10*O10
A11: A-L-0010 | B11: A | C11: Power block | D11: Lighting, receptacles and small power branch circuits (allowance) | E11: R2C | F11: R2C: unit / HRSG electrical e-house (32 x 40 ft) | G11: R2C | H11: R2C: unit / HRSG electrical e-house (32 x 40 ft) | I11: Building wire | J11: SIMpull THHN/THWN-2 600 V 1/C Cu (lighting, receptacles, small power) | K11: THHN|1/C|12 | L11: 1/C | M11: 12 | N11: 1 | O11: 1 | P11: 277 | S11: Conduit | T11: 2048 | U11: 0 | V11: =ROUNDUP((T11+U11+2*'Read Me'!$B$13)*(1+'Read Me'!$B$12),-1) | W11: =V11*N11*O11 | X11: =IF(LEFT(I11,2)="MV",2*N11*IF(L11="1/C",O11,1),0) | Y11: =IF(OR(LEFT(K11,4)="LVAX",LEFT(K11,6)="MV15AX",LEFT(K11,4)="CTAX",LEFT(K11,2)="W|"),2*N11*O11,0) | Z11: allowance: 1.6 ft of conductor per ft2 of floor | AA11: =N11*O11
A12: A-L-0011 | B12: A | C12: Power block | D12: Lighting, receptacles and small power branch circuits (allowance) | E12: R3 | F12: R3: ST auxiliary electrical e-house (40 x 65 ft) | G12: R3 | H12: R3: ST auxiliary electrical e-house (40 x 65 ft) | I12: Building wire | J12: SIMpull THHN/THWN-2 600 V 1/C Cu (lighting, receptacles, small power) | K12: THHN|1/C|12 | L12: 1/C | M12: 12 | N12: 1 | O12: 1 | P12: 277 | S12: Conduit | T12: 4160 | U12: 0 | V12: =ROUNDUP((T12+U12+2*'Read Me'!$B$13)*(1+'Read Me'!$B$12),-1) | W12: =V12*N12*O12 | X12: =IF(LEFT(I12,2)="MV",2*N12*IF(L12="1/C",O12,1),0) | Y12: =IF(OR(LEFT(K12,4)="LVAX",LEFT(K12,6)="MV15AX",LEFT(K12,4)="CTAX",LEFT(K12,2)="W|"),2*N12*O12,0) | Z12: allowance: 1.6 ft of conductor per ft2 of floor | AA12: =N12*O12
A13: A-C-0001 | B13: A | C13: Power block | D13: Motor 1 of 3: control / local station | E13: R3 | F13: R3: ST auxiliary electrical e-house (40 x 65 ft) | G13: AC-A/B/C | H13: Air compressors AC-A/B/C | I13: Control | J13: ARMOR-X MC-HL 600 V control, Cu #14 AWG (Class I Div 2) | K13: CTAX|7/C|14 | L13: 7/C | M13: 14 | N13: 1 | O13: 1 | S13: Tray | T13: 88 | U13: 84 | V13: =ROUNDUP((T13+U13+2*'Read Me'!$B$13)*(1+'Read Me'!$B$12),-1) | W13: =V13*N13*O13 | X13: =IF(LEFT(I13,2)="MV",2*N13*IF(L13="1/C",O13,1),0) | Y13: =IF(OR(LEFT(K13,4)="LVAX",LEFT(K13,6)="MV15AX",LEFT(K13,4)="CTAX",LEFT(K13,2)="W|"),2*N13*O13,0) | AA13: =N13*O13
A14: A-C-0002 | B14: A | C14: Power block | D14: Motor 2 of 3: control / local station | E14: R3 | F14: R3: ST auxiliary electrical e-house (40 x 65 ft) | G14: AC-A/B/C | H14: Air compressors AC-A/B/C | I14: Control | J14: ARMOR-X MC-HL 600 V control, Cu #14 AWG (Class I Div 2) | K14: CTAX|7/C|14 | L14: 7/C | M14: 14 | N14: 1 | O14: 1 | S14: Tray | T14: 88 | U14: 84 | V14: =ROUNDUP((T14+U14+2*'Read Me'!$B$13)*(1+'Read Me'!$B$12),-1) | W14: =V14*N14*O14 | X14: =IF(LEFT(I14,2)="MV",2*N14*IF(L14="1/C",O14,1),0) | Y14: =IF(OR(LEFT(K14,4)="LVAX",LEFT(K14,6)="MV15AX",LEFT(K14,4)="CTAX",LEFT(K14,2)="W|"),2*N14*O14,0) | AA14: =N14*O14
A15: A-C-0003 | B15: A | C15: Power block | D15: Motor 3 of 3: control / local station | E15: R3 | F15: R3: ST auxiliary electrical e-house (40 x 65 ft) | G15: AC-A/B/C | H15: Air compressors AC-A/B/C | I15: Control | J15: ARMOR-X MC-HL 600 V control, Cu #14 AWG (Class I Div 2) | K15: CTAX|7/C|14 | L15: 7/C | M15: 14 | N15: 1 | O15: 1 | S15: Tray | T15: 88 | U15: 84 | V15: =ROUNDUP((T15+U15+2*'Read Me'!$B$13)*(1+'Read Me'!$B$12),-1) | W15: =V15*N15*O15 | X15: =IF(LEFT(I15,2)="MV",2*N15*IF(L15="1/C",O15,1),0) | Y15: =IF(OR(LEFT(K15,4)="LVAX",LEFT(K15,6)="MV15AX",LEFT(K15,4)="CTAX",LEFT(K15,2)="W|"),2*N15*O15,0) | AA15: =N15*O15
A16: A-C-0004 | B16: A | C16: Power block | D16: Motor 1 of 4: control / local station | E16: R2A | F16: R2A: unit / HRSG electrical e-house (32 x 40 ft) | G16: BFP-1 | H16: BFP-1A/B: boiler feed pumps (13.8 kV DOL) | I16: Control | J16: Control cable 600 V Type TC-ER, Cu #14 AWG, PVC jacket | K16: CT|7/C|14 | L16: 7/C | M16: 14 | N16: 1 | O16: 1 | S16: Tray | T16: 481 | U16: 84 | V16: =ROUNDUP((T16+U16+2*'Read Me'!$B$13)*(1+'Read Me'!$B$12),-1) | W16: =V16*N16*O16 | X16: =IF(LEFT(I16,2)="MV",2*N16*IF(L16="1/C",O16,1),0) | Y16: =IF(OR(LEFT(K16,4)="LVAX",LEFT(K16,6)="MV15AX",LEFT(K16,4)="CTAX",LEFT(K16,2)="W|"),2*N16*O16,0) | AA16: =N16*O16
A17: A-C-0005 | B17: A | C17: Power block | D17: Motor 2 of 4: control / local station | E17: R2A | F17: R2A: unit / HRSG electrical e-house (32 x 40 ft) | G17: BFP-1 | H17: BFP-1A/B: boiler feed pumps (13.8 kV DOL) | I17: Control | J17: Control cable 600 V Type TC-ER, Cu #14 AWG, PVC jacket | K17: CT|7/C|14 | L17: 7/C | M17: 14 | N17: 1 | O17: 1 | S17: Tray | T17: 481 | U17: 84 | V17: =ROUNDUP((T17+U17+2*'Read Me'!$B$13)*(1+'Read Me'!$B$12),-1) | W17: =V17*N17*O17 | X17: =IF(LEFT(I17,2)="MV",2*N17*IF(L17="1/C",O17,1),0) | Y17: =IF(OR(LEFT(K17,4)="LVAX",LEFT(K17,6)="MV15AX",LEFT(K17,4)="CTAX",LEFT(K17,2)="W|"),2*N17*O17,0) | AA17: =N17*O17
A18: A-C-0006 | B18: A | C18: Power block | D18: Motor 3 of 4: control / local station | E18: R2A | F18: R2A: unit / HRSG electrical e-house (32 x 40 ft) | G18: BFP-1 | H18: BFP-1A/B: boiler feed pumps (13.8 kV DOL) | I18: Control | J18: Control cable 600 V Type TC-ER, Cu #14 AWG, PVC jacket | K18: CT|7/C|14 | L18: 7/C | M18: 14 | N18: 1 | O18: 1 | S18: Tray | T18: 481 | U18: 84 | V18: =ROUNDUP((T18+U18+2*'Read Me'!$B$13)*(1+'Read Me'!$B$12),-1) | W18: =V18*N18*O18 | X18: =IF(LEFT(I18,2)="MV",2*N18*IF(L18="1/C",O18,1),0) | Y18: =IF(OR(LEFT(K18,4)="LVAX",LEFT(K18,6)="MV15AX",LEFT(K18,4)="CTAX",LEFT(K18,2)="W|"),2*N18*O18,0) | AA18: =N18*O18
A19: A-C-0007 | B19: A | C19: Power block | D19: Motor 4 of 4: control / local station | E19: R2A | F19: R2A: unit / HRSG electrical e-house (32 x 40 ft) | G19: BFP-1 | H19: BFP-1A/B: boiler feed pumps (13.8 kV DOL) | I19: Control | J19: Control cable 600 V Type TC-ER, Cu #14 AWG, PVC jacket | K19: CT|7/C|14 | L19: 7/C | M19: 14 | N19: 1 | O19: 1 | S19: Tray | T19: 481 | U19: 84 | V19: =ROUNDUP((T19+U19+2*'Read Me'!$B$13)*(1+'Read Me'!$B$12),-1) | W19: =V19*N19*O19 | X19: =IF(LEFT(I19,2)="MV",2*N19*IF(L19="1/C",O19,1),0) | Y19: =IF(OR(LEFT(K19,4)="LVAX",LEFT(K19,6)="MV15AX",LEFT(K19,4)="CTAX",LEFT(K19,2)="W|"),2*N19*O19,0) | AA19: =N19*O19
A20: A-C-0008 | B20: A | C20: Power block | D20: Motor 1 of 4: control / local station | E20: R2B | F20: R2B: unit / HRSG electrical e-house (32 x 40 ft) | G20: BFP-2 | H20: BFP-2A/B: boiler feed pumps (13.8 kV DOL) | I20: Control | J20: Control cable 600 V Type TC-ER, Cu #14 AWG, PVC jacket | K20: CT|7/C|14 | L20: 7/C | M20: 14 | N20: 1 | O20: 1 | S20: Tray | T20: 479 | U20: 84 | V20: =ROUNDUP((T20+U20+2*'Read Me'!$B$13)*(1+'Read Me'!$B$12),-1) | W20: =V20*N20*O20 | X20: =IF(LEFT(I20,2)="MV",2*N20*IF(L20="1/C",O20,1),0) | Y20: =IF(OR(LEFT(K20,4)="LVAX",LEFT(K20,6)="MV15AX",LEFT(K20,4)="CTAX",LEFT(K20,2)="W|"),2*N20*O20,0) | AA20: =N20*O20
A21: A-C-0009 | B21: A | C21: Power block | D21: Motor 2 of 4: control / local station | E21: R2B | F21: R2B: unit / HRSG electrical e-house (32 x 40 ft) | G21: BFP-2 | H21: BFP-2A/B: boiler feed pumps (13.8 kV DOL) | I21: Control | J21: Control cable 600 V Type TC-ER, Cu #14 AWG, PVC jacket | K21: CT|7/C|14 | L21: 7/C | M21: 14 | N21: 1 | O21: 1 | S21: Tray | T21: 479 | U21: 84 | V21: =ROUNDUP((T21+U21+2*'Read Me'!$B$13)*(1+'Read Me'!$B$12),-1) | W21: =V21*N21*O21 | X21: =IF(LEFT(I21,2)="MV",2*N21*IF(L21="1/C",O21,1),0) | Y21: =IF(OR(LEFT(K21,4)="LVAX",LEFT(K21,6)="MV15AX",LEFT(K21,4)="CTAX",LEFT(K21,2)="W|"),2*N21*O21,0) | AA21: =N21*O21
A22: A-C-0010 | B22: A | C22: Power block | D22: Motor 3 of 4: control / local station | E22: R2B | F22: R2B: unit / HRSG electrical e-house (32 x 40 ft) | G22: BFP-2 | H22: BFP-2A/B: boiler feed pumps (13.8 kV DOL) | I22: Control | J22: Control cable 600 V Type TC-ER, Cu #14 AWG, PVC jacket | K22: CT|7/C|14 | L22: 7/C | M22: 14 | N22: 1 | O22: 1 | S22: Tray | T22: 479 | U22: 84 | V22: =ROUNDUP((T22+U22+2*'Read Me'!$B$13)*(1+'Read Me'!$B$12),-1) | W22: =V22*N22*O22 | X22: =IF(LEFT(I22,2)="MV",2*N22*IF(L22="1/C",O22,1),0) | Y22: =IF(OR(LEFT(K22,4)="LVAX",LEFT(K22,6)="MV15AX",LEFT(K22,4)="CTAX",LEFT(K22,2)="W|"),2*N22*O22,0) | AA22: =N22*O22
A23: A-C-0011 | B23: A | C23: Power block | D23: Motor 4 of 4: control / local station | E23: R2B | F23: R2B: unit / HRSG electrical e-house (32 x 40 ft) | G23: BFP-2 | H23: BFP-2A/B: boiler feed pumps (13.8 kV DOL) | I23: Control | J23: Control cable 600 V Type TC-ER, Cu #14 AWG, PVC jacket | K23: CT|7/C|14 | L23: 7/C | M23: 14 | N23: 1 | O23: 1 | S23: Tray | T23: 479 | U23: 84 | V23: =ROUNDUP((T23+U23+2*'Read Me'!$B$13)*(1+'Read Me'!$B$12),-1) | W23: =V23*N23*O23 | X23: =IF(LEFT(I23,2)="MV",2*N23*IF(L23="1/C",O23,1),0) | Y23: =IF(OR(LEFT(K23,4)="LVAX",LEFT(K23,6)="MV15AX",LEFT(K23,4)="CTAX",LEFT(K23,2)="W|"),2*N23*O23,0) | AA23: =N23*O23
A24: A-C-0012 | B24: A | C24: Power block | D24: Motor 1 of 4: control / local station | E24: R2C | F24: R2C: unit / HRSG electrical e-house (32 x 40 ft) | G24: BFP-3 | H24: BFP-3A/B: boiler feed pumps (13.8 kV DOL) | I24: Control | J24: Control cable 600 V Type TC-ER, Cu #14 AWG, PVC jacket | K24: CT|7/C|14 | L24: 7/C | M24: 14 | N24: 1 | O24: 1 | S24: Tray | T24: 481 | U24: 84 | V24: =ROUNDUP((T24+U24+2*'Read Me'!$B$13)*(1+'Read Me'!$B$12),-1) | W24: =V24*N24*O24 | X24: =IF(LEFT(I24,2)="MV",2*N24*IF(L24="1/C",O24,1),0) | Y24: =IF(OR(LEFT(K24,4)="LVAX",LEFT(K24,6)="MV15AX",LEFT(K24,4)="CTAX",LEFT(K24,2)="W|"),2*N24*O24,0) | AA24: =N24*O24
... A42: A-C-0030 | B42: A | C42: Power block | D42: Motor 2 of 2: control / local station | E42: R3 | F42: R3: ST auxiliary electrical e-house (40 x 65 ft) | G42: EHC-ST | H42: EHC-ST: ST electro-hydraulic control power unit | I42: Control | J42: Control cable 600 V Type TC-ER, Cu #14 AWG, PVC jacket | K42: CT|7/C|14 | L42: 7/C | M42: 14 | N42: 1 | O42: 1 | S42: Tray | T42: 67 | U42: 89 | V42: =ROUNDUP((T42+U42+2*'Read Me'!$B$13)*(1+'Read Me'!$B$12),-1) | W42: =V42*N42*O42 | X42: =IF(LEFT(I42,2)="MV",2*N42*IF(L42="1/C",O42,1),0) | Y42: =IF(OR(LEFT(K42,4)="LVAX",LEFT(K42,6)="MV15AX",LEFT(K42,4)="CTAX",LEFT(K42,2)="W|"),2*N42*O42,0) | AA42: =N42*O42
A43: A-C-0031 | B43: A | C43: Power block | D43: Solenoid to JB JB-EHC-ST-SOL01: 10 x 2/C (field cables) | E43: EHC-ST | F43: EHC-ST: ST electro-hydraulic control power unit | G43: JB-EHC-ST-SOL01 | H43: EHC-ST: ST electro-hydraulic control power unit | I43: Control | J43: Control cable 600 V Type TC-ER, Cu #14 AWG, PVC jacket | K43: CT|2/C|14 | L43: 2/C | M43: 14 | N43: 10 | O43: 1 | S43: Tray / conduit | T43: 53 | U43: 10 | V43: =ROUNDUP((T43+U43+2*'Read Me'!$B$13)*(1+'Read Me'!$B$12),-1) | W43: =V43*N43*O43 | X43: =IF(LEFT(I43,2)="MV",2*N43*IF(L43="1/C",O43,1),0) | Y43: =IF(OR(LEFT(K43,4)="LVAX",LEFT(K43,6)="MV15AX",LEFT(K43,4)="CTAX",LEFT(K43,2)="W|"),2*N43*O43,0) | Z43: device-to-JB field wiring, one cable per device | AA43: =N43*O43
A44: A-C-0032 | B44: A | C44: Power block | D44: Home run JB-EHC-ST-SOL01 to the control / marshalling room | E44: R3 | F44: R3: ST auxiliary electrical e-house (40 x 65 ft) | G44: JB-EHC-ST-SOL01 | H44: EHC-ST: ST electro-hydraulic control power unit | I44: Control | J44: Control cable 600 V Type TC-ER, Cu #14 AWG, PVC jacket | K44: CT|25/C|14 | L44: 25/C | M44: 14 | N44: 1 | O44: 1 | S44: Tray | T44: 67 | U44: 89 | V44: =ROUNDUP((T44+U44+2*'Read Me'!$B$13)*(1+'Read Me'!$B$12),-1) | W44: =V44*N44*O44 | X44: =IF(LEFT(I44,2)="MV",2*N44*IF(L44="1/C",O44,1),0) | Y44: =IF(OR(LEFT(K44,4)="LVAX",LEFT(K44,6)="MV15AX",LEFT(K44,4)="CTAX",LEFT(K44,2)="W|"),2*N44*O44,0) | AA44: =N44*O44
A45: A-C-0033 | B45: A | C45: Power block | D45: Control | E45: R2A | F45: R2A: unit / HRSG electrical e-house (32 x 40 ft) | G45: ET-1 | H45: ET-1: excitation transformer (dry type, GTG-1 terminals) | I45: Control | J45: Control cable 600 V Type TC-ER, Cu #14 AWG, PVC jacket | K45: CT|7/C|14 | L45: 7/C | M45: 14 | N45: 1 | O45: 1 | S45: Tray | T45: 403 | U45: 119 | V45: =ROUNDUP((T45+U45+2*'Read Me'!$B$13)*(1+'Read Me'!$B$12),-1) | W45: =V45*N45*O45 | X45: =IF(LEFT(I45,2)="MV",2*N45*IF(L45="1/C",O45,1),0) | Y45: =IF(OR(LEFT(K45,4)="LVAX",LEFT(K45,6)="MV15AX",LEFT(K45,4)="CTAX",LEFT(K45,2)="W|"),2*N45*O45,0) | AA45: =N45*O45
A46: A-C-0034 | B46: A | C46: Power block | D46: Control | E46: R2A | F46: R2A: unit / HRSG electrical e-house (32 x 40 ft) | G46: ET-1 | H46: ET-1: excitation transformer (dry type, GTG-1 terminals) | I46: Control | J46: Control cable 600 V Type TC-ER, Cu #14 AWG, PVC jacket | K46: CT|12/C|14 | L46: 12/C | M46: 14 | N46: 1 | O46: 1 | S46: Tray | T46: 403 | U46: 119 | V46: =ROUNDUP((T46+U46+2*'Read Me'!$B$13)*(1+'Read Me'!$B$12),-1) | W46: =V46*N46*O46 | X46: =IF(LEFT(I46,2)="MV",2*N46*IF(L46="1/C",O46,1),0) | Y46: =IF(OR(LEFT(K46,4)="LVAX",LEFT(K46,6)="MV15AX",LEFT(K46,4)="CTAX",LEFT(K46,2)="W|"),2*N46*O46,0) | AA46: =N46*O46
A47: A-C-0035 | B47: A | C47: Power block | D47: CT / VT | E47: R2A | F47: R2A: unit / HRSG electrical e-house (32 x 40 ft) | G47: ET-1 | H47: ET-1: excitation transformer (dry type, GTG-1 terminals) | I47: Control | J47: Control cable 600 V Type TC-ER, Cu #10 AWG (CT / VT circuits) | K47: CTCT|4/C|10 | L47: 4/C | M47: 10 | N47: 1 | O47: 1 | S47: Tray | T47: 403 | U47: 119 | V47: =ROUNDUP((T47+U47+2*'Read Me'!$B$13)*(1+'Read Me'!$B$12),-1) | W47: =V47*N47*O47 | X47: =IF(LEFT(I47,2)="MV",2*N47*IF(L47="1/C",O47,1),0) | Y47: =IF(OR(LEFT(K47,4)="LVAX",LEFT(K47,6)="MV15AX",LEFT(K47,4)="CTAX",LEFT(K47,2)="W|"),2*N47*O47,0) | AA47: =N47*O47
A48: A-C-0036 | B48: A | C48: Power block | D48: CT / VT | E48: R2A | F48: R2A: unit / HRSG electrical e-house (32 x 40 ft) | G48: ET-1 | H48: ET-1: excitation transformer (dry type, GTG-1 terminals) | I48: Control | J48: Control cable 600 V Type TC-ER, Cu #10 AWG (CT / VT circuits) | K48: CTCT|4/C|10 | L48: 4/C | M48: 10 | N48: 1 | O48: 1 | S48: Tray | T48: 403 | U48: 119 | V48: =ROUNDUP((T48+U48+2*'Read Me'!$B$13)*(1+'Read Me'!$B$12),-1) | W48: =V48*N48*O48 | X48: =IF(LEFT(I48,2)="MV",2*N48*IF(L48="1/C",O48,1),0) | Y48: =IF(OR(LEFT(K48,4)="LVAX",LEFT(K48,6)="MV15AX",LEFT(K48,4)="CTAX",LEFT(K48,2)="W|"),2*N48*O48,0) | AA48: =N48*O48
A49: A-C-0037 | B49: A | C49: Power block | D49: Control | E49: R2B | F49: R2B: unit / HRSG electrical e-house (32 x 40 ft) | G49: ET-2 | H49: ET-2: excitation transformer (dry type, GTG-2 terminals) | I49: Control | J49: Control cable 600 V Type TC-ER, Cu #14 AWG, PVC jacket | K49: CT|7/C|14 | L49: 7/C | M49: 14 | N49: 1 | O49: 1 | S49: Tray | T49: 1277 | U49: 209 | V49: =ROUNDUP((T49+U49+2*'Read Me'!$B$13)*(1+'Read Me'!$B$12),-1) | W49: =V49*N49*O49 | X49: =IF(LEFT(I49,2)="MV",2*N49*IF(L49="1/C",O49,1),0) | Y49: =IF(OR(LEFT(K49,4)="LVAX",LEFT(K49,6)="MV15AX",LEFT(K49,4)="CTAX",LEFT(K49,2)="W|"),2*N49*O49,0) | AA49: =N49*O49
A50: A-C-0038 | B50: A | C50: Power block | D50: Control | E50: R2B | F50: R2B: unit / HRSG electrical e-house (32 x 40 ft) | G50: ET-2 | H50: ET-2: excitation transformer (dry type, GTG-2 terminals) | I50: Control | J50: Control cable 600 V Type TC-ER, Cu #14 AWG, PVC jacket | K50: CT|12/C|14 | L50: 12/C | M50: 14 | N50: 1 | O50: 1 | S50: Tray | T50: 1277 | U50: 209 | V50: =ROUNDUP((T50+U50+2*'Read Me'!$B$13)*(1+'Read Me'!$B$12),-1) | W50: =V50*N50*O50 | X50: =IF(LEFT(I50,2)="MV",2*N50*IF(L50="1/C",O50,1),0) | Y50: =IF(OR(LEFT(K50,4)="LVAX",LEFT(K50,6)="MV15AX",LEFT(K50,4)="CTAX",LEFT(K50,2)="W|"),2*N50*O50,0) | AA50: =N50*O50
A51: A-C-0039 | B51: A | C51: Power block | D51: CT / VT | E51: R2B | F51: R2B: unit / HRSG electrical e-house (32 x 40 ft) | G51: ET-2 | H51: ET-2: excitation transformer (dry type, GTG-2 terminals) | I51: Control | J51: Control cable 600 V Type TC-ER, Cu #10 AWG (CT / VT circuits) | K51: CTCT|4/C|10 | L51: 4/C | M51: 10 | N51: 1 | O51: 1 | S51: Tray | T51: 1277 | U51: 209 | V51: =ROUNDUP((T51+U51+2*'Read Me'!$B$13)*(1+'Read Me'!$B$12),-1) | W51: =V51*N51*O51 | X51: =IF(LEFT(I51,2)="MV",2*N51*IF(L51="1/C",O51,1),0) | Y51: =IF(OR(LEFT(K51,4)="LVAX",LEFT(K51,6)="MV15AX",LEFT(K51,4)="CTAX",LEFT(K51,2)="W|"),2*N51*O51,0) | AA51: =N51*O51
A52: A-C-0040 | B52: A | C52: Power block | D52: CT / VT | E52: R2B | F52: R2B: unit / HRSG electrical e-house (32 x 40 ft) | G52: ET-2 | H52: ET-2: excitation transformer (dry type, GTG-2 terminals) | I52: Control | J52: Control cable 600 V Type TC-ER, Cu #10 AWG (CT / VT circuits) | K52: CTCT|4/C|10 | L52: 4/C | M52: 10 | N52: 1 | O52: 1 | S52: Tray | T52: 1277 | U52: 209 | V52: =ROUNDUP((T52+U52+2*'Read Me'!$B$13)*(1+'Read Me'!$B$12),-1) | W52: =V52*N52*O52 | X52: =IF(LEFT(I52,2)="MV",2*N52*IF(L52="1/C",O52,1),0) | Y52: =IF(OR(LEFT(K52,4)="LVAX",LEFT(K52,6)="MV15AX",LEFT(K52,4)="CTAX",LEFT(K52,2)="W|"),2*N52*O52,0) | AA52: =N52*O52
A53: A-C-0041 | B53: A | C53: Power block | D53: Control | E53: R2C | F53: R2C: unit / HRSG electrical e-house (32 x 40 ft) | G53: ET-3 | H53: ET-3: excitation transformer (dry type, GTG-3 terminals) | I53: Control | J53: Control cable 600 V Type TC-ER, Cu #14 AWG, PVC jacket | K53: CT|7/C|14 | L53: 7/C | M53: 14 | N53: 1 | O53: 1 | S53: Duct bank | T53: 1214 | U53: 102 | V53: =ROUNDUP((T53+U53+2*'Read Me'!$B$13)*(1+'Read Me'!$B$12),-1) | W53: =V53*N53*O53 | X53: =IF(LEFT(I53,2)="MV",2*N53*IF(L53="1/C",O53,1),0) | Y53: =IF(OR(LEFT(K53,4)="LVAX",LEFT(K53,6)="MV15AX",LEFT(K53,4)="CTAX",LEFT(K53,2)="W|"),2*N53*O53,0) | AA53: =N53*O53
A54: A-C-0042 | B54: A | C54: Power block | D54: Control | E54: R2C | F54: R2C: unit / HRSG electrical e-house (32 x 40 ft) | G54: ET-3 | H54: ET-3: excitation transformer (dry type, GTG-3 terminals) | I54: Control | J54: Control cable 600 V Type TC-ER, Cu #14 AWG, PVC jacket | K54: CT|12/C|14 | L54: 12/C | M54: 14 | N54: 1 | O54: 1 | S54: Duct bank | T54: 1214 | U54: 102 | V54: =ROUNDUP((T54+U54+2*'Read Me'!$B$13)*(1+'Read Me'!$B$12),-1) | W54: =V54*N54*O54 | X54: =IF(LEFT(I54,2)="MV",2*N54*IF(L54="1/C",O54,1),0) | Y54: =IF(OR(LEFT(K54,4)="LVAX",LEFT(K54,6)="MV15AX",LEFT(K54,4)="CTAX",LEFT(K54,2)="W|"),2*N54*O54,0) | AA54: =N54*O54
A55: A-C-0043 | B55: A | C55: Power block | D55: CT / VT | E55: R2C | F55: R2C: unit / HRSG electrical e-house (32 x 40 ft) | G55: ET-3 | H55: ET-3: excitation transformer (dry type, GTG-3 terminals) | I55: Control | J55: Control cable 600 V Type TC-ER, Cu #10 AWG (CT / VT circuits) | K55: CTCT|4/C|10 | L55: 4/C | M55: 10 | N55: 1 | O55: 1 | S55: Duct bank | T55: 1214 | U55: 102 | V55: =ROUNDUP((T55+U55+2*'Read Me'!$B$13)*(1+'Read Me'!$B$12),-1) | W55: =V55*N55*O55 | X55: =IF(LEFT(I55,2)="MV",2*N55*IF(L55="1/C",O55,1),0) | Y55: =IF(OR(LEFT(K55,4)="LVAX",LEFT(K55,6)="MV15AX",LEFT(K55,4)="CTAX",LEFT(K55,2)="W|"),2*N55*O55,0) | AA55: =N55*O55
... A58: A-C-0046 | B58: A | C58: Power block | D58: Motor 2 of 2: control / local station | E58: MCC-GT1 | F58: R1 MCC-GT1 | G58: FH-1 | H58: FH-1: GT inlet filter house on its own frame | I58: Control | J58: Control cable 600 V Type TC-ER, Cu #14 AWG, PVC jacket | K58: CT|7/C|14 | L58: 7/C | M58: 14 | N58: 1 | O58: 1 | S58: Tray | T58: 451 | U58: 157 | V58: =ROUNDUP((T58+U58+2*'Read Me'!$B$13)*(1+'Read Me'!$B$12),-1) | W58: =V58*N58*O58 | X58: =IF(LEFT(I58,2)="MV",2*N58*IF(L58="1/C",O58,1),0) | Y58: =IF(OR(LEFT(K58,4)="LVAX",LEFT(K58,6)="MV15AX",LEFT(K58,4)="CTAX",LEFT(K58,2)="W|"),2*N58*O58,0) | AA58: =N58*O58
A59: A-C-0047 | B59: A | C59: Power block | D59: Solenoid to JB JB-FH-1-SOL01: 10 x 2/C (field cables) | E59: FH-1 | F59: FH-1: GT inlet filter house on its own frame | G59: JB-FH-1-SOL01 | H59: FH-1: GT inlet filter house on its own frame | I59: Control | J59: Control cable 600 V Type TC-ER, Cu #14 AWG, PVC jacket | K59: CT|2/C|14 | L59: 2/C | M59: 14 | N59: 10 | O59: 1 | S59: Tray / conduit | T59: 140 | U59: 10 | V59: =ROUNDUP((T59+U59+2*'Read Me'!$B$13)*(1+'Read Me'!$B$12),-1) | W59: =V59*N59*O59 | X59: =IF(LEFT(I59,2)="MV",2*N59*IF(L59="1/C",O59,1),0) | Y59: =IF(OR(LEFT(K59,4)="LVAX",LEFT(K59,6)="MV15AX",LEFT(K59,4)="CTAX",LEFT(K59,2)="W|"),2*N59*O59,0) | Z59: device-to-JB field wiring, one cable per device | AA59: =N59*O59
...

Sheet Cable BOM
A1: Product key | B1: Class | C1: Product (typical Southwire family) | D1: Conductors | E1: Size | F1: Cables | G1: Total length (ft) | H1: Waste | I1: Order length (ft) | J1: Standard reel (ft) | K1: Reels | L1: Order length (km)
A2: MV15|1/C|2 | B2: MV 15 kV | C2: MV-105 15 kV 1/C Cu, EPR 133%, Cu tape shield, PVC jacket (triplexed) | D2: 1/C | E2: 2 | F2: =SUMIFS('Cable Schedule'!$AA$2:$AA$5696,'Cable Schedule'!$K$2:$K$5696,A2) | G2: =SUMIFS('Cable Schedule'!$W$2:$W$5696,'Cable Schedule'!$K$2:$K$5696,A2) | H2: ='Read Me'!$B$14 | I2: =ROUNDUP(G2*(1+H2),-2) | J2: 2500 | K2: =IF(J2>0,ROUNDUP(I2/J2,0),0) | L2: =I2*0.3048/1000
A3: MV15|1/C|1/0 | B3: MV 15 kV | C3: MV-105 15 kV 1/C Cu, EPR 133%, Cu tape shield, PVC jacket (triplexed) | D3: 1/C | E3: 1/0 | F3: =SUMIFS('Cable Schedule'!$AA$2:$AA$5696,'Cable Schedule'!$K$2:$K$5696,A3) | G3: =SUMIFS('Cable Schedule'!$W$2:$W$5696,'Cable Schedule'!$K$2:$K$5696,A3) | H3: ='Read Me'!$B$14 | I3: =ROUNDUP(G3*(1+H3),-2) | J3: 2500 | K3: =IF(J3>0,ROUNDUP(I3/J3,0),0) | L3: =I3*0.3048/1000
A4: MV15|1/C|2/0 | B4: MV 15 kV | C4: MV-105 15 kV 1/C Cu, EPR 133%, Cu tape shield, PVC jacket (triplexed) | D4: 1/C | E4: 2/0 | F4: =SUMIFS('Cable Schedule'!$AA$2:$AA$5696,'Cable Schedule'!$K$2:$K$5696,A4) | G4: =SUMIFS('Cable Schedule'!$W$2:$W$5696,'Cable Schedule'!$K$2:$K$5696,A4) | H4: ='Read Me'!$B$14 | I4: =ROUNDUP(G4*(1+H4),-2) | J4: 2500 | K4: =IF(J4>0,ROUNDUP(I4/J4,0),0) | L4: =I4*0.3048/1000
A5: MV15|1/C|4/0 | B5: MV 15 kV | C5: MV-105 15 kV 1/C Cu, EPR 133%, Cu tape shield, PVC jacket (triplexed) | D5: 1/C | E5: 4/0 | F5: =SUMIFS('Cable Schedule'!$AA$2:$AA$5696,'Cable Schedule'!$K$2:$K$5696,A5) | G5: =SUMIFS('Cable Schedule'!$W$2:$W$5696,'Cable Schedule'!$K$2:$K$5696,A5) | H5: ='Read Me'!$B$14 | I5: =ROUNDUP(G5*(1+H5),-2) | J5: 2500 | K5: =IF(J5>0,ROUNDUP(I5/J5,0),0) | L5: =I5*0.3048/1000
A6: MV15|1/C|250 | B6: MV 15 kV | C6: MV-105 15 kV 1/C Cu, EPR 133%, Cu tape shield, PVC jacket (triplexed) | D6: 1/C | E6: 250 kcmil | F6: =SUMIFS('Cable Schedule'!$AA$2:$AA$5696,'Cable Schedule'!$K$2:$K$5696,A6) | G6: =SUMIFS('Cable Schedule'!$W$2:$W$5696,'Cable Schedule'!$K$2:$K$5696,A6) | H6: ='Read Me'!$B$14 | I6: =ROUNDUP(G6*(1+H6),-2) | J6: 2500 | K6: =IF(J6>0,ROUNDUP(I6/J6,0),0) | L6: =I6*0.3048/1000
A7: MV15|1/C|500 | B7: MV 15 kV | C7: MV-105 15 kV 1/C Cu, EPR 133%, Cu tape shield, PVC jacket (triplexed) | D7: 1/C | E7: 500 kcmil | F7: =SUMIFS('Cable Schedule'!$AA$2:$AA$5696,'Cable Schedule'!$K$2:$K$5696,A7) | G7: =SUMIFS('Cable Schedule'!$W$2:$W$5696,'Cable Schedule'!$K$2:$K$5696,A7) | H7: ='Read Me'!$B$14 | I7: =ROUNDUP(G7*(1+H7),-2) | J7: 2500 | K7: =IF(J7>0,ROUNDUP(I7/J7,0),0) | L7: =I7*0.3048/1000
A8: MV15|1/C|750 | B8: MV 15 kV | C8: MV-105 15 kV 1/C Cu, EPR 133%, Cu tape shield, PVC jacket (triplexed) | D8: 1/C | E8: 750 kcmil | F8: =SUMIFS('Cable Schedule'!$AA$2:$AA$5696,'Cable Schedule'!$K$2:$K$5696,A8) | G8: =SUMIFS('Cable Schedule'!$W$2:$W$5696,'Cable Schedule'!$K$2:$K$5696,A8) | H8: ='Read Me'!$B$14 | I8: =ROUNDUP(G8*(1+H8),-2) | J8: 2500 | K8: =IF(J8>0,ROUNDUP(I8/J8,0),0) | L8: =I8*0.3048/1000
A9: MV15|1/C|1000 | B9: MV 15 kV | C9: MV-105 15 kV 1/C Cu, EPR 133%, Cu tape shield, PVC jacket (triplexed) | D9: 1/C | E9: 1000 kcmil | F9: =SUMIFS('Cable Schedule'!$AA$2:$AA$5696,'Cable Schedule'!$K$2:$K$5696,A9) | G9: =SUMIFS('Cable Schedule'!$W$2:$W$5696,'Cable Schedule'!$K$2:$K$5696,A9) | H9: ='Read Me'!$B$14 | I9: =ROUNDUP(G9*(1+H9),-2) | J9: 2500 | K9: =IF(J9>0,ROUNDUP(I9/J9,0),0) | L9: =I9*0.3048/1000
A10: MV15AX|3/C|2 | B10: MV 15 kV | C10: ARMOR-X MC-HL / MV-105 15 kV 3/C Cu, EPR 133%, tape shield, gnd, CWA, red PVC | D10: 3/C | E10: 2 | F10: =SUMIFS('Cable Schedule'!$AA$2:$AA$5696,'Cable Schedule'!$K$2:$K$5696,A10) | G10: =SUMIFS('Cable Schedule'!$W$2:$W$5696,'Cable Schedule'!$K$2:$K$5696,A10) | H10: ='Read Me'!$B$14 | I10: =ROUNDUP(G10*(1+H10),-2) | J10: 2000 | K10: =IF(J10>0,ROUNDUP(I10/J10,0),0) | L10: =I10*0.3048/1000
A11: MV15AX|3/C|1/0 | B11: MV 15 kV | C11: ARMOR-X MC-HL / MV-105 15 kV 3/C Cu, EPR 133%, tape shield, gnd, CWA, red PVC | D11: 3/C | E11: 1/0 | F11: =SUMIFS('Cable Schedule'!$AA$2:$AA$5696,'Cable Schedule'!$K$2:$K$5696,A11) | G11: =SUMIFS('Cable Schedule'!$W$2:$W$5696,'Cable Schedule'!$K$2:$K$5696,A11) | H11: ='Read Me'!$B$14 | I11: =ROUNDUP(G11*(1+H11),-2) | J11: 2000 | K11: =IF(J11>0,ROUNDUP(I11/J11,0),0) | L11: =I11*0.3048/1000
A12: MV5|3/C|2 | B12: MV 5 kV | C12: MV-105 5 kV 3/C Cu, EPR 133%, tape shield, gnd, PVC jacket | D12: 3/C | E12: 2 | F12: =SUMIFS('Cable Schedule'!$AA$2:$AA$5696,'Cable Schedule'!$K$2:$K$5696,A12) | G12: =SUMIFS('Cable Schedule'!$W$2:$W$5696,'Cable Schedule'!$K$2:$K$5696,A12) | H12: ='Read Me'!$B$14 | I12: =ROUNDUP(G12*(1+H12),-2) | J12: 2500 | K12: =IF(J12>0,ROUNDUP(I12/J12,0),0) | L12: =I12*0.3048/1000
A13: MV5|3/C|1/0 | B13: MV 5 kV | C13: MV-105 5 kV 3/C Cu, EPR 133%, tape shield, gnd, PVC jacket | D13: 3/C | E13: 1/0 | F13: =SUMIFS('Cable Schedule'!$AA$2:$AA$5696,'Cable Schedule'!$K$2:$K$5696,A13) | G13: =SUMIFS('Cable Schedule'!$W$2:$W$5696,'Cable Schedule'!$K$2:$K$5696,A13) | H13: ='Read Me'!$B$14 | I13: =ROUNDUP(G13*(1+H13),-2) | J13: 2500 | K13: =IF(J13>0,ROUNDUP(I13/J13,0),0) | L13: =I13*0.3048/1000
... A82: ACSR|1/C|1590 | B82: Overhead | C82: Overhead conductor ACSR 1590 kcmil 'Falcon' (typ.) | D82: 1/C | E82: 1590 kcmil | F82: =SUMIFS('Cable Schedule'!$AA$2:$AA$5696,'Cable Schedule'!$K$2:$K$5696,A82) | G82: =SUMIFS('Cable Schedule'!$W$2:$W$5696,'Cable Schedule'!$K$2:$K$5696,A82) | H82: ='Read Me'!$B$14 | I82: =ROUNDUP(G82*(1+H82),-2) | J82: 7000 | K82: =IF(J82>0,ROUNDUP(I82/J82,0),0) | L82: =I82*0.3048/1000
C83: Total | F83: =SUM(F2:F82) | G83: =SUM(G2:G82) | I83: =SUM(I2:I82) | K83: =SUM(K2:K82) | L83: =SUM(L2:L82)
A85: Standard reel lengths are typical inputs (blue); edit to the actual reel / SIMpull reel sizes.

Sheet Accessories
A1: Accessory | B1: Quantity
A2: MV termination kits (outdoor / indoor, per conductor or per 3/C end) | B2: =SUM('Cable Schedule'!X2:X5696)
A3: ARMOR-X / Type W connectors and glands | B3: =SUM('Cable Schedule'!Y2:Y5696)
A4: MV splice kits (allowance: 1 per 2,500 ft of MV 1/C) | B4: =ROUNDUP(SUMIFS('Cable Schedule'!W2:W5696,'Cable Schedule'!I2:I5696,"MV*",'Cable Schedule'!L2:L5696,"1/C")/2500,0)
A5: 230 kV outdoor terminations | B5: =2*SUMIFS('Cable Schedule'!O2:O5696,'Cable Schedule'!I2:I5696,"HV 230 kV")
A6: 600 V compression lugs (power, 4 per end) | B6: =2*4*SUMIFS('Cable Schedule'!N2:N5696,'Cable Schedule'!I2:I5696,"LV 600 V")
A7: Instrument / control cable glands (2 per run) | B7: =2*(COUNTIF('Cable Schedule'!I2:I5696,"Control")+COUNTIF('Cable Schedule'!I2:I5696,"Instrumentation"))
A8: Fibre patch / termination (2 per link) | B8: =2*COUNTIF('Cable Schedule'!I2:I5696,"Fibre / data")
A9: Ground connections: exothermic welds (allowance 1 per 25 ft of grid) | B9: =ROUNDUP(SUMIFS('Cable Schedule'!W2:W5696,'Cable Schedule'!I2:I5696,"Grounding")/25,0)

Sheet Summary
A1: Total cable length (ft) by zone and class
A2: Zone | B2: MV 15 kV | C2: MV 5 kV | D2: MV 25 kV | E2: MV 35 kV | F2: HV 230 kV | G2: LV 600 V | H2: Control | I2: Instrumentation | J2: Fire alarm | K2: Fibre / data | L2: DC 2 kV | M2: Portable MV | N2: Portable LV | O2: Building wire | P2: Grounding | Q2: Overhead | R2: Total
A3: A Power block | B3: =SUMIFS('Cable Schedule'!$W$2:$W$5696,'Cable Schedule'!$B$2:$B$5696,"A",'Cable Schedule'!$I$2:$I$5696,"MV 15 kV") | C3: =SUMIFS('Cable Schedule'!$W$2:$W$5696,'Cable Schedule'!$B$2:$B$5696,"A",'Cable Schedule'!$I$2:$I$5696,"MV 5 kV") | D3: =SUMIFS('Cable Schedule'!$W$2:$W$5696,'Cable Schedule'!$B$2:$B$5696,"A",'Cable Schedule'!$I$2:$I$5696,"MV 25 kV") | E3: =SUMIFS('Cable Schedule'!$W$2:$W$5696,'Cable Schedule'!$B$2:$B$5696,"A",'Cable Schedule'!$I$2:$I$5696,"MV 35 kV") | F3: =SUMIFS('Cable Schedule'!$W$2:$W$5696,'Cable Schedule'!$B$2:$B$5696,"A",'Cable Schedule'!$I$2:$I$5696,"HV 230 kV") | G3: =SUMIFS('Cable Schedule'!$W$2:$W$5696,'Cable Schedule'!$B$2:$B$5696,"A",'Cable Schedule'!$I$2:$I$5696,"LV 600 V") | H3: =SUMIFS('Cable Schedule'!$W$2:$W$5696,'Cable Schedule'!$B$2:$B$5696,"A",'Cable Schedule'!$I$2:$I$5696,"Control") | I3: =SUMIFS('Cable Schedule'!$W$2:$W$5696,'Cable Schedule'!$B$2:$B$5696,"A",'Cable Schedule'!$I$2:$I$5696,"Instrumentation") | J3: =SUMIFS('Cable Schedule'!$W$2:$W$5696,'Cable Schedule'!$B$2:$B$5696,"A",'Cable Schedule'!$I$2:$I$5696,"Fire alarm") | K3: =SUMIFS('Cable Schedule'!$W$2:$W$5696,'Cable Schedule'!$B$2:$B$5696,"A",'Cable Schedule'!$I$2:$I$5696,"Fibre / data") | L3: =SUMIFS('Cable Schedule'!$W$2:$W$5696,'Cable Schedule'!$B$2:$B$5696,"A",'Cable Schedule'!$I$2:$I$5696,"DC 2 kV") | M3: =SUMIFS('Cable Schedule'!$W$2:$W$5696,'Cable Schedule'!$B$2:$B$5696,"A",'Cable Schedule'!$I$2:$I$5696,"Portable MV") | N3: =SUMIFS('Cable Schedule'!$W$2:$W$5696,'Cable Schedule'!$B$2:$B$5696,"A",'Cable Schedule'!$I$2:$I$5696,"Portable LV") | O3: =SUMIFS('Cable Schedule'!$W$2:$W$5696,'Cable Schedule'!$B$2:$B$5696,"A",'Cable Schedule'!$I$2:$I$5696,"Building wire") | P3: =SUMIFS('Cable Schedule'!$W$2:$W$5696,'Cable Schedule'!$B$2:$B$5696,"A",'Cable Schedule'!$I$2:$I$5696,"Grounding") | Q3: =SUMIFS('Cable Schedule'!$W$2:$W$5696,'Cable Schedule'!$B$2:$B$5696,"A",'Cable Schedule'!$I$2:$I$5696,"Overhead") | R3: =SUM(B3:Q3)
A4: B ACC | B4: =SUMIFS('Cable Schedule'!$W$2:$W$5696,'Cable Schedule'!$B$2:$B$5696,"B",'Cable Schedule'!$I$2:$I$5696,"MV 15 kV") | C4: =SUMIFS('Cable Schedule'!$W$2:$W$5696,'Cable Schedule'!$B$2:$B$5696,"B",'Cable Schedule'!$I$2:$I$5696,"MV 5 kV") | D4: =SUMIFS('Cable Schedule'!$W$2:$W$5696,'Cable Schedule'!$B$2:$B$5696,"B",'Cable Schedule'!$I$2:$I$5696,"MV 25 kV") | E4: =SUMIFS('Cable Schedule'!$W$2:$W$5696,'Cable Schedule'!$B$2:$B$5696,"B",'Cable Schedule'!$I$2:$I$5696,"MV 35 kV") | F4: =SUMIFS('Cable Schedule'!$W$2:$W$5696,'Cable Schedule'!$B$2:$B$5696,"B",'Cable Schedule'!$I$2:$I$5696,"HV 230 kV") | G4: =SUMIFS('Cable Schedule'!$W$2:$W$5696,'Cable Schedule'!$B$2:$B$5696,"B",'Cable Schedule'!$I$2:$I$5696,"LV 600 V") | H4: =SUMIFS('Cable Schedule'!$W$2:$W$5696,'Cable Schedule'!$B$2:$B$5696,"B",'Cable Schedule'!$I$2:$I$5696,"Control") | I4: =SUMIFS('Cable Schedule'!$W$2:$W$5696,'Cable Schedule'!$B$2:$B$5696,"B",'Cable Schedule'!$I$2:$I$5696,"Instrumentation") | J4: =SUMIFS('Cable Schedule'!$W$2:$W$5696,'Cable Schedule'!$B$2:$B$5696,"B",'Cable Schedule'!$I$2:$I$5696,"Fire alarm") | K4: =SUMIFS('Cable Schedule'!$W$2:$W$5696,'Cable Schedule'!$B$2:$B$5696,"B",'Cable Schedule'!$I$2:$I$5696,"Fibre / data") | L4: =SUMIFS('Cable Schedule'!$W$2:$W$5696,'Cable Schedule'!$B$2:$B$5696,"B",'Cable Schedule'!$I$2:$I$5696,"DC 2 kV") | M4: =SUMIFS('Cable Schedule'!$W$2:$W$5696,'Cable Schedule'!$B$2:$B$5696,"B",'Cable Schedule'!$I$2:$I$5696,"Portable MV") | N4: =SUMIFS('Cable Schedule'!$W$2:$W$5696,'Cable Schedule'!$B$2:$B$5696,"B",'Cable Schedule'!$I$2:$I$5696,"Portable LV") | O4: =SUMIFS('Cable Schedule'!$W$2:$W$5696,'Cable Schedule'!$B$2:$B$5696,"B",'Cable Schedule'!$I$2:$I$5696,"Building wire") | P4: =SUMIFS('Cable Schedule'!$W$2:$W$5696,'Cable Schedule'!$B$2:$B$5696,"B",'Cable Schedule'!$I$2:$I$5696,"Grounding") | Q4: =SUMIFS('Cable Schedule'!$W$2:$W$5696,'Cable Schedule'!$B$2:$B$5696,"B",'Cable Schedule'!$I$2:$I$5696,"Overhead") | R4: =SUM(B4:Q4)
A5: C Grid interface | B5: =SUMIFS('Cable Schedule'!$W$2:$W$5696,'Cable Schedule'!$B$2:$B$5696,"C",'Cable Schedule'!$I$2:$I$5696,"MV 15 kV") | C5: =SUMIFS('Cable Schedule'!$W$2:$W$5696,'Cable Schedule'!$B$2:$B$5696,"C",'Cable Schedule'!$I$2:$I$5696,"MV 5 kV") | D5: =SUMIFS('Cable Schedule'!$W$2:$W$5696,'Cable Schedule'!$B$2:$B$5696,"C",'Cable Schedule'!$I$2:$I$5696,"MV 25 kV") | E5: =SUMIFS('Cable Schedule'!$W$2:$W$5696,'Cable Schedule'!$B$2:$B$5696,"C",'Cable Schedule'!$I$2:$I$5696,"MV 35 kV") | F5: =SUMIFS('Cable Schedule'!$W$2:$W$5696,'Cable Schedule'!$B$2:$B$5696,"C",'Cable Schedule'!$I$2:$I$5696,"HV 230 kV") | G5: =SUMIFS('Cable Schedule'!$W$2:$W$5696,'Cable Schedule'!$B$2:$B$5696,"C",'Cable Schedule'!$I$2:$I$5696,"LV 600 V") | H5: =SUMIFS('Cable Schedule'!$W$2:$W$5696,'Cable Schedule'!$B$2:$B$5696,"C",'Cable Schedule'!$I$2:$I$5696,"Control") | I5: =SUMIFS('Cable Schedule'!$W$2:$W$5696,'Cable Schedule'!$B$2:$B$5696,"C",'Cable Schedule'!$I$2:$I$5696,"Instrumentation") | J5: =SUMIFS('Cable Schedule'!$W$2:$W$5696,'Cable Schedule'!$B$2:$B$5696,"C",'Cable Schedule'!$I$2:$I$5696,"Fire alarm") | K5: =SUMIFS('Cable Schedule'!$W$2:$W$5696,'Cable Schedule'!$B$2:$B$5696,"C",'Cable Schedule'!$I$2:$I$5696,"Fibre / data") | L5: =SUMIFS('Cable Schedule'!$W$2:$W$5696,'Cable Schedule'!$B$2:$B$5696,"C",'Cable Schedule'!$I$2:$I$5696,"DC 2 kV") | M5: =SUMIFS('Cable Schedule'!$W$2:$W$5696,'Cable Schedule'!$B$2:$B$5696,"C",'Cable Schedule'!$I$2:$I$5696,"Portable MV") | N5: =SUMIFS('Cable Schedule'!$W$2:$W$5696,'Cable Schedule'!$B$2:$B$5696,"C",'Cable Schedule'!$I$2:$I$5696,"Portable LV") | O5: =SUMIFS('Cable Schedule'!$W$2:$W$5696,'Cable Schedule'!$B$2:$B$5696,"C",'Cable Schedule'!$I$2:$I$5696,"Building wire") | P5: =SUMIFS('Cable Schedule'!$W$2:$W$5696,'Cable Schedule'!$B$2:$B$5696,"C",'Cable Schedule'!$I$2:$I$5696,"Grounding") | Q5: =SUMIFS('Cable Schedule'!$W$2:$W$5696,'Cable Schedule'!$B$2:$B$5696,"C",'Cable Schedule'!$I$2:$I$5696,"Overhead") | R5: =SUM(B5:Q5)
A6: D Fuel gas | B6: =SUMIFS('Cable Schedule'!$W$2:$W$5696,'Cable Schedule'!$B$2:$B$5696,"D",'Cable Schedule'!$I$2:$I$5696,"MV 15 kV") | C6: =SUMIFS('Cable Schedule'!$W$2:$W$5696,'Cable Schedule'!$B$2:$B$5696,"D",'Cable Schedule'!$I$2:$I$5696,"MV 5 kV") | D6: =SUMIFS('Cable Schedule'!$W$2:$W$5696,'Cable Schedule'!$B$2:$B$5696,"D",'Cable Schedule'!$I$2:$I$5696,"MV 25 kV") | E6: =SUMIFS('Cable Schedule'!$W$2:$W$5696,'Cable Schedule'!$B$2:$B$5696,"D",'Cable Schedule'!$I$2:$I$5696,"MV 35 kV") | F6: =SUMIFS('Cable Schedule'!$W$2:$W$5696,'Cable Schedule'!$B$2:$B$5696,"D",'Cable Schedule'!$I$2:$I$5696,"HV 230 kV") | G6: =SUMIFS('Cable Schedule'!$W$2:$W$5696,'Cable Schedule'!$B$2:$B$5696,"D",'Cable Schedule'!$I$2:$I$5696,"LV 600 V") | H6: =SUMIFS('Cable Schedule'!$W$2:$W$5696,'Cable Schedule'!$B$2:$B$5696,"D",'Cable Schedule'!$I$2:$I$5696,"Control") | I6: =SUMIFS('Cable Schedule'!$W$2:$W$5696,'Cable Schedule'!$B$2:$B$5696,"D",'Cable Schedule'!$I$2:$I$5696,"Instrumentation") | J6: =SUMIFS('Cable Schedule'!$W$2:$W$5696,'Cable Schedule'!$B$2:$B$5696,"D",'Cable Schedule'!$I$2:$I$5696,"Fire alarm") | K6: =SUMIFS('Cable Schedule'!$W$2:$W$5696,'Cable Schedule'!$B$2:$B$5696,"D",'Cable Schedule'!$I$2:$I$5696,"Fibre / data") | L6: =SUMIFS('Cable Schedule'!$W$2:$W$5696,'Cable Schedule'!$B$2:$B$5696,"D",'Cable Schedule'!$I$2:$I$5696,"DC 2 kV") | M6: =SUMIFS('Cable Schedule'!$W$2:$W$5696,'Cable Schedule'!$B$2:$B$5696,"D",'Cable Schedule'!$I$2:$I$5696,"Portable MV") | N6: =SUMIFS('Cable Schedule'!$W$2:$W$5696,'Cable Schedule'!$B$2:$B$5696,"D",'Cable Schedule'!$I$2:$I$5696,"Portable LV") | O6: =SUMIFS('Cable Schedule'!$W$2:$W$5696,'Cable Schedule'!$B$2:$B$5696,"D",'Cable Schedule'!$I$2:$I$5696,"Building wire") | P6: =SUMIFS('Cable Schedule'!$W$2:$W$5696,'Cable Schedule'!$B$2:$B$5696,"D",'Cable Schedule'!$I$2:$I$5696,"Grounding") | Q6: =SUMIFS('Cable Schedule'!$W$2:$W$5696,'Cable Schedule'!$B$2:$B$5696,"D",'Cable Schedule'!$I$2:$I$5696,"Overhead") | R6: =SUM(B6:Q6)
A7: E Water / utilities | B7: =SUMIFS('Cable Schedule'!$W$2:$W$5696,'Cable Schedule'!$B$2:$B$5696,"E",'Cable Schedule'!$I$2:$I$5696,"MV 15 kV") | C7: =SUMIFS('Cable Schedule'!$W$2:$W$5696,'Cable Schedule'!$B$2:$B$5696,"E",'Cable Schedule'!$I$2:$I$5696,"MV 5 kV") | D7: =SUMIFS('Cable Schedule'!$W$2:$W$5696,'Cable Schedule'!$B$2:$B$5696,"E",'Cable Schedule'!$I$2:$I$5696,"MV 25 kV") | E7: =SUMIFS('Cable Schedule'!$W$2:$W$5696,'Cable Schedule'!$B$2:$B$5696,"E",'Cable Schedule'!$I$2:$I$5696,"MV 35 kV") | F7: =SUMIFS('Cable Schedule'!$W$2:$W$5696,'Cable Schedule'!$B$2:$B$5696,"E",'Cable Schedule'!$I$2:$I$5696,"HV 230 kV") | G7: =SUMIFS('Cable Schedule'!$W$2:$W$5696,'Cable Schedule'!$B$2:$B$5696,"E",'Cable Schedule'!$I$2:$I$5696,"LV 600 V") | H7: =SUMIFS('Cable Schedule'!$W$2:$W$5696,'Cable Schedule'!$B$2:$B$5696,"E",'Cable Schedule'!$I$2:$I$5696,"Control") | I7: =SUMIFS('Cable Schedule'!$W$2:$W$5696,'Cable Schedule'!$B$2:$B$5696,"E",'Cable Schedule'!$I$2:$I$5696,"Instrumentation") | J7: =SUMIFS('Cable Schedule'!$W$2:$W$5696,'Cable Schedule'!$B$2:$B$5696,"E",'Cable Schedule'!$I$2:$I$5696,"Fire alarm") | K7: =SUMIFS('Cable Schedule'!$W$2:$W$5696,'Cable Schedule'!$B$2:$B$5696,"E",'Cable Schedule'!$I$2:$I$5696,"Fibre / data") | L7: =SUMIFS('Cable Schedule'!$W$2:$W$5696,'Cable Schedule'!$B$2:$B$5696,"E",'Cable Schedule'!$I$2:$I$5696,"DC 2 kV") | M7: =SUMIFS('Cable Schedule'!$W$2:$W$5696,'Cable Schedule'!$B$2:$B$5696,"E",'Cable Schedule'!$I$2:$I$5696,"Portable MV") | N7: =SUMIFS('Cable Schedule'!$W$2:$W$5696,'Cable Schedule'!$B$2:$B$5696,"E",'Cable Schedule'!$I$2:$I$5696,"Portable LV") | O7: =SUMIFS('Cable Schedule'!$W$2:$W$5696,'Cable Schedule'!$B$2:$B$5696,"E",'Cable Schedule'!$I$2:$I$5696,"Building wire") | P7: =SUMIFS('Cable Schedule'!$W$2:$W$5696,'Cable Schedule'!$B$2:$B$5696,"E",'Cable Schedule'!$I$2:$I$5696,"Grounding") | Q7: =SUMIFS('Cable Schedule'!$W$2:$W$5696,'Cable Schedule'!$B$2:$B$5696,"E",'Cable Schedule'!$I$2:$I$5696,"Overhead") | R7: =SUM(B7:Q7)
A8: F Controls / service | B8: =SUMIFS('Cable Schedule'!$W$2:$W$5696,'Cable Schedule'!$B$2:$B$5696,"F",'Cable Schedule'!$I$2:$I$5696,"MV 15 kV") | C8: =SUMIFS('Cable Schedule'!$W$2:$W$5696,'Cable Schedule'!$B$2:$B$5696,"F",'Cable Schedule'!$I$2:$I$5696,"MV 5 kV") | D8: =SUMIFS('Cable Schedule'!$W$2:$W$5696,'Cable Schedule'!$B$2:$B$5696,"F",'Cable Schedule'!$I$2:$I$5696,"MV 25 kV") | E8: =SUMIFS('Cable Schedule'!$W$2:$W$5696,'Cable Schedule'!$B$2:$B$5696,"F",'Cable Schedule'!$I$2:$I$5696,"MV 35 kV") | F8: =SUMIFS('Cable Schedule'!$W$2:$W$5696,'Cable Schedule'!$B$2:$B$5696,"F",'Cable Schedule'!$I$2:$I$5696,"HV 230 kV") | G8: =SUMIFS('Cable Schedule'!$W$2:$W$5696,'Cable Schedule'!$B$2:$B$5696,"F",'Cable Schedule'!$I$2:$I$5696,"LV 600 V") | H8: =SUMIFS('Cable Schedule'!$W$2:$W$5696,'Cable Schedule'!$B$2:$B$5696,"F",'Cable Schedule'!$I$2:$I$5696,"Control") | I8: =SUMIFS('Cable Schedule'!$W$2:$W$5696,'Cable Schedule'!$B$2:$B$5696,"F",'Cable Schedule'!$I$2:$I$5696,"Instrumentation") | J8: =SUMIFS('Cable Schedule'!$W$2:$W$5696,'Cable Schedule'!$B$2:$B$5696,"F",'Cable Schedule'!$I$2:$I$5696,"Fire alarm") | K8: =SUMIFS('Cable Schedule'!$W$2:$W$5696,'Cable Schedule'!$B$2:$B$5696,"F",'Cable Schedule'!$I$2:$I$5696,"Fibre / data") | L8: =SUMIFS('Cable Schedule'!$W$2:$W$5696,'Cable Schedule'!$B$2:$B$5696,"F",'Cable Schedule'!$I$2:$I$5696,"DC 2 kV") | M8: =SUMIFS('Cable Schedule'!$W$2:$W$5696,'Cable Schedule'!$B$2:$B$5696,"F",'Cable Schedule'!$I$2:$I$5696,"Portable MV") | N8: =SUMIFS('Cable Schedule'!$W$2:$W$5696,'Cable Schedule'!$B$2:$B$5696,"F",'Cable Schedule'!$I$2:$I$5696,"Portable LV") | O8: =SUMIFS('Cable Schedule'!$W$2:$W$5696,'Cable Schedule'!$B$2:$B$5696,"F",'Cable Schedule'!$I$2:$I$5696,"Building wire") | P8: =SUMIFS('Cable Schedule'!$W$2:$W$5696,'Cable Schedule'!$B$2:$B$5696,"F",'Cable Schedule'!$I$2:$I$5696,"Grounding") | Q8: =SUMIFS('Cable Schedule'!$W$2:$W$5696,'Cable Schedule'!$B$2:$B$5696,"F",'Cable Schedule'!$I$2:$I$5696,"Overhead") | R8: =SUM(B8:Q8)
A9: G Carbon capture | B9: =SUMIFS('Cable Schedule'!$W$2:$W$5696,'Cable Schedule'!$B$2:$B$5696,"G",'Cable Schedule'!$I$2:$I$5696,"MV 15 kV") | C9: =SUMIFS('Cable Schedule'!$W$2:$W$5696,'Cable Schedule'!$B$2:$B$5696,"G",'Cable Schedule'!$I$2:$I$5696,"MV 5 kV") | D9: =SUMIFS('Cable Schedule'!$W$2:$W$5696,'Cable Schedule'!$B$2:$B$5696,"G",'Cable Schedule'!$I$2:$I$5696,"MV 25 kV") | E9: =SUMIFS('Cable Schedule'!$W$2:$W$5696,'Cable Schedule'!$B$2:$B$5696,"G",'Cable Schedule'!$I$2:$I$5696,"MV 35 kV") | F9: =SUMIFS('Cable Schedule'!$W$2:$W$5696,'Cable Schedule'!$B$2:$B$5696,"G",'Cable Schedule'!$I$2:$I$5696,"HV 230 kV") | G9: =SUMIFS('Cable Schedule'!$W$2:$W$5696,'Cable Schedule'!$B$2:$B$5696,"G",'Cable Schedule'!$I$2:$I$5696,"LV 600 V") | H9: =SUMIFS('Cable Schedule'!$W$2:$W$5696,'Cable Schedule'!$B$2:$B$5696,"G",'Cable Schedule'!$I$2:$I$5696,"Control") | I9: =SUMIFS('Cable Schedule'!$W$2:$W$5696,'Cable Schedule'!$B$2:$B$5696,"G",'Cable Schedule'!$I$2:$I$5696,"Instrumentation") | J9: =SUMIFS('Cable Schedule'!$W$2:$W$5696,'Cable Schedule'!$B$2:$B$5696,"G",'Cable Schedule'!$I$2:$I$5696,"Fire alarm") | K9: =SUMIFS('Cable Schedule'!$W$2:$W$5696,'Cable Schedule'!$B$2:$B$5696,"G",'Cable Schedule'!$I$2:$I$5696,"Fibre / data") | L9: =SUMIFS('Cable Schedule'!$W$2:$W$5696,'Cable Schedule'!$B$2:$B$5696,"G",'Cable Schedule'!$I$2:$I$5696,"DC 2 kV") | M9: =SUMIFS('Cable Schedule'!$W$2:$W$5696,'Cable Schedule'!$B$2:$B$5696,"G",'Cable Schedule'!$I$2:$I$5696,"Portable MV") | N9: =SUMIFS('Cable Schedule'!$W$2:$W$5696,'Cable Schedule'!$B$2:$B$5696,"G",'Cable Schedule'!$I$2:$I$5696,"Portable LV") | O9: =SUMIFS('Cable Schedule'!$W$2:$W$5696,'Cable Schedule'!$B$2:$B$5696,"G",'Cable Schedule'!$I$2:$I$5696,"Building wire") | P9: =SUMIFS('Cable Schedule'!$W$2:$W$5696,'Cable Schedule'!$B$2:$B$5696,"G",'Cable Schedule'!$I$2:$I$5696,"Grounding") | Q9: =SUMIFS('Cable Schedule'!$W$2:$W$5696,'Cable Schedule'!$B$2:$B$5696,"G",'Cable Schedule'!$I$2:$I$5696,"Overhead") | R9: =SUM(B9:Q9)
A10: H BESS | B10: =SUMIFS('Cable Schedule'!$W$2:$W$5696,'Cable Schedule'!$B$2:$B$5696,"H",'Cable Schedule'!$I$2:$I$5696,"MV 15 kV") | C10: =SUMIFS('Cable Schedule'!$W$2:$W$5696,'Cable Schedule'!$B$2:$B$5696,"H",'Cable Schedule'!$I$2:$I$5696,"MV 5 kV") | D10: =SUMIFS('Cable Schedule'!$W$2:$W$5696,'Cable Schedule'!$B$2:$B$5696,"H",'Cable Schedule'!$I$2:$I$5696,"MV 25 kV") | E10: =SUMIFS('Cable Schedule'!$W$2:$W$5696,'Cable Schedule'!$B$2:$B$5696,"H",'Cable Schedule'!$I$2:$I$5696,"MV 35 kV") | F10: =SUMIFS('Cable Schedule'!$W$2:$W$5696,'Cable Schedule'!$B$2:$B$5696,"H",'Cable Schedule'!$I$2:$I$5696,"HV 230 kV") | G10: =SUMIFS('Cable Schedule'!$W$2:$W$5696,'Cable Schedule'!$B$2:$B$5696,"H",'Cable Schedule'!$I$2:$I$5696,"LV 600 V") | H10: =SUMIFS('Cable Schedule'!$W$2:$W$5696,'Cable Schedule'!$B$2:$B$5696,"H",'Cable Schedule'!$I$2:$I$5696,"Control") | I10: =SUMIFS('Cable Schedule'!$W$2:$W$5696,'Cable Schedule'!$B$2:$B$5696,"H",'Cable Schedule'!$I$2:$I$5696,"Instrumentation") | J10: =SUMIFS('Cable Schedule'!$W$2:$W$5696,'Cable Schedule'!$B$2:$B$5696,"H",'Cable Schedule'!$I$2:$I$5696,"Fire alarm") | K10: =SUMIFS('Cable Schedule'!$W$2:$W$5696,'Cable Schedule'!$B$2:$B$5696,"H",'Cable Schedule'!$I$2:$I$5696,"Fibre / data") | L10: =SUMIFS('Cable Schedule'!$W$2:$W$5696,'Cable Schedule'!$B$2:$B$5696,"H",'Cable Schedule'!$I$2:$I$5696,"DC 2 kV") | M10: =SUMIFS('Cable Schedule'!$W$2:$W$5696,'Cable Schedule'!$B$2:$B$5696,"H",'Cable Schedule'!$I$2:$I$5696,"Portable MV") | N10: =SUMIFS('Cable Schedule'!$W$2:$W$5696,'Cable Schedule'!$B$2:$B$5696,"H",'Cable Schedule'!$I$2:$I$5696,"Portable LV") | O10: =SUMIFS('Cable Schedule'!$W$2:$W$5696,'Cable Schedule'!$B$2:$B$5696,"H",'Cable Schedule'!$I$2:$I$5696,"Building wire") | P10: =SUMIFS('Cable Schedule'!$W$2:$W$5696,'Cable Schedule'!$B$2:$B$5696,"H",'Cable Schedule'!$I$2:$I$5696,"Grounding") | Q10: =SUMIFS('Cable Schedule'!$W$2:$W$5696,'Cable Schedule'!$B$2:$B$5696,"H",'Cable Schedule'!$I$2:$I$5696,"Overhead") | R10: =SUM(B10:Q10)
A11: I Modular / portable power | B11: =SUMIFS('Cable Schedule'!$W$2:$W$5696,'Cable Schedule'!$B$2:$B$5696,"I",'Cable Schedule'!$I$2:$I$5696,"MV 15 kV") | C11: =SUMIFS('Cable Schedule'!$W$2:$W$5696,'Cable Schedule'!$B$2:$B$5696,"I",'Cable Schedule'!$I$2:$I$5696,"MV 5 kV") | D11: =SUMIFS('Cable Schedule'!$W$2:$W$5696,'Cable Schedule'!$B$2:$B$5696,"I",'Cable Schedule'!$I$2:$I$5696,"MV 25 kV") | E11: =SUMIFS('Cable Schedule'!$W$2:$W$5696,'Cable Schedule'!$B$2:$B$5696,"I",'Cable Schedule'!$I$2:$I$5696,"MV 35 kV") | F11: =SUMIFS('Cable Schedule'!$W$2:$W$5696,'Cable Schedule'!$B$2:$B$5696,"I",'Cable Schedule'!$I$2:$I$5696,"HV 230 kV") | G11: =SUMIFS('Cable Schedule'!$W$2:$W$5696,'Cable Schedule'!$B$2:$B$5696,"I",'Cable Schedule'!$I$2:$I$5696,"LV 600 V") | H11: =SUMIFS('Cable Schedule'!$W$2:$W$5696,'Cable Schedule'!$B$2:$B$5696,"I",'Cable Schedule'!$I$2:$I$5696,"Control") | I11: =SUMIFS('Cable Schedule'!$W$2:$W$5696,'Cable Schedule'!$B$2:$B$5696,"I",'Cable Schedule'!$I$2:$I$5696,"Instrumentation") | J11: =SUMIFS('Cable Schedule'!$W$2:$W$5696,'Cable Schedule'!$B$2:$B$5696,"I",'Cable Schedule'!$I$2:$I$5696,"Fire alarm") | K11: =SUMIFS('Cable Schedule'!$W$2:$W$5696,'Cable Schedule'!$B$2:$B$5696,"I",'Cable Schedule'!$I$2:$I$5696,"Fibre / data") | L11: =SUMIFS('Cable Schedule'!$W$2:$W$5696,'Cable Schedule'!$B$2:$B$5696,"I",'Cable Schedule'!$I$2:$I$5696,"DC 2 kV") | M11: =SUMIFS('Cable Schedule'!$W$2:$W$5696,'Cable Schedule'!$B$2:$B$5696,"I",'Cable Schedule'!$I$2:$I$5696,"Portable MV") | N11: =SUMIFS('Cable Schedule'!$W$2:$W$5696,'Cable Schedule'!$B$2:$B$5696,"I",'Cable Schedule'!$I$2:$I$5696,"Portable LV") | O11: =SUMIFS('Cable Schedule'!$W$2:$W$5696,'Cable Schedule'!$B$2:$B$5696,"I",'Cable Schedule'!$I$2:$I$5696,"Building wire") | P11: =SUMIFS('Cable Schedule'!$W$2:$W$5696,'Cable Schedule'!$B$2:$B$5696,"I",'Cable Schedule'!$I$2:$I$5696,"Grounding") | Q11: =SUMIFS('Cable Schedule'!$W$2:$W$5696,'Cable Schedule'!$B$2:$B$5696,"I",'Cable Schedule'!$I$2:$I$5696,"Overhead") | R11: =SUM(B11:Q11)
A12: J GT inlet chilling | B12: =SUMIFS('Cable Schedule'!$W$2:$W$5696,'Cable Schedule'!$B$2:$B$5696,"J",'Cable Schedule'!$I$2:$I$5696,"MV 15 kV") | C12: =SUMIFS('Cable Schedule'!$W$2:$W$5696,'Cable Schedule'!$B$2:$B$5696,"J",'Cable Schedule'!$I$2:$I$5696,"MV 5 kV") | D12: =SUMIFS('Cable Schedule'!$W$2:$W$5696,'Cable Schedule'!$B$2:$B$5696,"J",'Cable Schedule'!$I$2:$I$5696,"MV 25 kV") | E12: =SUMIFS('Cable Schedule'!$W$2:$W$5696,'Cable Schedule'!$B$2:$B$5696,"J",'Cable Schedule'!$I$2:$I$5696,"MV 35 kV") | F12: =SUMIFS('Cable Schedule'!$W$2:$W$5696,'Cable Schedule'!$B$2:$B$5696,"J",'Cable Schedule'!$I$2:$I$5696,"HV 230 kV") | G12: =SUMIFS('Cable Schedule'!$W$2:$W$5696,'Cable Schedule'!$B$2:$B$5696,"J",'Cable Schedule'!$I$2:$I$5696,"LV 600 V") | H12: =SUMIFS('Cable Schedule'!$W$2:$W$5696,'Cable Schedule'!$B$2:$B$5696,"J",'Cable Schedule'!$I$2:$I$5696,"Control") | I12: =SUMIFS('Cable Schedule'!$W$2:$W$5696,'Cable Schedule'!$B$2:$B$5696,"J",'Cable Schedule'!$I$2:$I$5696,"Instrumentation") | J12: =SUMIFS('Cable Schedule'!$W$2:$W$5696,'Cable Schedule'!$B$2:$B$5696,"J",'Cable Schedule'!$I$2:$I$5696,"Fire alarm") | K12: =SUMIFS('Cable Schedule'!$W$2:$W$5696,'Cable Schedule'!$B$2:$B$5696,"J",'Cable Schedule'!$I$2:$I$5696,"Fibre / data") | L12: =SUMIFS('Cable Schedule'!$W$2:$W$5696,'Cable Schedule'!$B$2:$B$5696,"J",'Cable Schedule'!$I$2:$I$5696,"DC 2 kV") | M12: =SUMIFS('Cable Schedule'!$W$2:$W$5696,'Cable Schedule'!$B$2:$B$5696,"J",'Cable Schedule'!$I$2:$I$5696,"Portable MV") | N12: =SUMIFS('Cable Schedule'!$W$2:$W$5696,'Cable Schedule'!$B$2:$B$5696,"J",'Cable Schedule'!$I$2:$I$5696,"Portable LV") | O12: =SUMIFS('Cable Schedule'!$W$2:$W$5696,'Cable Schedule'!$B$2:$B$5696,"J",'Cable Schedule'!$I$2:$I$5696,"Building wire") | P12: =SUMIFS('Cable Schedule'!$W$2:$W$5696,'Cable Schedule'!$B$2:$B$5696,"J",'Cable Schedule'!$I$2:$I$5696,"Grounding") | Q12: =SUMIFS('Cable Schedule'!$W$2:$W$5696,'Cable Schedule'!$B$2:$B$5696,"J",'Cable Schedule'!$I$2:$I$5696,"Overhead") | R12: =SUM(B12:Q12)
A13: K Fuel supply (adjacent market) | B13: =SUMIFS('Cable Schedule'!$W$2:$W$5696,'Cable Schedule'!$B$2:$B$5696,"K",'Cable Schedule'!$I$2:$I$5696,"MV 15 kV") | C13: =SUMIFS('Cable Schedule'!$W$2:$W$5696,'Cable Schedule'!$B$2:$B$5696,"K",'Cable Schedule'!$I$2:$I$5696,"MV 5 kV") | D13: =SUMIFS('Cable Schedule'!$W$2:$W$5696,'Cable Schedule'!$B$2:$B$5696,"K",'Cable Schedule'!$I$2:$I$5696,"MV 25 kV") | E13: =SUMIFS('Cable Schedule'!$W$2:$W$5696,'Cable Schedule'!$B$2:$B$5696,"K",'Cable Schedule'!$I$2:$I$5696,"MV 35 kV") | F13: =SUMIFS('Cable Schedule'!$W$2:$W$5696,'Cable Schedule'!$B$2:$B$5696,"K",'Cable Schedule'!$I$2:$I$5696,"HV 230 kV") | G13: =SUMIFS('Cable Schedule'!$W$2:$W$5696,'Cable Schedule'!$B$2:$B$5696,"K",'Cable Schedule'!$I$2:$I$5696,"LV 600 V") | H13: =SUMIFS('Cable Schedule'!$W$2:$W$5696,'Cable Schedule'!$B$2:$B$5696,"K",'Cable Schedule'!$I$2:$I$5696,"Control") | I13: =SUMIFS('Cable Schedule'!$W$2:$W$5696,'Cable Schedule'!$B$2:$B$5696,"K",'Cable Schedule'!$I$2:$I$5696,"Instrumentation") | J13: =SUMIFS('Cable Schedule'!$W$2:$W$5696,'Cable Schedule'!$B$2:$B$5696,"K",'Cable Schedule'!$I$2:$I$5696,"Fire alarm") | K13: =SUMIFS('Cable Schedule'!$W$2:$W$5696,'Cable Schedule'!$B$2:$B$5696,"K",'Cable Schedule'!$I$2:$I$5696,"Fibre / data") | L13: =SUMIFS('Cable Schedule'!$W$2:$W$5696,'Cable Schedule'!$B$2:$B$5696,"K",'Cable Schedule'!$I$2:$I$5696,"DC 2 kV") | M13: =SUMIFS('Cable Schedule'!$W$2:$W$5696,'Cable Schedule'!$B$2:$B$5696,"K",'Cable Schedule'!$I$2:$I$5696,"Portable MV") | N13: =SUMIFS('Cable Schedule'!$W$2:$W$5696,'Cable Schedule'!$B$2:$B$5696,"K",'Cable Schedule'!$I$2:$I$5696,"Portable LV") | O13: =SUMIFS('Cable Schedule'!$W$2:$W$5696,'Cable Schedule'!$B$2:$B$5696,"K",'Cable Schedule'!$I$2:$I$5696,"Building wire") | P13: =SUMIFS('Cable Schedule'!$W$2:$W$5696,'Cable Schedule'!$B$2:$B$5696,"K",'Cable Schedule'!$I$2:$I$5696,"Grounding") | Q13: =SUMIFS('Cable Schedule'!$W$2:$W$5696,'Cable Schedule'!$B$2:$B$5696,"K",'Cable Schedule'!$I$2:$I$5696,"Overhead") | R13: =SUM(B13:Q13)
