Workbook

Sheet Cover
A1: CABLE SCHEDULE
A2: Combined Cycle Power Plant with Post-Combustion CCS, Gas Metering / LNG and Modular RICE Plant
A4: Document No. | B4: CCPP-E-CS-0001
A5: Revision | B5: C (Preliminary - issued for review, NOT FOR CONSTRUCTION). Rev B: converted to US NEC practice - 13.8 kV / 480 V, AWG/kcmil, Type MC-HL armored cable. Rev C: CO2 compressor VFD line/output split; ACC fan local disconnects with flexible Machine Flex type VFD final drops.
A6: Date | B6: 2026-10-18
A7: Basis of layout | B7: Equipment positions from the 3D line-art model examples/powerplant.go (repo shardt87/ln, branch claude/powerplant-example). Coordinates in metres, site grid: X east, Y north, Z up. Lengths reported in metres and feet.
A8: Basis of ratings | B8: Representative ratings for a ~1x1 F-class CCGT (GT ~290 MVA, ST ~175 MVA), amine CCS train, 8 x 2.5 MVA containerised gas engines, 230 kV switchyard. Ratings are typical values, NOT taken from a specific project. See 'Design Basis'.
A9: Cable construction | B9: Power, VFD and control: 600 V and 15 kV Type MC-HL, Cu, XHHW-2 / EPR (MV-105) insulation, continuous corrugated welded aluminum armor (CCW) with PVC jacket - e.g. Southwire Armor-X (product named as an example of the construction only). Final drops to vibrating VFD-driven motors (ACC fans): flexible shielded VFD cable Type TC-ER with 3 symmetrical grounds - e.g. Southwire Machine Flex. Instrument: armored PLTC / ITC-HL. All tray-rated (-TC/-ER), sunlight resistant, UL 1685 / IEEE 1202 FT4. MC-HL with listed fittings is suitable for Class I Div 1 & 2 areas (gas metering, LNG, BOG) per NEC 501.10.
A11: Sheets
A12: Design Basis | B12: Global inputs: route slack, termination allowance, sag allowance, wastage, voltage drop limits, standards.
A13: Equipment | B13: Equipment / termination point list with site coordinates (from the 3D model).
A14: Cable Types | B14: Cable / conductor / busduct library: OD, ampacity, mV/A/m, mass, reel length.
A15: Raceways | B15: Trays, trenches, duct banks, busducts, OHL - elevation, correction factor and fill check.
A16: Cable Schedule | B16: One row per circuit. Route length, total length, running and design current, loading, voltage drop and check are all formulas.
A17: BOQ Summary | B17: Quantities by cable type (with wastage, reels, mass) and by system.
A18: References | B18: Public documents identified as references for typical arrangements, and cable product data.
A20: Legend
A21: Blue text | B21: Hard-coded input - edit these
A22: Black text | B22: Formula - do not overwrite
A23: Green text | B23: Lookup from another sheet
A24: Yellow fill | B24: Key assumption to be verified against vendor / project data
A26: Route length method | B26: M = Manhattan route along raceway: (|dX|+|dY| + rise from each end to raceway elevation) x (1+slack) + 2 x termination allowance. D = direct span (overhead conductors): 3D distance x (1+sag allowance). A value in 'Length Override' replaces the calculation (used for earth grids / bonds).
A27: Sizing | B27: Design current = running current x sizing factor: 1.25 for motors (NEC 430.22) and continuous loads (NEC 210.19 / 215.2), 1.15 for generator conductors (NEC 445.13), 1.00 for transformer secondaries / busduct. Allowable ampacity = base ampacity (NEC 310.16 75 C column for 600 V; NEC 311.60 for 15 kV) x raceway correction factor. Voltage drop uses NEC Ch. 9 Table 9 effective Z at 0.85 PF (AC) or Table 8 DC resistance.
A28: Limitations | B28: Preliminary sizing only. Short-circuit withstand (ICEA P-32-382), motor starting voltage dip, ground fault return path, detailed tray fill per NEC 392.22 and ampacity per NEC 392.80 / IEEE 835 (Neher-McGrath for duct banks) must be verified at detailed design. Raceway fill counts each cable on its primary raceway only.

Sheet Design Basis
A1: DESIGN BASIS - GLOBAL INPUTS
A3: Parameter | C3: Value | D3: Note
A4: Route slack / snaking allowance | C4: 0.1 | D4: Typical 5-15% on tray routes for bends, drops and snaking.
A5: Termination allowance per end (m) | C5: 3 | D5: Gland / connector, tail and dressing inside panel / terminal box.
A6: Overhead conductor sag allowance | C6: 0.03 | D6: Conductor length over chord for strung bus and line spans.
A7: Procurement wastage allowance | C7: 0.05 | D7: Applied in BOQ only.
A8: Ambient air design temperature (deg C) | C8: 40 | D8: Information - included in raceway correction factors (NEC 310.15(B) 0.88 for 75 C at 40 C).
A9: Earth thermal resistivity (RHO) | C9: 90 | D9: Information - included in duct bank factors (IEEE 835 / NEC 311.60, RHO 90).
A10: Feet per metre | C10: 3.28084 | D10: Unit conversion.
A12: System | B12: Nominal voltage | C12: Max steady-state voltage drop | D12: Note
A13: HV Overhead | B13: 230 kV | D13: Strung bus / OHL - checked for ampacity only.
A14: Busduct | B14: 18 / 19 kV IPB, 480 V LV busway | D14: Checked for ampacity only.
A15: MV Power | B15: 13.8 kV | C15: 0.03 | D15: Feeder volt drop, full load running.
A16: LV Power | B16: 480 V, 3-ph 3-wire + ground | C16: 0.03 | D16: NEC 215.2 / 210.19 informational notes: 3% feeder or branch, 5% total.
A17: DC Power | B17: 125 V DC / 120-208 V UPS | C17: 0.03 | D17: Battery / UPS to load.
A18: Control | B18: 120 V AC / 125 V DC | D18: Size by CT burden / voltage at coil - not checked here.
A19: Instrument | B19: 24 V DC / 4-20 mA / TC | D19: Not checked here.
A20: Fibre Optic | B20: - | D20: -
A21: Earthing | B21: - | D21: Size per IEEE 80 fault study.
A24: Design standards (reference)
A25: NFPA 70 (NEC) 2023: 310.16 / 311.60 ampacity, 330 Type MC, 392 cable tray, 430.22 motors, 445.13 generators, 501.10 Class I wiring, 725 PLTC, 727 ITC
A26: NEC Chapter 9 Tables 8 and 9: conductor DC resistance and AC effective impedance (voltage drop)
A27: UL 1569 Metal-Clad Cables; UL 2225 cables and fittings for hazardous locations (MC-HL)
A28: ICEA S-95-658 (NEMA WC70) 600 V cables; ICEA S-93-639 (NEMA WC74) 5-46 kV shielded power cables; ICEA S-73-532 control & instrument
A29: IEEE 835: Power cable ampacity tables; IEEE 525: Cable design and installation in substations
A30: IEEE 1202 / UL 1685: Vertical tray flame test (FT4)
A31: IEEE 738: Bare overhead conductor ampacity; IEEE C37.23: Metal-enclosed (isolated phase) bus
A32: IEEE 80: AC substation grounding

Sheet Equipment
A1: Tag | B1: Description | C1: Area | D1: X (m) | E1: Y (m) | F1: Z term. (m) | G1: Location in 3D model / basis
A2: SWY-B1 | B2: 230 kV bay 1 - RICE transformer bay (gantry dead-end) | C2: 10 | D2: 20 | E2: 137.5 | F2: 12.5 | G2: Gantry x=20
A3: SWY-B2 | B3: 230 kV bay 2 - bus coupler (gantry dead-end) | C3: 10 | D3: 40 | E3: 137.5 | F3: 12.5 | G3: Gantry x=40
A4: SWY-B3 | B4: 230 kV bay 3 - GT generator bay (gantry dead-end) | C4: 10 | D4: 60 | E4: 137.5 | F4: 12.5 | G4: Gantry x=60
A5: SWY-B4 | B5: 230 kV bay 4 - ST generator bay / line exit (gantry dead-end) | C5: 10 | D5: 80 | E5: 137.5 | F5: 12.5 | G5: Gantry x=80
A6: TWR-01 | B6: 230 kV transmission tower 1 (terminal) | C6: 10 | D6: 130 | E6: 137.5 | F6: 31.5 | G6: Tower x=130
A7: TWR-02 | B7: 230 kV transmission tower 2 (suspension) | C7: 10 | D7: 200 | E7: 152.5 | F7: 31.5 | G7: Tower x=200
A8: TWR-03 | B8: 230 kV transmission tower 3 (suspension) | C8: 10 | D8: 270 | E8: 167.5 | F8: 31.5 | G8: Tower x=270
A9: SWY-RB | B9: Switchyard relay & control building | C9: 10 | D9: 95 | E9: 128 | F9: 0.5 | G9: Not drawn - assumed
A10: RICE-TX-HV | B10: RICE step-up transformer 13.8/230 kV 22 MVA - HV bushings | C10: 50 | D10: 19 | E10: 107.5 | F10: 8 | G10: Transformer at (14-20,105-110)
A11: RICE-TX-LV | B11: RICE step-up transformer 13.8/230 kV 22 MVA - LV cable box | C11: 50 | D11: 14.5 | E11: 107.5 | F11: 2 | G11: Transformer at (14-20,105-110)
A12: GEN-GT | B12: Gas turbine generator ~290 MVA, 19 kV - line terminals | C12: 20 | D12: 58 | E12: 18 | F12: 4 | G12: GT generator box (52-64,10-18)
A13: GEN-ST | B13: Steam turbine generator ~175 MVA, 18 kV - line terminals | C13: 20 | D13: 60 | E13: 46 | F13: 6 | G13: ST hall north wall
... A153: EG-SWY | B153: Switchyard earth grid (nearest riser) | C153: 10 | D153: 50 | E153: 137.5 | F153: -0.8 | G153: Buried

Sheet Cable Types
A1: Code | B1: Description | C1: Category | D1: Conductors / cables per run | E1: OD (mm) | F1: Base ampacity per run (A) | G1: mV/A/m (3-ph line, or 1-ph/DC loop) | H1: Mass (kg/m per conductor) | I1: Std reel length (m) | J1: Basis
A2: ACSR-DRAKE | B2: ACSR 795 kcmil 'Drake' 26/7, 1 per phase | C2: HV Overhead | D2: 3 | E2: 28.1 | F2: 900 | H2: 1.628 | I2: 2000 | J2: IEEE 738 typical (40 C ambient, 75 C conductor, 2 ft/s wind)
A3: ACSR-DRAKE-2B | B3: ACSR 795 kcmil 'Drake' 26/7, twin bundle per phase | C3: HV Overhead | D3: 6 | E3: 28.1 | F3: 1800 | H3: 1.628 | I3: 2000 | J3: IEEE 738 typical (40 C ambient, 75 C conductor, 2 ft/s wind)
A4: SW-7/16-EHS | B4: Shield wire 7/16" EHS galvanized steel | C4: HV Overhead | D4: 1 | E4: 11.1 | H4: 0.595 | I4: 3000 | J4: IEEE 738 typical (40 C ambient, 75 C conductor, 2 ft/s wind)
A5: OPGW-24 | B5: OPGW 24-fiber shield wire | C5: HV Overhead | D5: 1 | E5: 14 | H5: 0.62 | I5: 4000 | J5: IEEE 738 typical (40 C ambient, 75 C conductor, 2 ft/s wind)
A6: IPB-10K | B6: Isolated phase bus 24 kV, 10 kA (per phase metre) | C6: Busduct | D6: 3 | F6: 10000 | H6: 160 | J6: Vendor nominal rating (IEEE C37.23 / UL 857)
A7: IPB-7K | B7: Isolated phase bus 24 kV, 7 kA (per phase metre) | C7: Busduct | D7: 3 | F7: 7000 | H7: 120 | J7: Vendor nominal rating (IEEE C37.23 / UL 857)
A8: IPB-3K | B8: Isolated phase tap bus 24 kV, 3 kA (per phase metre) | C8: Busduct | D8: 3 | F8: 3000 | H8: 70 | J8: Vendor nominal rating (IEEE C37.23 / UL 857)
A9: LVBD-4000 | B9: 600 V busway 4000 A, Cu, 3-ph + ground, outdoor feeder | C9: Busduct | D9: 1 | F9: 4000 | H9: 45 | J9: Vendor nominal rating (IEEE C37.23 / UL 857)
A10: LVBD-2500 | B10: 600 V busway 2500 A, Cu, 3-ph + ground, outdoor feeder | C10: Busduct | D10: 1 | F10: 2500 | H10: 30 | J10: Vendor nominal rating (IEEE C37.23 / UL 857)
A11: MV-1C-2-NGR | B11: 15 kV MV-105 1/C #2 AWG Cu EPR 133% shielded, Type MC-HL, CCW Al armor (Armor-X type), PVC jkt | C11: MV Power | D11: 1 | E11: 33 | F11: 195 | H11: 1.6 | I11: 300 | J11: NEC 311.60(C) 15 kV Cu 90 C in air, 40 C ambient (approx.); VD from R cos + X sin at 0.85 PF
A12: MV-3C-2 | B12: 15 kV MV-105 3/C #2 AWG Cu EPR 133% shielded + GC, Type MC-HL, CCW Al armor (Armor-X type), PVC jkt | C12: MV Power | D12: 1 | E12: 61 | F12: 165 | G12: 1.068 | H12: 4 | I12: 300 | J12: NEC 311.60(C) 15 kV Cu 90 C in air, 40 C ambient (approx.); VD from R cos + X sin at 0.85 PF
A13: MV-3C-1/0 | B13: 15 kV MV-105 3/C 1/0 AWG Cu EPR 133% shielded + GC, Type MC-HL, CCW Al armor (Armor-X type), PVC jkt | C13: MV Power | D13: 1 | E13: 66 | F13: 215 | G13: 0.716 | H13: 5.3 | I13: 300 | J13: NEC 311.60(C) 15 kV Cu 90 C in air, 40 C ambient (approx.); VD from R cos + X sin at 0.85 PF
A14: MV-3C-4/0 | B14: 15 kV MV-105 3/C 4/0 AWG Cu EPR 133% shielded + GC, Type MC-HL, CCW Al armor (Armor-X type), PVC jkt | C14: MV Power | D14: 1 | E14: 76 | F14: 310 | G14: 0.426 | H14: 8 | I14: 300 | J14: NEC 311.60(C) 15 kV Cu 90 C in air, 40 C ambient (approx.); VD from R cos + X sin at 0.85 PF
A15: MV-3C-500 | B15: 15 kV MV-105 3/C 500 kcmil Cu EPR 133% shielded + GC, Type MC-HL, CCW Al armor (Armor-X type), PVC jkt | C15: MV Power | D15: 1 | E15: 94 | F15: 515 | G15: 0.256 | H15: 15.5 | I15: 300 | J15: NEC 311.60(C) 15 kV Cu 90 C in air, 40 C ambient (approx.); VD from R cos + X sin at 0.85 PF
A16: MV-1C-500-TPX | B16: 15 kV MV-105 1/C 500 kcmil Cu EPR 133% shielded, Type MC-HL, CCW Al armor (Armor-X type), PVC jkt, triplexed set | C16: MV Power | D16: 3 | E16: 41 | F16: 585 | G16: 0.256 | H16: 4.4 | I16: 300 | J16: NEC 311.60(C) 15 kV Cu 90 C in air, 40 C ambient (approx.); VD from R cos + X sin at 0.85 PF
A17: MV-1C-750-TPX | B17: 15 kV MV-105 1/C 750 kcmil Cu EPR 133% shielded, Type MC-HL, CCW Al armor (Armor-X type), PVC jkt, triplexed set | C17: MV Power | D17: 3 | E17: 46 | F17: 740 | G17: 0.21 | H17: 6.2 | I17: 300 | J17: NEC 311.60(C) 15 kV Cu 90 C in air, 40 C ambient (approx.); VD from R cos + X sin at 0.85 PF
A18: MV-1C-1000-TPX | B18: 15 kV MV-105 1/C 1000 kcmil Cu EPR 133% shielded, Type MC-HL, CCW Al armor (Armor-X type), PVC jkt, triplexed set | C18: MV Power | D18: 3 | E18: 51 | F18: 860 | G18: 0.188 | H18: 7.9 | I18: 300 | J18: NEC 311.60(C) 15 kV Cu 90 C in air, 40 C ambient (approx.); VD from R cos + X sin at 0.85 PF
A19: LV-3C-10 | B19: 600 V 3/C #10 AWG + G Cu XHHW-2, Type MC-HL, CCW Al armor (Armor-X type), PVC jkt | C19: LV Power | D19: 1 | E19: 20 | F19: 35 | G19: 6.251 | H19: 0.6 | I19: 600 | J19: NEC 310.16 Cu 75 C column (termination limit); NEC 392.80(A)(1); VD NEC Ch.9 Table 9, 0.85 PF
A20: LV-3C-6 | B20: 600 V 3/C #6 AWG + G Cu XHHW-2, Type MC-HL, CCW Al armor (Armor-X type), PVC jkt | C20: LV Power | D20: 1 | E20: 24 | F20: 65 | G20: 2.557 | H20: 0.95 | I20: 600 | J20: NEC 310.16 Cu 75 C column (termination limit); NEC 392.80(A)(1); VD NEC Ch.9 Table 9, 0.85 PF
A21: LV-3C-2 | B21: 600 V 3/C #2 AWG + G Cu XHHW-2, Type MC-HL, CCW Al armor (Armor-X type), PVC jkt | C21: LV Power | D21: 1 | E21: 31 | F21: 115 | G21: 1.08 | H21: 1.8 | I21: 600 | J21: NEC 310.16 Cu 75 C column (termination limit); NEC 392.80(A)(1); VD NEC Ch.9 Table 9, 0.85 PF
A22: LV-3C-1/0 | B22: 600 V 3/C 1/0 AWG + G Cu XHHW-2, Type MC-HL, CCW Al armor (Armor-X type), PVC jkt | C22: LV Power | D22: 1 | E22: 37 | F22: 150 | G22: 0.682 | H22: 2.6 | I22: 300 | J22: NEC 310.16 Cu 75 C column (termination limit); NEC 392.80(A)(1); VD NEC Ch.9 Table 9, 0.85 PF
A23: LV-3C-4/0 | B23: 600 V 3/C 4/0 AWG + G Cu XHHW-2, Type MC-HL, CCW Al armor (Armor-X type), PVC jkt | C23: LV Power | D23: 1 | E23: 47 | F23: 230 | G23: 0.392 | H23: 4.6 | I23: 300 | J23: NEC 310.16 Cu 75 C column (termination limit); NEC 392.80(A)(1); VD NEC Ch.9 Table 9, 0.85 PF
... A31: LV-1C-500 | B31: 600 V 1/C 500 kcmil Cu XHHW-2, Type MC-HL, CCW Al armor (Armor-X type), PVC jkt (+/- pair) | C31: DC Power | D31: 2 | E31: 34 | F31: 465 | G31: 0.169 | H31: 3.3 | I31: 300 | J31: NEC 310.16 75 C (1/C in tray: 392.80(A)(2), 75% of 310.17); VD NEC Ch.9 Table 8 DC loop
A32: CTL-7C-12 | B32: 600 V 7/C #12 AWG Cu XHHW-2 control, Type MC-HL, CCW Al armor (Armor-X type), PVC jkt | C32: Control | D32: 1 | E32: 19 | H32: 0.6 | I32: 600 | J32: Not current-rated here
A33: CTL-12C-14 | B33: 600 V 12/C #14 AWG Cu XHHW-2 control, Type MC-HL, CCW Al armor (Armor-X type), PVC jkt | C33: Control | D33: 1 | E33: 21 | H33: 0.7 | I33: 600 | J33: Not current-rated here
A34: CTL-25C-14 | B34: 600 V 25/C #14 AWG Cu XHHW-2 control, Type MC-HL, CCW Al armor (Armor-X type), PVC jkt | C34: Control | D34: 1 | E34: 27 | H34: 1.1 | I34: 600 | J34: Not current-rated here
A35: CTL-12C-10 | B35: 600 V 12/C #10 AWG Cu XHHW-2 control (CT circuits), Type MC-HL, CCW Al armor (Armor-X type), PVC jkt | C35: Control | D35: 1 | E35: 27 | H35: 1.2 | I35: 600 | J35: Not current-rated here
A36: INS-1TSP-16 | B36: 300 V 1 TSP #16 AWG, PLTC/ITC-HL, CCW armor, PVC jkt (IS blue) | C36: Instrument | D36: 1 | E36: 13 | H36: 0.25 | I36: 600 | J36: Not current-rated here
A37: INS-2TSP-16 | B37: 300 V 2 TSP #16 AWG, PLTC/ITC-HL, CCW armor, PVC jkt (IS blue) | C37: Instrument | D37: 1 | E37: 16 | H37: 0.35 | I37: 600 | J37: Not current-rated here
A38: INS-12TSP-18 | B38: 300 V 12 TSP #18 AWG indiv. + overall shield, PLTC/ITC-HL, CCW armor | C38: Instrument | D38: 1 | E38: 30 | H38: 0.9 | I38: 600 | J38: Not current-rated here
A39: INS-24TSP-18 | B39: 300 V 24 TSP #18 AWG indiv. + overall shield, PLTC/ITC-HL, CCW armor | C39: Instrument | D39: 1 | E39: 38 | H39: 1.4 | I39: 600 | J39: Not current-rated here
A40: INS-TC-12P-KX | B40: 300 V 12 pair #16 AWG type KX thermocouple extension, ITC-HL, CCW armor | C40: Instrument | D40: 1 | E40: 30 | H40: 0.8 | I40: 600 | J40: Not current-rated here
A41: INS-RS485 | B41: 300 V 1 TSP #22 AWG 120 ohm RS-485, ITC-HL, CCW armor | C41: Instrument | D41: 1 | E41: 12 | H41: 0.2 | I41: 600 | J41: Not current-rated here
A42: FO-24SM | B42: 24-fiber single-mode OFCR, interlocked Al armor | C42: Fibre Optic | D42: 1 | E42: 19 | H42: 0.3 | I42: 2000 | J42: -
A43: FO-48SM | B43: 48-fiber single-mode OFCR, interlocked Al armor | C43: Fibre Optic | D43: 1 | E43: 21 | H43: 0.36 | I43: 2000 | J43: -
... A45: EB-CU-2/0 | B45: Green insulated Cu 2/0 AWG bonding jumper | C45: Earthing | D45: 1 | E45: 15 | H45: 0.62 | I45: 300 | J45: Size per IEEE 80 fault study

Sheet Cable Schedule
A1: CABLE SCHEDULE - CCPP-E-CS-0001 Rev C (PRELIMINARY) - US NEC practice, Type MC-HL armored cable | AI1: Calculation helpers (lookups - do not edit)
A2: Cable No. | B2: Area | C2: System | D2: Service / Function | E2: From Tag | F2: From Equipment | G2: To Tag | H2: To Equipment | I2: Cable Type | J2: Cable Description | K2: Parallel Runs | L2: Raceway | M2: Route Method | N2: Length Override (m) | O2: Route Length / Run (m) | P2: Route Length / Run (ft) | Q2: Total Conductor Length (m) | R2: Total Conductor Length (ft) | S2: System Voltage (V) | T2: Phases | U2: Load (kW / kVA) | V2: PF x Eff. | W2: Running Current (A) | X2: Sizing Factor | Y2: Design Current (A) | Z2: Allowable Ampacity / Run (A) | AA2: Total Capacity (A) | AB2: Loading (%) | AC2: Volt Drop (%) | AD2: VD Limit (%) | AE2: Check | AF2: Cable Area (mm2) | AG2: Notes | AI2: X from | AJ2: Y from | AK2: Z from | AL2: X to | AM2: Y to | AN2: Z to | AO2: Raceway Elev. | AP2: Correction | AQ2: Cond. / Run | AR2: OD (mm) | AS2: Base Ampacity (A) | AT2: mV/A/m
A3: 10-HV-001 | B3: 10 | C3: HV Overhead | D3: GT GSU 230 kV to bay 3 (strung) | E3: GSU-GT-HV | F3: =INDEX(Equipment!$B$2:$B$153,MATCH(E3,Equipment!$A$2:$A$153,0)) -> GT step-up transformer 19/230 kV 290 MVA - HV bushings | G3: SWY-B3 | H3: =INDEX(Equipment!$B$2:$B$153,MATCH(G3,Equipment!$A$2:$A$153,0)) -> 230 kV bay 3 - GT generator bay (gantry dead-end) | I3: ACSR-DRAKE | J3: =INDEX('Cable Types'!$B$2:$B$45,MATCH(I3,'Cable Types'!$A$2:$A$45,0)) -> ACSR 795 kcmil 'Drake' 26/7, 1 per phase | K3: 1 | L3: OHL | M3: D | O3: =IF(N3<>"",N3,IF(M3="D",ROUNDUP(SQRT((AL3-AI3)^2+(AM3-AJ3)^2+(AN3-AK3)^2)*(1+'Design Basis'!$C$6),0),ROUNDUP((ABS(AL3-AI3)+ABS(AM3-AJ3)+ABS(AO3-AK3)+ABS(AO3-AN3))*(1+'Design Basis'!$C$4)+2*'Design Basis'!$C$5,0))) -> 75 | P3: =ROUND(O3*'Design Basis'!$C$10,0) -> 246 | Q3: =O3*K3*AQ3 -> 225 | R3: =ROUND(Q3*'Design Basis'!$C$10,0) -> 738 | S3: 230000 | T3: 3 | U3: 290000 | V3: 1 | W3: =IF(OR(U3="",S3=""),"",IF(T3=3,U3*1000/(SQRT(3)*S3*V3),U3*1000/(S3*V3))) -> 727.96338 | X3: 1 | Y3: =IF(W3="","",W3*IF(X3="",1,X3)) -> 727.96338 | Z3: =IF(OR(AS3="",AP3=""),"",AS3*AP3) -> 900 | AA3: =IF(Z3="","",Z3*K3) -> 900 | AB3: =IF(OR(Y3="",AA3=""),"",Y3/AA3) -> 0.8088482 | AC3: =IF(OR(W3="",AT3=""),"",AT3*(W3/K3)*O3/1000/S3) | AD3: =IF(W3="","",IFERROR(IF(INDEX('Design Basis'!$C$13:$C$21,MATCH(C3,'Design Basis'!$A$13:$A$21,0))="","",INDEX('Design Basis'!$C$13:$C$21,MATCH(C3,'Design Basis'!$A$13:$A$21,0))),"")) | AE3: =IF(W3="","n/a",IF(AA3="","CHECK",IF(AND(AB3<=1,OR(AC3="",AD3="",AC3<=AD3)),"OK","CHECK"))) -> OK | AF3: =IF(AR3="","",K3*AQ3*PI()/4*AR3^2) -> 1860.4747 | AG3: Load in kVA | AI3: =INDEX(Equipment!$D$2:$D$153,MATCH(E3,Equipment!$A$2:$A$153,0)) -> 54 | AJ3: =INDEX(Equipment!$E$2:$E$153,MATCH(E3,Equipment!$A$2:$A$153,0)) -> 65.5 | AK3: =INDEX(Equipment!$F$2:$F$153,MATCH(E3,Equipment!$A$2:$A$153,0)) -> 10 | AL3: =INDEX(Equipment!$D$2:$D$153,MATCH(G3,Equipment!$A$2:$A$153,0)) -> 60 | AM3: =INDEX(Equipment!$E$2:$E$153,MATCH(G3,Equipment!$A$2:$A$153,0)) -> 137.5 | AN3: =INDEX(Equipment!$F$2:$F$153,MATCH(G3,Equipment!$A$2:$A$153,0)) -> 12.5 | AO3: =IF(INDEX(Raceways!$D$2:$D$18,MATCH(L3,Raceways!$A$2:$A$18,0))="",0,INDEX(Raceways!$D$2:$D$18,MATCH(L3,Raceways!$A$2:$A$18,0))) -> 0 | AP3: =IF(INDEX(Raceways!$I$2:$I$18,MATCH(L3,Raceways!$A$2:$A$18,0))="","",INDEX(Raceways!$I$2:$I$18,MATCH(L3,Raceways!$A$2:$A$18,0))) -> 1 | AQ3: =INDEX('Cable Types'!$D$2:$D$45,MATCH(I3,'Cable Types'!$A$2:$A$45,0)) -> 3 | AR3: =IF(INDEX('Cable Types'!$E$2:$E$45,MATCH(I3,'Cable Types'!$A$2:$A$45,0))="","",INDEX('Cable Types'!$E$2:$E$45,MATCH(I3,'Cable Types'!$A$2:$A$45,0))) -> 28.1 | AS3: =IF(INDEX('Cable Types'!$F$2:$F$45,MATCH(I3,'Cable Types'!$A$2:$A$45,0))="","",INDEX('Cable Types'!$F$2:$F$45,MATCH(I3,'Cable Types'!$A$2:$A$45,0))) -> 900 | AT3: =IF(INDEX('Cable Types'!$G$2:$G$45,MATCH(I3,'Cable Types'!$A$2:$A$45,0))="","",INDEX('Cable Types'!$G$2:$G$45,MATCH(I3,'Cable Types'!$A$2:$A$45,0)))
A4: 10-HV-002 | B4: 10 | C4: HV Overhead | D4: ST GSU 230 kV to bay 4 (strung) | E4: GSU-ST-HV | F4: =INDEX(Equipment!$B$2:$B$153,MATCH(E4,Equipment!$A$2:$A$153,0)) -> ST step-up transformer 18/230 kV 175 MVA - HV bushings | G4: SWY-B4 | H4: =INDEX(Equipment!$B$2:$B$153,MATCH(G4,Equipment!$A$2:$A$153,0)) -> 230 kV bay 4 - ST generator bay / line exit (gantry dead-end) | I4: ACSR-DRAKE | J4: =INDEX('Cable Types'!$B$2:$B$45,MATCH(I4,'Cable Types'!$A$2:$A$45,0)) -> ACSR 795 kcmil 'Drake' 26/7, 1 per phase | K4: 1 | L4: OHL | M4: D | O4: =IF(N4<>"",N4,IF(M4="D",ROUNDUP(SQRT((AL4-AI4)^2+(AM4-AJ4)^2+(AN4-AK4)^2)*(1+'Design Basis'!$C$6),0),ROUNDUP((ABS(AL4-AI4)+ABS(AM4-AJ4)+ABS(AO4-AK4)+ABS(AO4-AN4))*(1+'Design Basis'!$C$4)+2*'Design Basis'!$C$5,0))) -> 75 | P4: =ROUND(O4*'Design Basis'!$C$10,0) -> 246 | Q4: =O4*K4*AQ4 -> 225 | R4: =ROUND(Q4*'Design Basis'!$C$10,0) -> 738 | S4: 230000 | T4: 3 | U4: 175000 | V4: 1 | W4: =IF(OR(U4="",S4=""),"",IF(T4=3,U4*1000/(SQRT(3)*S4*V4),U4*1000/(S4*V4))) -> 439.28825 | X4: 1 | Y4: =IF(W4="","",W4*IF(X4="",1,X4)) -> 439.28825 | Z4: =IF(OR(AS4="",AP4=""),"",AS4*AP4) -> 900 | AA4: =IF(Z4="","",Z4*K4) -> 900 | AB4: =IF(OR(Y4="",AA4=""),"",Y4/AA4) -> 0.48809805 | AC4: =IF(OR(W4="",AT4=""),"",AT4*(W4/K4)*O4/1000/S4) | AD4: =IF(W4="","",IFERROR(IF(INDEX('Design Basis'!$C$13:$C$21,MATCH(C4,'Design Basis'!$A$13:$A$21,0))="","",INDEX('Design Basis'!$C$13:$C$21,MATCH(C4,'Design Basis'!$A$13:$A$21,0))),"")) | AE4: =IF(W4="","n/a",IF(AA4="","CHECK",IF(AND(AB4<=1,OR(AC4="",AD4="",AC4<=AD4)),"OK","CHECK"))) -> OK | AF4: =IF(AR4="","",K4*AQ4*PI()/4*AR4^2) -> 1860.4747 | AG4: Load in kVA | AI4: =INDEX(Equipment!$D$2:$D$153,MATCH(E4,Equipment!$A$2:$A$153,0)) -> 74 | AJ4: =INDEX(Equipment!$E$2:$E$153,MATCH(E4,Equipment!$A$2:$A$153,0)) -> 65.5 | AK4: =INDEX(Equipment!$F$2:$F$153,MATCH(E4,Equipment!$A$2:$A$153,0)) -> 10 | AL4: =INDEX(Equipment!$D$2:$D$153,MATCH(G4,Equipment!$A$2:$A$153,0)) -> 80 | AM4: =INDEX(Equipment!$E$2:$E$153,MATCH(G4,Equipment!$A$2:$A$153,0)) -> 137.5 | AN4: =INDEX(Equipment!$F$2:$F$153,MATCH(G4,Equipment!$A$2:$A$153,0)) -> 12.5 | AO4: =IF(INDEX(Raceways!$D$2:$D$18,MATCH(L4,Raceways!$A$2:$A$18,0))="",0,INDEX(Raceways!$D$2:$D$18,MATCH(L4,Raceways!$A$2:$A$18,0))) -> 0 | AP4: =IF(INDEX(Raceways!$I$2:$I$18,MATCH(L4,Raceways!$A$2:$A$18,0))="","",INDEX(Raceways!$I$2:$I$18,MATCH(L4,Raceways!$A$2:$A$18,0))) -> 1 | AQ4: =INDEX('Cable Types'!$D$2:$D$45,MATCH(I4,'Cable Types'!$A$2:$A$45,0)) -> 3 | AR4: =IF(INDEX('Cable Types'!$E$2:$E$45,MATCH(I4,'Cable Types'!$A$2:$A$45,0))="","",INDEX('Cable Types'!$E$2:$E$45,MATCH(I4,'Cable Types'!$A$2:$A$45,0))) -> 28.1 | AS4: =IF(INDEX('Cable Types'!$F$2:$F$45,MATCH(I4,'Cable Types'!$A$2:$A$45,0))="","",INDEX('Cable Types'!$F$2:$F$45,MATCH(I4,'Cable Types'!$A$2:$A$45,0))) -> 900 | AT4: =IF(INDEX('Cable Types'!$G$2:$G$45,MATCH(I4,'Cable Types'!$A$2:$A$45,0))="","",INDEX('Cable Types'!$G$2:$G$45,MATCH(I4,'Cable Types'!$A$2:$A$45,0)))
A5: 10-HV-003 | B5: 10 | C5: HV Overhead | D5: RICE transformer 230 kV to bay 1 (strung) | E5: RICE-TX-HV | F5: =INDEX(Equipment!$B$2:$B$153,MATCH(E5,Equipment!$A$2:$A$153,0)) -> RICE step-up transformer 13.8/230 kV 22 MVA - HV bushings | G5: SWY-B1 | H5: =INDEX(Equipment!$B$2:$B$153,MATCH(G5,Equipment!$A$2:$A$153,0)) -> 230 kV bay 1 - RICE transformer bay (gantry dead-end) | I5: ACSR-DRAKE | J5: =INDEX('Cable Types'!$B$2:$B$45,MATCH(I5,'Cable Types'!$A$2:$A$45,0)) -> ACSR 795 kcmil 'Drake' 26/7, 1 per phase | K5: 1 | L5: OHL | M5: D | O5: =IF(N5<>"",N5,IF(M5="D",ROUNDUP(SQRT((AL5-AI5)^2+(AM5-AJ5)^2+(AN5-AK5)^2)*(1+'Design Basis'!$C$6),0),ROUNDUP((ABS(AL5-AI5)+ABS(AM5-AJ5)+ABS(AO5-AK5)+ABS(AO5-AN5))*(1+'Design Basis'!$C$4)+2*'Design Basis'!$C$5,0))) -> 32 | P5: =ROUND(O5*'Design Basis'!$C$10,0) -> 105 | Q5: =O5*K5*AQ5 -> 96 | R5: =ROUND(Q5*'Design Basis'!$C$10,0) -> 315 | S5: 230000 | T5: 3 | U5: 22000 | V5: 1 | W5: =IF(OR(U5="",S5=""),"",IF(T5=3,U5*1000/(SQRT(3)*S5*V5),U5*1000/(S5*V5))) -> 55.224808 | X5: 1 | Y5: =IF(W5="","",W5*IF(X5="",1,X5)) -> 55.224808 | Z5: =IF(OR(AS5="",AP5=""),"",AS5*AP5) -> 900 | AA5: =IF(Z5="","",Z5*K5) -> 900 | AB5: =IF(OR(Y5="",AA5=""),"",Y5/AA5) -> 0.061360898 | AC5: =IF(OR(W5="",AT5=""),"",AT5*(W5/K5)*O5/1000/S5) | AD5: =IF(W5="","",IFERROR(IF(INDEX('Design Basis'!$C$13:$C$21,MATCH(C5,'Design Basis'!$A$13:$A$21,0))="","",INDEX('Design Basis'!$C$13:$C$21,MATCH(C5,'Design Basis'!$A$13:$A$21,0))),"")) | AE5: =IF(W5="","n/a",IF(AA5="","CHECK",IF(AND(AB5<=1,OR(AC5="",AD5="",AC5<=AD5)),"OK","CHECK"))) -> OK | AF5: =IF(AR5="","",K5*AQ5*PI()/4*AR5^2) -> 1860.4747 | AG5: Load in kVA | AI5: =INDEX(Equipment!$D$2:$D$153,MATCH(E5,Equipment!$A$2:$A$153,0)) -> 19 | AJ5: =INDEX(Equipment!$E$2:$E$153,MATCH(E5,Equipment!$A$2:$A$153,0)) -> 107.5 | AK5: =INDEX(Equipment!$F$2:$F$153,MATCH(E5,Equipment!$A$2:$A$153,0)) -> 8 | AL5: =INDEX(Equipment!$D$2:$D$153,MATCH(G5,Equipment!$A$2:$A$153,0)) -> 20 | AM5: =INDEX(Equipment!$E$2:$E$153,MATCH(G5,Equipment!$A$2:$A$153,0)) -> 137.5 | AN5: =INDEX(Equipment!$F$2:$F$153,MATCH(G5,Equipment!$A$2:$A$153,0)) -> 12.5 | AO5: =IF(INDEX(Raceways!$D$2:$D$18,MATCH(L5,Raceways!$A$2:$A$18,0))="",0,INDEX(Raceways!$D$2:$D$18,MATCH(L5,Raceways!$A$2:$A$18,0))) -> 0 | AP5: =IF(INDEX(Raceways!$I$2:$I$18,MATCH(L5,Raceways!$A$2:$A$18,0))="","",INDEX(Raceways!$I$2:$I$18,MATCH(L5,Raceways!$A$2:$A$18,0))) -> 1 | AQ5: =INDEX('Cable Types'!$D$2:$D$45,MATCH(I5,'Cable Types'!$A$2:$A$45,0)) -> 3 | AR5: =IF(INDEX('Cable Types'!$E$2:$E$45,MATCH(I5,'Cable Types'!$A$2:$A$45,0))="","",INDEX('Cable Types'!$E$2:$E$45,MATCH(I5,'Cable Types'!$A$2:$A$45,0))) -> 28.1 | AS5: =IF(INDEX('Cable Types'!$F$2:$F$45,MATCH(I5,'Cable Types'!$A$2:$A$45,0))="","",INDEX('Cable Types'!$F$2:$F$45,MATCH(I5,'Cable Types'!$A$2:$A$45,0))) -> 900 | AT5: =IF(INDEX('Cable Types'!$G$2:$G$45,MATCH(I5,'Cable Types'!$A$2:$A$45,0))="","",INDEX('Cable Types'!$G$2:$G$45,MATCH(I5,'Cable Types'!$A$2:$A$45,0)))
A6: 10-HV-004 | B6: 10 | C6: HV Overhead | D6: Strung main bus bay 1 - bay 2 | E6: SWY-B1 | F6: =INDEX(Equipment!$B$2:$B$153,MATCH(E6,Equipment!$A$2:$A$153,0)) -> 230 kV bay 1 - RICE transformer bay (gantry dead-end) | G6: SWY-B2 | H6: =INDEX(Equipment!$B$2:$B$153,MATCH(G6,Equipment!$A$2:$A$153,0)) -> 230 kV bay 2 - bus coupler (gantry dead-end) | I6: ACSR-DRAKE-2B | J6: =INDEX('Cable Types'!$B$2:$B$45,MATCH(I6,'Cable Types'!$A$2:$A$45,0)) -> ACSR 795 kcmil 'Drake' 26/7, twin bundle per phase | K6: 1 | L6: OHL | M6: D | O6: =IF(N6<>"",N6,IF(M6="D",ROUNDUP(SQRT((AL6-AI6)^2+(AM6-AJ6)^2+(AN6-AK6)^2)*(1+'Design Basis'!$C$6),0),ROUNDUP((ABS(AL6-AI6)+ABS(AM6-AJ6)+ABS(AO6-AK6)+ABS(AO6-AN6))*(1+'Design Basis'!$C$4)+2*'Design Basis'!$C$5,0))) -> 21 | P6: =ROUND(O6*'Design Basis'!$C$10,0) -> 69 | Q6: =O6*K6*AQ6 -> 126 | R6: =ROUND(Q6*'Design Basis'!$C$10,0) -> 413 | S6: 230000 | T6: 3 | U6: 487000 | V6: 1 | W6: =IF(OR(U6="",S6=""),"",IF(T6=3,U6*1000/(SQRT(3)*S6*V6),U6*1000/(S6*V6))) -> 1222.4764 | X6: 1 | Y6: =IF(W6="","",W6*IF(X6="",1,X6)) -> 1222.4764 | Z6: =IF(OR(AS6="",AP6=""),"",AS6*AP6) -> 1800 | AA6: =IF(Z6="","",Z6*K6) -> 1800 | AB6: =IF(OR(Y6="",AA6=""),"",Y6/AA6) -> 0.67915358 | AC6: =IF(OR(W6="",AT6=""),"",AT6*(W6/K6)*O6/1000/S6) | AD6: =IF(W6="","",IFERROR(IF(INDEX('Design Basis'!$C$13:$C$21,MATCH(C6,'Design Basis'!$A$13:$A$21,0))="","",INDEX('Design Basis'!$C$13:$C$21,MATCH(C6,'Design Basis'!$A$13:$A$21,0))),"")) | AE6: =IF(W6="","n/a",IF(AA6="","CHECK",IF(AND(AB6<=1,OR(AC6="",AD6="",AC6<=AD6)),"OK","CHECK"))) -> OK | AF6: =IF(AR6="","",K6*AQ6*PI()/4*AR6^2) -> 3720.9495 | AG6: Rated for total plant export | AI6: =INDEX(Equipment!$D$2:$D$153,MATCH(E6,Equipment!$A$2:$A$153,0)) -> 20 | AJ6: =INDEX(Equipment!$E$2:$E$153,MATCH(E6,Equipment!$A$2:$A$153,0)) -> 137.5 | AK6: =INDEX(Equipment!$F$2:$F$153,MATCH(E6,Equipment!$A$2:$A$153,0)) -> 12.5 | AL6: =INDEX(Equipment!$D$2:$D$153,MATCH(G6,Equipment!$A$2:$A$153,0)) -> 40 | AM6: =INDEX(Equipment!$E$2:$E$153,MATCH(G6,Equipment!$A$2:$A$153,0)) -> 137.5 | AN6: =INDEX(Equipment!$F$2:$F$153,MATCH(G6,Equipment!$A$2:$A$153,0)) -> 12.5 | AO6: =IF(INDEX(Raceways!$D$2:$D$18,MATCH(L6,Raceways!$A$2:$A$18,0))="",0,INDEX(Raceways!$D$2:$D$18,MATCH(L6,Raceways!$A$2:$A$18,0))) -> 0 | AP6: =IF(INDEX(Raceways!$I$2:$I$18,MATCH(L6,Raceways!$A$2:$A$18,0))="","",INDEX(Raceways!$I$2:$I$18,MATCH(L6,Raceways!$A$2:$A$18,0))) -> 1 | AQ6: =INDEX('Cable Types'!$D$2:$D$45,MATCH(I6,'Cable Types'!$A$2:$A$45,0)) -> 6 | AR6: =IF(INDEX('Cable Types'!$E$2:$E$45,MATCH(I6,'Cable Types'!$A$2:$A$45,0))="","",INDEX('Cable Types'!$E$2:$E$45,MATCH(I6,'Cable Types'!$A$2:$A$45,0))) -> 28.1 | AS6: =IF(INDEX('Cable Types'!$F$2:$F$45,MATCH(I6,'Cable Types'!$A$2:$A$45,0))="","",INDEX('Cable Types'!$F$2:$F$45,MATCH(I6,'Cable Types'!$A$2:$A$45,0))) -> 1800 | AT6: =IF(INDEX('Cable Types'!$G$2:$G$45,MATCH(I6,'Cable Types'!$A$2:$A$45,0))="","",INDEX('Cable Types'!$G$2:$G$45,MATCH(I6,'Cable Types'!$A$2:$A$45,0)))
A7: 10-HV-005 | B7: 10 | C7: HV Overhead | D7: Strung main bus bay 2 - bay 3 | E7: SWY-B2 | F7: =INDEX(Equipment!$B$2:$B$153,MATCH(E7,Equipment!$A$2:$A$153,0)) -> 230 kV bay 2 - bus coupler (gantry dead-end) | G7: SWY-B3 | H7: =INDEX(Equipment!$B$2:$B$153,MATCH(G7,Equipment!$A$2:$A$153,0)) -> 230 kV bay 3 - GT generator bay (gantry dead-end) | I7: ACSR-DRAKE-2B | J7: =INDEX('Cable Types'!$B$2:$B$45,MATCH(I7,'Cable Types'!$A$2:$A$45,0)) -> ACSR 795 kcmil 'Drake' 26/7, twin bundle per phase | K7: 1 | L7: OHL | M7: D | O7: =IF(N7<>"",N7,IF(M7="D",ROUNDUP(SQRT((AL7-AI7)^2+(AM7-AJ7)^2+(AN7-AK7)^2)*(1+'Design Basis'!$C$6),0),ROUNDUP((ABS(AL7-AI7)+ABS(AM7-AJ7)+ABS(AO7-AK7)+ABS(AO7-AN7))*(1+'Design Basis'!$C$4)+2*'Design Basis'!$C$5,0))) -> 21 | P7: =ROUND(O7*'Design Basis'!$C$10,0) -> 69 | Q7: =O7*K7*AQ7 -> 126 | R7: =ROUND(Q7*'Design Basis'!$C$10,0) -> 413 | S7: 230000 | T7: 3 | U7: 487000 | V7: 1 | W7: =IF(OR(U7="",S7=""),"",IF(T7=3,U7*1000/(SQRT(3)*S7*V7),U7*1000/(S7*V7))) -> 1222.4764 | X7: 1 | Y7: =IF(W7="","",W7*IF(X7="",1,X7)) -> 1222.4764 | Z7: =IF(OR(AS7="",AP7=""),"",AS7*AP7) -> 1800 | AA7: =IF(Z7="","",Z7*K7) -> 1800 | AB7: =IF(OR(Y7="",AA7=""),"",Y7/AA7) -> 0.67915358 | AC7: =IF(OR(W7="",AT7=""),"",AT7*(W7/K7)*O7/1000/S7) | AD7: =IF(W7="","",IFERROR(IF(INDEX('Design Basis'!$C$13:$C$21,MATCH(C7,'Design Basis'!$A$13:$A$21,0))="","",INDEX('Design Basis'!$C$13:$C$21,MATCH(C7,'Design Basis'!$A$13:$A$21,0))),"")) | AE7: =IF(W7="","n/a",IF(AA7="","CHECK",IF(AND(AB7<=1,OR(AC7="",AD7="",AC7<=AD7)),"OK","CHECK"))) -> OK | AF7: =IF(AR7="","",K7*AQ7*PI()/4*AR7^2) -> 3720.9495 | AI7: =INDEX(Equipment!$D$2:$D$153,MATCH(E7,Equipment!$A$2:$A$153,0)) -> 40 | AJ7: =INDEX(Equipment!$E$2:$E$153,MATCH(E7,Equipment!$A$2:$A$153,0)) -> 137.5 | AK7: =INDEX(Equipment!$F$2:$F$153,MATCH(E7,Equipment!$A$2:$A$153,0)) -> 12.5 | AL7: =INDEX(Equipment!$D$2:$D$153,MATCH(G7,Equipment!$A$2:$A$153,0)) -> 60 | AM7: =INDEX(Equipment!$E$2:$E$153,MATCH(G7,Equipment!$A$2:$A$153,0)) -> 137.5 | AN7: =INDEX(Equipment!$F$2:$F$153,MATCH(G7,Equipment!$A$2:$A$153,0)) -> 12.5 | AO7: =IF(INDEX(Raceways!$D$2:$D$18,MATCH(L7,Raceways!$A$2:$A$18,0))="",0,INDEX(Raceways!$D$2:$D$18,MATCH(L7,Raceways!$A$2:$A$18,0))) -> 0 | AP7: =IF(INDEX(Raceways!$I$2:$I$18,MATCH(L7,Raceways!$A$2:$A$18,0))="","",INDEX(Raceways!$I$2:$I$18,MATCH(L7,Raceways!$A$2:$A$18,0))) -> 1 | AQ7: =INDEX('Cable Types'!$D$2:$D$45,MATCH(I7,'Cable Types'!$A$2:$A$45,0)) -> 6 | AR7: =IF(INDEX('Cable Types'!$E$2:$E$45,MATCH(I7,'Cable Types'!$A$2:$A$45,0))="","",INDEX('Cable Types'!$E$2:$E$45,MATCH(I7,'Cable Types'!$A$2:$A$45,0))) -> 28.1 | AS7: =IF(INDEX('Cable Types'!$F$2:$F$45,MATCH(I7,'Cable Types'!$A$2:$A$45,0))="","",INDEX('Cable Types'!$F$2:$F$45,MATCH(I7,'Cable Types'!$A$2:$A$45,0))) -> 1800 | AT7: =IF(INDEX('Cable Types'!$G$2:$G$45,MATCH(I7,'Cable Types'!$A$2:$A$45,0))="","",INDEX('Cable Types'!$G$2:$G$45,MATCH(I7,'Cable Types'!$A$2:$A$45,0)))
A8: 10-HV-006 | B8: 10 | C8: HV Overhead | D8: Strung main bus bay 3 - bay 4 | E8: SWY-B3 | F8: =INDEX(Equipment!$B$2:$B$153,MATCH(E8,Equipment!$A$2:$A$153,0)) -> 230 kV bay 3 - GT generator bay (gantry dead-end) | G8: SWY-B4 | H8: =INDEX(Equipment!$B$2:$B$153,MATCH(G8,Equipment!$A$2:$A$153,0)) -> 230 kV bay 4 - ST generator bay / line exit (gantry dead-end) | I8: ACSR-DRAKE-2B | J8: =INDEX('Cable Types'!$B$2:$B$45,MATCH(I8,'Cable Types'!$A$2:$A$45,0)) -> ACSR 795 kcmil 'Drake' 26/7, twin bundle per phase | K8: 1 | L8: OHL | M8: D | O8: =IF(N8<>"",N8,IF(M8="D",ROUNDUP(SQRT((AL8-AI8)^2+(AM8-AJ8)^2+(AN8-AK8)^2)*(1+'Design Basis'!$C$6),0),ROUNDUP((ABS(AL8-AI8)+ABS(AM8-AJ8)+ABS(AO8-AK8)+ABS(AO8-AN8))*(1+'Design Basis'!$C$4)+2*'Design Basis'!$C$5,0))) -> 21 | P8: =ROUND(O8*'Design Basis'!$C$10,0) -> 69 | Q8: =O8*K8*AQ8 -> 126 | R8: =ROUND(Q8*'Design Basis'!$C$10,0) -> 413 | S8: 230000 | T8: 3 | U8: 487000 | V8: 1 | W8: =IF(OR(U8="",S8=""),"",IF(T8=3,U8*1000/(SQRT(3)*S8*V8),U8*1000/(S8*V8))) -> 1222.4764 | X8: 1 | Y8: =IF(W8="","",W8*IF(X8="",1,X8)) -> 1222.4764 | Z8: =IF(OR(AS8="",AP8=""),"",AS8*AP8) -> 1800 | AA8: =IF(Z8="","",Z8*K8) -> 1800 | AB8: =IF(OR(Y8="",AA8=""),"",Y8/AA8) -> 0.67915358 | AC8: =IF(OR(W8="",AT8=""),"",AT8*(W8/K8)*O8/1000/S8) | AD8: =IF(W8="","",IFERROR(IF(INDEX('Design Basis'!$C$13:$C$21,MATCH(C8,'Design Basis'!$A$13:$A$21,0))="","",INDEX('Design Basis'!$C$13:$C$21,MATCH(C8,'Design Basis'!$A$13:$A$21,0))),"")) | AE8: =IF(W8="","n/a",IF(AA8="","CHECK",IF(AND(AB8<=1,OR(AC8="",AD8="",AC8<=AD8)),"OK","CHECK"))) -> OK | AF8: =IF(AR8="","",K8*AQ8*PI()/4*AR8^2) -> 3720.9495 | AI8: =INDEX(Equipment!$D$2:$D$153,MATCH(E8,Equipment!$A$2:$A$153,0)) -> 60 | AJ8: =INDEX(Equipment!$E$2:$E$153,MATCH(E8,Equipment!$A$2:$A$153,0)) -> 137.5 | AK8: =INDEX(Equipment!$F$2:$F$153,MATCH(E8,Equipment!$A$2:$A$153,0)) -> 12.5 | AL8: =INDEX(Equipment!$D$2:$D$153,MATCH(G8,Equipment!$A$2:$A$153,0)) -> 80 | AM8: =INDEX(Equipment!$E$2:$E$153,MATCH(G8,Equipment!$A$2:$A$153,0)) -> 137.5 | AN8: =INDEX(Equipment!$F$2:$F$153,MATCH(G8,Equipment!$A$2:$A$153,0)) -> 12.5 | AO8: =IF(INDEX(Raceways!$D$2:$D$18,MATCH(L8,Raceways!$A$2:$A$18,0))="",0,INDEX(Raceways!$D$2:$D$18,MATCH(L8,Raceways!$A$2:$A$18,0))) -> 0 | AP8: =IF(INDEX(Raceways!$I$2:$I$18,MATCH(L8,Raceways!$A$2:$A$18,0))="","",INDEX(Raceways!$I$2:$I$18,MATCH(L8,Raceways!$A$2:$A$18,0))) -> 1 | AQ8: =INDEX('Cable Types'!$D$2:$D$45,MATCH(I8,'Cable Types'!$A$2:$A$45,0)) -> 6 | AR8: =IF(INDEX('Cable Types'!$E$2:$E$45,MATCH(I8,'Cable Types'!$A$2:$A$45,0))="","",INDEX('Cable Types'!$E$2:$E$45,MATCH(I8,'Cable Types'!$A$2:$A$45,0))) -> 28.1 | AS8: =IF(INDEX('Cable Types'!$F$2:$F$45,MATCH(I8,'Cable Types'!$A$2:$A$45,0))="","",INDEX('Cable Types'!$F$2:$F$45,MATCH(I8,'Cable Types'!$A$2:$A$45,0))) -> 1800 | AT8: =IF(INDEX('Cable Types'!$G$2:$G$45,MATCH(I8,'Cable Types'!$A$2:$A$45,0))="","",INDEX('Cable Types'!$G$2:$G$45,MATCH(I8,'Cable Types'!$A$2:$A$45,0)))
A9: 10-HV-007 | B9: 10 | C9: HV Overhead | D9: Outgoing 230 kV line: bay 4 to terminal tower T1 | E9: SWY-B4 | F9: =INDEX(Equipment!$B$2:$B$153,MATCH(E9,Equipment!$A$2:$A$153,0)) -> 230 kV bay 4 - ST generator bay / line exit (gantry dead-end) | G9: TWR-01 | H9: =INDEX(Equipment!$B$2:$B$153,MATCH(G9,Equipment!$A$2:$A$153,0)) -> 230 kV transmission tower 1 (terminal) | I9: ACSR-DRAKE-2B | J9: =INDEX('Cable Types'!$B$2:$B$45,MATCH(I9,'Cable Types'!$A$2:$A$45,0)) -> ACSR 795 kcmil 'Drake' 26/7, twin bundle per phase | K9: 1 | L9: OHL | M9: D | O9: =IF(N9<>"",N9,IF(M9="D",ROUNDUP(SQRT((AL9-AI9)^2+(AM9-AJ9)^2+(AN9-AK9)^2)*(1+'Design Basis'!$C$6),0),ROUNDUP((ABS(AL9-AI9)+ABS(AM9-AJ9)+ABS(AO9-AK9)+ABS(AO9-AN9))*(1+'Design Basis'!$C$4)+2*'Design Basis'!$C$5,0))) -> 56 | P9: =ROUND(O9*'Design Basis'!$C$10,0) -> 184 | Q9: =O9*K9*AQ9 -> 336 | R9: =ROUND(Q9*'Design Basis'!$C$10,0) -> 1102 | S9: 230000 | T9: 3 | U9: 487000 | V9: 1 | W9: =IF(OR(U9="",S9=""),"",IF(T9=3,U9*1000/(SQRT(3)*S9*V9),U9*1000/(S9*V9))) -> 1222.4764 | X9: 1 | Y9: =IF(W9="","",W9*IF(X9="",1,X9)) -> 1222.4764 | Z9: =IF(OR(AS9="",AP9=""),"",AS9*AP9) -> 1800 | AA9: =IF(Z9="","",Z9*K9) -> 1800 | AB9: =IF(OR(Y9="",AA9=""),"",Y9/AA9) -> 0.67915358 | AC9: =IF(OR(W9="",AT9=""),"",AT9*(W9/K9)*O9/1000/S9) | AD9: =IF(W9="","",IFERROR(IF(INDEX('Design Basis'!$C$13:$C$21,MATCH(C9,'Design Basis'!$A$13:$A$21,0))="","",INDEX('Design Basis'!$C$13:$C$21,MATCH(C9,'Design Basis'!$A$13:$A$21,0))),"")) | AE9: =IF(W9="","n/a",IF(AA9="","CHECK",IF(AND(AB9<=1,OR(AC9="",AD9="",AC9<=AD9)),"OK","CHECK"))) -> OK | AF9: =IF(AR9="","",K9*AQ9*PI()/4*AR9^2) -> 3720.9495 | AI9: =INDEX(Equipment!$D$2:$D$153,MATCH(E9,Equipment!$A$2:$A$153,0)) -> 80 | AJ9: =INDEX(Equipment!$E$2:$E$153,MATCH(E9,Equipment!$A$2:$A$153,0)) -> 137.5 | AK9: =INDEX(Equipment!$F$2:$F$153,MATCH(E9,Equipment!$A$2:$A$153,0)) -> 12.5 | AL9: =INDEX(Equipment!$D$2:$D$153,MATCH(G9,Equipment!$A$2:$A$153,0)) -> 130 | AM9: =INDEX(Equipment!$E$2:$E$153,MATCH(G9,Equipment!$A$2:$A$153,0)) -> 137.5 | AN9: =INDEX(Equipment!$F$2:$F$153,MATCH(G9,Equipment!$A$2:$A$153,0)) -> 31.5 | AO9: =IF(INDEX(Raceways!$D$2:$D$18,MATCH(L9,Raceways!$A$2:$A$18,0))="",0,INDEX(Raceways!$D$2:$D$18,MATCH(L9,Raceways!$A$2:$A$18,0))) -> 0 | AP9: =IF(INDEX(Raceways!$I$2:$I$18,MATCH(L9,Raceways!$A$2:$A$18,0))="","",INDEX(Raceways!$I$2:$I$18,MATCH(L9,Raceways!$A$2:$A$18,0))) -> 1 | AQ9: =INDEX('Cable Types'!$D$2:$D$45,MATCH(I9,'Cable Types'!$A$2:$A$45,0)) -> 6 | AR9: =IF(INDEX('Cable Types'!$E$2:$E$45,MATCH(I9,'Cable Types'!$A$2:$A$45,0))="","",INDEX('Cable Types'!$E$2:$E$45,MATCH(I9,'Cable Types'!$A$2:$A$45,0))) -> 28.1 | AS9: =IF(INDEX('Cable Types'!$F$2:$F$45,MATCH(I9,'Cable Types'!$A$2:$A$45,0))="","",INDEX('Cable Types'!$F$2:$F$45,MATCH(I9,'Cable Types'!$A$2:$A$45,0))) -> 1800 | AT9: =IF(INDEX('Cable Types'!$G$2:$G$45,MATCH(I9,'Cable Types'!$A$2:$A$45,0))="","",INDEX('Cable Types'!$G$2:$G$45,MATCH(I9,'Cable Types'!$A$2:$A$45,0)))
A10: 10-HV-008 | B10: 10 | C10: HV Overhead | D10: Outgoing 230 kV line span T1 - T2 | E10: TWR-01 | F10: =INDEX(Equipment!$B$2:$B$153,MATCH(E10,Equipment!$A$2:$A$153,0)) -> 230 kV transmission tower 1 (terminal) | G10: TWR-02 | H10: =INDEX(Equipment!$B$2:$B$153,MATCH(G10,Equipment!$A$2:$A$153,0)) -> 230 kV transmission tower 2 (suspension) | I10: ACSR-DRAKE-2B | J10: =INDEX('Cable Types'!$B$2:$B$45,MATCH(I10,'Cable Types'!$A$2:$A$45,0)) -> ACSR 795 kcmil 'Drake' 26/7, twin bundle per phase | K10: 1 | L10: OHL | M10: D | O10: =IF(N10<>"",N10,IF(M10="D",ROUNDUP(SQRT((AL10-AI10)^2+(AM10-AJ10)^2+(AN10-AK10)^2)*(1+'Design Basis'!$C$6),0),ROUNDUP((ABS(AL10-AI10)+ABS(AM10-AJ10)+ABS(AO10-AK10)+ABS(AO10-AN10))*(1+'Design Basis'!$C$4)+2*'Design Basis'!$C$5,0))) -> 74 | P10: =ROUND(O10*'Design Basis'!$C$10,0) -> 243 | Q10: =O10*K10*AQ10 -> 444 | R10: =ROUND(Q10*'Design Basis'!$C$10,0) -> 1457 | S10: 230000 | T10: 3 | U10: 487000 | V10: 1 | W10: =IF(OR(U10="",S10=""),"",IF(T10=3,U10*1000/(SQRT(3)*S10*V10),U10*1000/(S10*V10))) -> 1222.4764 | X10: 1 | Y10: =IF(W10="","",W10*IF(X10="",1,X10)) -> 1222.4764 | Z10: =IF(OR(AS10="",AP10=""),"",AS10*AP10) -> 1800 | AA10: =IF(Z10="","",Z10*K10) -> 1800 | AB10: =IF(OR(Y10="",AA10=""),"",Y10/AA10) -> 0.67915358 | AC10: =IF(OR(W10="",AT10=""),"",AT10*(W10/K10)*O10/1000/S10) | AD10: =IF(W10="","",IFERROR(IF(INDEX('Design Basis'!$C$13:$C$21,MATCH(C10,'Design Basis'!$A$13:$A$21,0))="","",INDEX('Design Basis'!$C$13:$C$21,MATCH(C10,'Design Basis'!$A$13:$A$21,0))),"")) | AE10: =IF(W10="","n/a",IF(AA10="","CHECK",IF(AND(AB10<=1,OR(AC10="",AD10="",AC10<=AD10)),"OK","CHECK"))) -> OK | AF10: =IF(AR10="","",K10*AQ10*PI()/4*AR10^2) -> 3720.9495 | AI10: =INDEX(Equipment!$D$2:$D$153,MATCH(E10,Equipment!$A$2:$A$153,0)) -> 130 | AJ10: =INDEX(Equipment!$E$2:$E$153,MATCH(E10,Equipment!$A$2:$A$153,0)) -> 137.5 | AK10: =INDEX(Equipment!$F$2:$F$153,MATCH(E10,Equipment!$A$2:$A$153,0)) -> 31.5 | AL10: =INDEX(Equipment!$D$2:$D$153,MATCH(G10,Equipment!$A$2:$A$153,0)) -> 200 | AM10: =INDEX(Equipment!$E$2:$E$153,MATCH(G10,Equipment!$A$2:$A$153,0)) -> 152.5 | AN10: =INDEX(Equipment!$F$2:$F$153,MATCH(G10,Equipment!$A$2:$A$153,0)) -> 31.5 | AO10: =IF(INDEX(Raceways!$D$2:$D$18,MATCH(L10,Raceways!$A$2:$A$18,0))="",0,INDEX(Raceways!$D$2:$D$18,MATCH(L10,Raceways!$A$2:$A$18,0))) -> 0 | AP10: =IF(INDEX(Raceways!$I$2:$I$18,MATCH(L10,Raceways!$A$2:$A$18,0))="","",INDEX(Raceways!$I$2:$I$18,MATCH(L10,Raceways!$A$2:$A$18,0))) -> 1 | AQ10: =INDEX('Cable Types'!$D$2:$D$45,MATCH(I10,'Cable Types'!$A$2:$A$45,0)) -> 6 | AR10: =IF(INDEX('Cable Types'!$E$2:$E$45,MATCH(I10,'Cable Types'!$A$2:$A$45,0))="","",INDEX('Cable Types'!$E$2:$E$45,MATCH(I10,'Cable Types'!$A$2:$A$45,0))) -> 28.1 | AS10: =IF(INDEX('Cable Types'!$F$2:$F$45,MATCH(I10,'Cable Types'!$A$2:$A$45,0))="","",INDEX('Cable Types'!$F$2:$F$45,MATCH(I10,'Cable Types'!$A$2:$A$45,0))) -> 1800 | AT10: =IF(INDEX('Cable Types'!$G$2:$G$45,MATCH(I10,'Cable Types'!$A$2:$A$45,0))="","",INDEX('Cable Types'!$G$2:$G$45,MATCH(I10,'Cable Types'!$A$2:$A$45,0)))
A11: 10-HV-009 | B11: 10 | C11: HV Overhead | D11: Outgoing 230 kV line span T2 - T3 | E11: TWR-02 | F11: =INDEX(Equipment!$B$2:$B$153,MATCH(E11,Equipment!$A$2:$A$153,0)) -> 230 kV transmission tower 2 (suspension) | G11: TWR-03 | H11: =INDEX(Equipment!$B$2:$B$153,MATCH(G11,Equipment!$A$2:$A$153,0)) -> 230 kV transmission tower 3 (suspension) | I11: ACSR-DRAKE-2B | J11: =INDEX('Cable Types'!$B$2:$B$45,MATCH(I11,'Cable Types'!$A$2:$A$45,0)) -> ACSR 795 kcmil 'Drake' 26/7, twin bundle per phase | K11: 1 | L11: OHL | M11: D | O11: =IF(N11<>"",N11,IF(M11="D",ROUNDUP(SQRT((AL11-AI11)^2+(AM11-AJ11)^2+(AN11-AK11)^2)*(1+'Design Basis'!$C$6),0),ROUNDUP((ABS(AL11-AI11)+ABS(AM11-AJ11)+ABS(AO11-AK11)+ABS(AO11-AN11))*(1+'Design Basis'!$C$4)+2*'Design Basis'!$C$5,0))) -> 74 | P11: =ROUND(O11*'Design Basis'!$C$10,0) -> 243 | Q11: =O11*K11*AQ11 -> 444 | R11: =ROUND(Q11*'Design Basis'!$C$10,0) -> 1457 | S11: 230000 | T11: 3 | U11: 487000 | V11: 1 | W11: =IF(OR(U11="",S11=""),"",IF(T11=3,U11*1000/(SQRT(3)*S11*V11),U11*1000/(S11*V11))) -> 1222.4764 | X11: 1 | Y11: =IF(W11="","",W11*IF(X11="",1,X11)) -> 1222.4764 | Z11: =IF(OR(AS11="",AP11=""),"",AS11*AP11) -> 1800 | AA11: =IF(Z11="","",Z11*K11) -> 1800 | AB11: =IF(OR(Y11="",AA11=""),"",Y11/AA11) -> 0.67915358 | AC11: =IF(OR(W11="",AT11=""),"",AT11*(W11/K11)*O11/1000/S11) | AD11: =IF(W11="","",IFERROR(IF(INDEX('Design Basis'!$C$13:$C$21,MATCH(C11,'Design Basis'!$A$13:$A$21,0))="","",INDEX('Design Basis'!$C$13:$C$21,MATCH(C11,'Design Basis'!$A$13:$A$21,0))),"")) | AE11: =IF(W11="","n/a",IF(AA11="","CHECK",IF(AND(AB11<=1,OR(AC11="",AD11="",AC11<=AD11)),"OK","CHECK"))) -> OK | AF11: =IF(AR11="","",K11*AQ11*PI()/4*AR11^2) -> 3720.9495 | AI11: =INDEX(Equipment!$D$2:$D$153,MATCH(E11,Equipment!$A$2:$A$153,0)) -> 200 | AJ11: =INDEX(Equipment!$E$2:$E$153,MATCH(E11,Equipment!$A$2:$A$153,0)) -> 152.5 | AK11: =INDEX(Equipment!$F$2:$F$153,MATCH(E11,Equipment!$A$2:$A$153,0)) -> 31.5 | AL11: =INDEX(Equipment!$D$2:$D$153,MATCH(G11,Equipment!$A$2:$A$153,0)) -> 270 | AM11: =INDEX(Equipment!$E$2:$E$153,MATCH(G11,Equipment!$A$2:$A$153,0)) -> 167.5 | AN11: =INDEX(Equipment!$F$2:$F$153,MATCH(G11,Equipment!$A$2:$A$153,0)) -> 31.5 | AO11: =IF(INDEX(Raceways!$D$2:$D$18,MATCH(L11,Raceways!$A$2:$A$18,0))="",0,INDEX(Raceways!$D$2:$D$18,MATCH(L11,Raceways!$A$2:$A$18,0))) -> 0 | AP11: =IF(INDEX(Raceways!$I$2:$I$18,MATCH(L11,Raceways!$A$2:$A$18,0))="","",INDEX(Raceways!$I$2:$I$18,MATCH(L11,Raceways!$A$2:$A$18,0))) -> 1 | AQ11: =INDEX('Cable Types'!$D$2:$D$45,MATCH(I11,'Cable Types'!$A$2:$A$45,0)) -> 6 | AR11: =IF(INDEX('Cable Types'!$E$2:$E$45,MATCH(I11,'Cable Types'!$A$2:$A$45,0))="","",INDEX('Cable Types'!$E$2:$E$45,MATCH(I11,'Cable Types'!$A$2:$A$45,0))) -> 28.1 | AS11: =IF(INDEX('Cable Types'!$F$2:$F$45,MATCH(I11,'Cable Types'!$A$2:$A$45,0))="","",INDEX('Cable Types'!$F$2:$F$45,MATCH(I11,'Cable Types'!$A$2:$A$45,0))) -> 1800 | AT11: =IF(INDEX('Cable Types'!$G$2:$G$45,MATCH(I11,'Cable Types'!$A$2:$A$45,0))="","",INDEX('Cable Types'!$G$2:$G$45,MATCH(I11,'Cable Types'!$A$2:$A$45,0)))
A12: 10-HV-010 | B12: 10 | C12: HV Overhead | D12: Switchyard shield wires (2 off) bay 1 - bay 4 | E12: SWY-B1 | F12: =INDEX(Equipment!$B$2:$B$153,MATCH(E12,Equipment!$A$2:$A$153,0)) -> 230 kV bay 1 - RICE transformer bay (gantry dead-end) | G12: SWY-B4 | H12: =INDEX(Equipment!$B$2:$B$153,MATCH(G12,Equipment!$A$2:$A$153,0)) -> 230 kV bay 4 - ST generator bay / line exit (gantry dead-end) | I12: SW-7/16-EHS | J12: =INDEX('Cable Types'!$B$2:$B$45,MATCH(I12,'Cable Types'!$A$2:$A$45,0)) -> Shield wire 7/16" EHS galvanized steel | K12: 2 | L12: OHL | M12: D | O12: =IF(N12<>"",N12,IF(M12="D",ROUNDUP(SQRT((AL12-AI12)^2+(AM12-AJ12)^2+(AN12-AK12)^2)*(1+'Design Basis'!$C$6),0),ROUNDUP((ABS(AL12-AI12)+ABS(AM12-AJ12)+ABS(AO12-AK12)+ABS(AO12-AN12))*(1+'Design Basis'!$C$4)+2*'Design Basis'!$C$5,0))) -> 62 | P12: =ROUND(O12*'Design Basis'!$C$10,0) -> 203 | Q12: =O12*K12*AQ12 -> 124 | R12: =ROUND(Q12*'Design Basis'!$C$10,0) -> 407 | W12: =IF(OR(U12="",S12=""),"",IF(T12=3,U12*1000/(SQRT(3)*S12*V12),U12*1000/(S12*V12))) | Y12: =IF(W12="","",W12*IF(X12="",1,X12)) | Z12: =IF(OR(AS12="",AP12=""),"",AS12*AP12) | AA12: =IF(Z12="","",Z12*K12) | AB12: =IF(OR(Y12="",AA12=""),"",Y12/AA12) | AC12: =IF(OR(W12="",AT12=""),"",AT12*(W12/K12)*O12/1000/S12) | AD12: =IF(W12="","",IFERROR(IF(INDEX('Design Basis'!$C$13:$C$21,MATCH(C12,'Design Basis'!$A$13:$A$21,0))="","",INDEX('Design Basis'!$C$13:$C$21,MATCH(C12,'Design Basis'!$A$13:$A$21,0))),"")) | AE12: =IF(W12="","n/a",IF(AA12="","CHECK",IF(AND(AB12<=1,OR(AC12="",AD12="",AC12<=AD12)),"OK","CHECK"))) -> n/a | AF12: =IF(AR12="","",K12*AQ12*PI()/4*AR12^2) -> 193.53782 | AG12: Lightning shielding over gantries | AI12: =INDEX(Equipment!$D$2:$D$153,MATCH(E12,Equipment!$A$2:$A$153,0)) -> 20 | AJ12: =INDEX(Equipment!$E$2:$E$153,MATCH(E12,Equipment!$A$2:$A$153,0)) -> 137.5 | AK12: =INDEX(Equipment!$F$2:$F$153,MATCH(E12,Equipment!$A$2:$A$153,0)) -> 12.5 | AL12: =INDEX(Equipment!$D$2:$D$153,MATCH(G12,Equipment!$A$2:$A$153,0)) -> 80 | AM12: =INDEX(Equipment!$E$2:$E$153,MATCH(G12,Equipment!$A$2:$A$153,0)) -> 137.5 | AN12: =INDEX(Equipment!$F$2:$F$153,MATCH(G12,Equipment!$A$2:$A$153,0)) -> 12.5 | AO12: =IF(INDEX(Raceways!$D$2:$D$18,MATCH(L12,Raceways!$A$2:$A$18,0))="",0,INDEX(Raceways!$D$2:$D$18,MATCH(L12,Raceways!$A$2:$A$18,0))) -> 0 | AP12: =IF(INDEX(Raceways!$I$2:$I$18,MATCH(L12,Raceways!$A$2:$A$18,0))="","",INDEX(Raceways!$I$2:$I$18,MATCH(L12,Raceways!$A$2:$A$18,0))) -> 1 | AQ12: =INDEX('Cable Types'!$D$2:$D$45,MATCH(I12,'Cable Types'!$A$2:$A$45,0)) -> 1 | AR12: =IF(INDEX('Cable Types'!$E$2:$E$45,MATCH(I12,'Cable Types'!$A$2:$A$45,0))="","",INDEX('Cable Types'!$E$2:$E$45,MATCH(I12,'Cable Types'!$A$2:$A$45,0))) -> 11.1 | AS12: =IF(INDEX('Cable Types'!$F$2:$F$45,MATCH(I12,'Cable Types'!$A$2:$A$45,0))="","",INDEX('Cable Types'!$F$2:$F$45,MATCH(I12,'Cable Types'!$A$2:$A$45,0))) | AT12: =IF(INDEX('Cable Types'!$G$2:$G$45,MATCH(I12,'Cable Types'!$A$2:$A$45,0))="","",INDEX('Cable Types'!$G$2:$G$45,MATCH(I12,'Cable Types'!$A$2:$A$45,0)))
A13: 10-HV-011 | B13: 10 | C13: HV Overhead | D13: Line OPGW: bay 4 to T3 (teleprotection / SCADA) | E13: SWY-B4 | F13: =INDEX(Equipment!$B$2:$B$153,MATCH(E13,Equipment!$A$2:$A$153,0)) -> 230 kV bay 4 - ST generator bay / line exit (gantry dead-end) | G13: TWR-03 | H13: =INDEX(Equipment!$B$2:$B$153,MATCH(G13,Equipment!$A$2:$A$153,0)) -> 230 kV transmission tower 3 (suspension) | I13: OPGW-24 | J13: =INDEX('Cable Types'!$B$2:$B$45,MATCH(I13,'Cable Types'!$A$2:$A$45,0)) -> OPGW 24-fiber shield wire | K13: 1 | L13: OHL | M13: D | O13: =IF(N13<>"",N13,IF(M13="D",ROUNDUP(SQRT((AL13-AI13)^2+(AM13-AJ13)^2+(AN13-AK13)^2)*(1+'Design Basis'!$C$6),0),ROUNDUP((ABS(AL13-AI13)+ABS(AM13-AJ13)+ABS(AO13-AK13)+ABS(AO13-AN13))*(1+'Design Basis'!$C$4)+2*'Design Basis'!$C$5,0))) -> 200 | P13: =ROUND(O13*'Design Basis'!$C$10,0) -> 656 | Q13: =O13*K13*AQ13 -> 200 | R13: =ROUND(Q13*'Design Basis'!$C$10,0) -> 656 | W13: =IF(OR(U13="",S13=""),"",IF(T13=3,U13*1000/(SQRT(3)*S13*V13),U13*1000/(S13*V13))) | Y13: =IF(W13="","",W13*IF(X13="",1,X13)) | Z13: =IF(OR(AS13="",AP13=""),"",AS13*AP13) | AA13: =IF(Z13="","",Z13*K13) | AB13: =IF(OR(Y13="",AA13=""),"",Y13/AA13) | AC13: =IF(OR(W13="",AT13=""),"",AT13*(W13/K13)*O13/1000/S13) | AD13: =IF(W13="","",IFERROR(IF(INDEX('Design Basis'!$C$13:$C$21,MATCH(C13,'Design Basis'!$A$13:$A$21,0))="","",INDEX('Design Basis'!$C$13:$C$21,MATCH(C13,'Design Basis'!$A$13:$A$21,0))),"")) | AE13: =IF(W13="","n/a",IF(AA13="","CHECK",IF(AND(AB13<=1,OR(AC13="",AD13="",AC13<=AD13)),"OK","CHECK"))) -> n/a | AF13: =IF(AR13="","",K13*AQ13*PI()/4*AR13^2) -> 153.93804 | AG13: Chord length bay 4 -> T3; refine per tower spotting | AI13: =INDEX(Equipment!$D$2:$D$153,MATCH(E13,Equipment!$A$2:$A$153,0)) -> 80 | AJ13: =INDEX(Equipment!$E$2:$E$153,MATCH(E13,Equipment!$A$2:$A$153,0)) -> 137.5 | AK13: =INDEX(Equipment!$F$2:$F$153,MATCH(E13,Equipment!$A$2:$A$153,0)) -> 12.5 | AL13: =INDEX(Equipment!$D$2:$D$153,MATCH(G13,Equipment!$A$2:$A$153,0)) -> 270 | AM13: =INDEX(Equipment!$E$2:$E$153,MATCH(G13,Equipment!$A$2:$A$153,0)) -> 167.5 | AN13: =INDEX(Equipment!$F$2:$F$153,MATCH(G13,Equipment!$A$2:$A$153,0)) -> 31.5 | AO13: =IF(INDEX(Raceways!$D$2:$D$18,MATCH(L13,Raceways!$A$2:$A$18,0))="",0,INDEX(Raceways!$D$2:$D$18,MATCH(L13,Raceways!$A$2:$A$18,0))) -> 0 | AP13: =IF(INDEX(Raceways!$I$2:$I$18,MATCH(L13,Raceways!$A$2:$A$18,0))="","",INDEX(Raceways!$I$2:$I$18,MATCH(L13,Raceways!$A$2:$A$18,0))) -> 1 | AQ13: =INDEX('Cable Types'!$D$2:$D$45,MATCH(I13,'Cable Types'!$A$2:$A$45,0)) -> 1 | AR13: =IF(INDEX('Cable Types'!$E$2:$E$45,MATCH(I13,'Cable Types'!$A$2:$A$45,0))="","",INDEX('Cable Types'!$E$2:$E$45,MATCH(I13,'Cable Types'!$A$2:$A$45,0))) -> 14 | AS13: =IF(INDEX('Cable Types'!$F$2:$F$45,MATCH(I13,'Cable Types'!$A$2:$A$45,0))="","",INDEX('Cable Types'!$F$2:$F$45,MATCH(I13,'Cable Types'!$A$2:$A$45,0))) | AT13: =IF(INDEX('Cable Types'!$G$2:$G$45,MATCH(I13,'Cable Types'!$A$2:$A$45,0))="","",INDEX('Cable Types'!$G$2:$G$45,MATCH(I13,'Cable Types'!$A$2:$A$45,0)))
A14: 20-IPB-001 | B14: 20 | C14: Busduct | D14: GT generator main IPB to GSU-GT LV | E14: GEN-GT | F14: =INDEX(Equipment!$B$2:$B$153,MATCH(E14,Equipment!$A$2:$A$153,0)) -> Gas turbine generator ~290 MVA, 19 kV - line terminals | G14: GSU-GT-LV | H14: =INDEX(Equipment!$B$2:$B$153,MATCH(G14,Equipment!$A$2:$A$153,0)) -> GT step-up transformer - LV bushings / marshalling box | I14: IPB-10K | J14: =INDEX('Cable Types'!$B$2:$B$45,MATCH(I14,'Cable Types'!$A$2:$A$45,0)) -> Isolated phase bus 24 kV, 10 kA (per phase metre) | K14: 1 | L14: IPB-GT | M14: M | O14: =IF(N14<>"",N14,IF(M14="D",ROUNDUP(SQRT((AL14-AI14)^2+(AM14-AJ14)^2+(AN14-AK14)^2)*(1+'Design Basis'!$C$6),0),ROUNDUP((ABS(AL14-AI14)+ABS(AM14-AJ14)+ABS(AO14-AK14)+ABS(AO14-AN14))*(1+'Design Basis'!$C$4)+2*'Design Basis'!$C$5,0))) -> 58 | P14: =ROUND(O14*'Design Basis'!$C$10,0) -> 190 | Q14: =O14*K14*AQ14 -> 174 | R14: =ROUND(Q14*'Design Basis'!$C$10,0) -> 571 | S14: 19000 | T14: 3 | U14: 290000 | V14: 1 | W14: =IF(OR(U14="",S14=""),"",IF(T14=3,U14*1000/(SQRT(3)*S14*V14),U14*1000/(S14*V14))) -> 8812.1883 | X14: 1 | Y14: =IF(W14="","",W14*IF(X14="",1,X14)) -> 8812.1883 | Z14: =IF(OR(AS14="",AP14=""),"",AS14*AP14) -> 10000 | AA14: =IF(Z14="","",Z14*K14) -> 10000 | AB14: =IF(OR(Y14="",AA14=""),"",Y14/AA14) -> 0.88121883 | AC14: =IF(OR(W14="",AT14=""),"",AT14*(W14/K14)*O14/1000/S14) | AD14: =IF(W14="","",IFERROR(IF(INDEX('Design Basis'!$C$13:$C$21,MATCH(C14,'Design Basis'!$A$13:$A$21,0))="","",INDEX('Design Basis'!$C$13:$C$21,MATCH(C14,'Design Basis'!$A$13:$A$21,0))),"")) | AE14: =IF(W14="","n/a",IF(AA14="","CHECK",IF(AND(AB14<=1,OR(AC14="",AD14="",AC14<=AD14)),"OK","CHECK"))) -> OK | AF14: =IF(AR14="","",K14*AQ14*PI()/4*AR14^2) | AG14: Includes GCB if fitted | AI14: =INDEX(Equipment!$D$2:$D$153,MATCH(E14,Equipment!$A$2:$A$153,0)) -> 58 | AJ14: =INDEX(Equipment!$E$2:$E$153,MATCH(E14,Equipment!$A$2:$A$153,0)) -> 18 | AK14: =INDEX(Equipment!$F$2:$F$153,MATCH(E14,Equipment!$A$2:$A$153,0)) -> 4 | AL14: =INDEX(Equipment!$D$2:$D$153,MATCH(G14,Equipment!$A$2:$A$153,0)) -> 54 | AM14: =INDEX(Equipment!$E$2:$E$153,MATCH(G14,Equipment!$A$2:$A$153,0)) -> 60 | AN14: =INDEX(Equipment!$F$2:$F$153,MATCH(G14,Equipment!$A$2:$A$153,0)) -> 4.5 | AO14: =IF(INDEX(Raceways!$D$2:$D$18,MATCH(L14,Raceways!$A$2:$A$18,0))="",0,INDEX(Raceways!$D$2:$D$18,MATCH(L14,Raceways!$A$2:$A$18,0))) -> 4 | AP14: =IF(INDEX(Raceways!$I$2:$I$18,MATCH(L14,Raceways!$A$2:$A$18,0))="","",INDEX(Raceways!$I$2:$I$18,MATCH(L14,Raceways!$A$2:$A$18,0))) -> 1 | AQ14: =INDEX('Cable Types'!$D$2:$D$45,MATCH(I14,'Cable Types'!$A$2:$A$45,0)) -> 3 | AR14: =IF(INDEX('Cable Types'!$E$2:$E$45,MATCH(I14,'Cable Types'!$A$2:$A$45,0))="","",INDEX('Cable Types'!$E$2:$E$45,MATCH(I14,'Cable Types'!$A$2:$A$45,0))) | AS14: =IF(INDEX('Cable Types'!$F$2:$F$45,MATCH(I14,'Cable Types'!$A$2:$A$45,0))="","",INDEX('Cable Types'!$F$2:$F$45,MATCH(I14,'Cable Types'!$A$2:$A$45,0))) -> 10000 | AT14: =IF(INDEX('Cable Types'!$G$2:$G$45,MATCH(I14,'Cable Types'!$A$2:$A$45,0))="","",INDEX('Cable Types'!$G$2:$G$45,MATCH(I14,'Cable Types'!$A$2:$A$45,0)))
A15: 20-IPB-002 | B15: 20 | C15: Busduct | D15: GT IPB tap to UAT-1 | E15: GEN-GT | F15: =INDEX(Equipment!$B$2:$B$153,MATCH(E15,Equipment!$A$2:$A$153,0)) -> Gas turbine generator ~290 MVA, 19 kV - line terminals | G15: UAT-1 | H15: =INDEX(Equipment!$B$2:$B$153,MATCH(G15,Equipment!$A$2:$A$153,0)) -> Unit auxiliary transformer 1, 19/13.8 kV 45 MVA | I15: IPB-3K | J15: =INDEX('Cable Types'!$B$2:$B$45,MATCH(I15,'Cable Types'!$A$2:$A$45,0)) -> Isolated phase tap bus 24 kV, 3 kA (per phase metre) | K15: 1 | L15: IPB-GT | M15: M | O15: =IF(N15<>"",N15,IF(M15="D",ROUNDUP(SQRT((AL15-AI15)^2+(AM15-AJ15)^2+(AN15-AK15)^2)*(1+'Design Basis'!$C$6),0),ROUNDUP((ABS(AL15-AI15)+ABS(AM15-AJ15)+ABS(AO15-AK15)+ABS(AO15-AN15))*(1+'Design Basis'!$C$4)+2*'Design Basis'!$C$5,0))) -> 74 | P15: =ROUND(O15*'Design Basis'!$C$10,0) -> 243 | Q15: =O15*K15*AQ15 -> 222 | R15: =ROUND(Q15*'Design Basis'!$C$10,0) -> 728 | S15: 19000 | T15: 3 | U15: 45000 | V15: 1 | W15: =IF(OR(U15="",S15=""),"",IF(T15=3,U15*1000/(SQRT(3)*S15*V15),U15*1000/(S15*V15))) -> 1367.4085 | X15: 1 | Y15: =IF(W15="","",W15*IF(X15="",1,X15)) -> 1367.4085 | Z15: =IF(OR(AS15="",AP15=""),"",AS15*AP15) -> 3000 | AA15: =IF(Z15="","",Z15*K15) -> 3000 | AB15: =IF(OR(Y15="",AA15=""),"",Y15/AA15) -> 0.45580284 | AC15: =IF(OR(W15="",AT15=""),"",AT15*(W15/K15)*O15/1000/S15) | AD15: =IF(W15="","",IFERROR(IF(INDEX('Design Basis'!$C$13:$C$21,MATCH(C15,'Design Basis'!$A$13:$A$21,0))="","",INDEX('Design Basis'!$C$13:$C$21,MATCH(C15,'Design Basis'!$A$13:$A$21,0))),"")) | AE15: =IF(W15="","n/a",IF(AA15="","CHECK",IF(AND(AB15<=1,OR(AC15="",AD15="",AC15<=AD15)),"OK","CHECK"))) -> OK | AF15: =IF(AR15="","",K15*AQ15*PI()/4*AR15^2) | AI15: =INDEX(Equipment!$D$2:$D$153,MATCH(E15,Equipment!$A$2:$A$153,0)) -> 58 | AJ15: =INDEX(Equipment!$E$2:$E$153,MATCH(E15,Equipment!$A$2:$A$153,0)) -> 18 | AK15: =INDEX(Equipment!$F$2:$F$153,MATCH(E15,Equipment!$A$2:$A$153,0)) -> 4 | AL15: =INDEX(Equipment!$D$2:$D$153,MATCH(G15,Equipment!$A$2:$A$153,0)) -> 44 | AM15: =INDEX(Equipment!$E$2:$E$153,MATCH(G15,Equipment!$A$2:$A$153,0)) -> 64 | AN15: =INDEX(Equipment!$F$2:$F$153,MATCH(G15,Equipment!$A$2:$A$153,0)) -> 3 | AO15: =IF(INDEX(Raceways!$D$2:$D$18,MATCH(L15,Raceways!$A$2:$A$18,0))="",0,INDEX(Raceways!$D$2:$D$18,MATCH(L15,Raceways!$A$2:$A$18,0))) -> 4 | AP15: =IF(INDEX(Raceways!$I$2:$I$18,MATCH(L15,Raceways!$A$2:$A$18,0))="","",INDEX(Raceways!$I$2:$I$18,MATCH(L15,Raceways!$A$2:$A$18,0))) -> 1 | AQ15: =INDEX('Cable Types'!$D$2:$D$45,MATCH(I15,'Cable Types'!$A$2:$A$45,0)) -> 3 | AR15: =IF(INDEX('Cable Types'!$E$2:$E$45,MATCH(I15,'Cable Types'!$A$2:$A$45,0))="","",INDEX('Cable Types'!$E$2:$E$45,MATCH(I15,'Cable Types'!$A$2:$A$45,0))) | AS15: =IF(INDEX('Cable Types'!$F$2:$F$45,MATCH(I15,'Cable Types'!$A$2:$A$45,0))="","",INDEX('Cable Types'!$F$2:$F$45,MATCH(I15,'Cable Types'!$A$2:$A$45,0))) -> 3000 | AT15: =IF(INDEX('Cable Types'!$G$2:$G$45,MATCH(I15,'Cable Types'!$A$2:$A$45,0))="","",INDEX('Cable Types'!$G$2:$G$45,MATCH(I15,'Cable Types'!$A$2:$A$45,0)))
A16: 20-IPB-003 | B16: 20 | C16: Busduct | D16: ST generator main IPB to GSU-ST LV | E16: GEN-ST | F16: =INDEX(Equipment!$B$2:$B$153,MATCH(E16,Equipment!$A$2:$A$153,0)) -> Steam turbine generator ~175 MVA, 18 kV - line terminals | G16: GSU-ST-LV | H16: =INDEX(Equipment!$B$2:$B$153,MATCH(G16,Equipment!$A$2:$A$153,0)) -> ST step-up transformer - LV bushings / marshalling box | I16: IPB-7K | J16: =INDEX('Cable Types'!$B$2:$B$45,MATCH(I16,'Cable Types'!$A$2:$A$45,0)) -> Isolated phase bus 24 kV, 7 kA (per phase metre) | K16: 1 | L16: IPB-ST | M16: M | O16: =IF(N16<>"",N16,IF(M16="D",ROUNDUP(SQRT((AL16-AI16)^2+(AM16-AJ16)^2+(AN16-AK16)^2)*(1+'Design Basis'!$C$6),0),ROUNDUP((ABS(AL16-AI16)+ABS(AM16-AJ16)+ABS(AO16-AK16)+ABS(AO16-AN16))*(1+'Design Basis'!$C$4)+2*'Design Basis'!$C$5,0))) -> 40 | P16: =ROUND(O16*'Design Basis'!$C$10,0) -> 131 | Q16: =O16*K16*AQ16 -> 120 | R16: =ROUND(Q16*'Design Basis'!$C$10,0) -> 394 | S16: 18000 | T16: 3 | U16: 175000 | V16: 1 | W16: =IF(OR(U16="",S16=""),"",IF(T16=3,U16*1000/(SQRT(3)*S16*V16),U16*1000/(S16*V16))) -> 5613.1276 | X16: 1 | Y16: =IF(W16="","",W16*IF(X16="",1,X16)) -> 5613.1276 | Z16: =IF(OR(AS16="",AP16=""),"",AS16*AP16) -> 7000 | AA16: =IF(Z16="","",Z16*K16) -> 7000 | AB16: =IF(OR(Y16="",AA16=""),"",Y16/AA16) -> 0.80187537 | AC16: =IF(OR(W16="",AT16=""),"",AT16*(W16/K16)*O16/1000/S16) | AD16: =IF(W16="","",IFERROR(IF(INDEX('Design Basis'!$C$13:$C$21,MATCH(C16,'Design Basis'!$A$13:$A$21,0))="","",INDEX('Design Basis'!$C$13:$C$21,MATCH(C16,'Design Basis'!$A$13:$A$21,0))),"")) | AE16: =IF(W16="","n/a",IF(AA16="","CHECK",IF(AND(AB16<=1,OR(AC16="",AD16="",AC16<=AD16)),"OK","CHECK"))) -> OK | AF16: =IF(AR16="","",K16*AQ16*PI()/4*AR16^2) | AI16: =INDEX(Equipment!$D$2:$D$153,MATCH(E16,Equipment!$A$2:$A$153,0)) -> 60 | AJ16: =INDEX(Equipment!$E$2:$E$153,MATCH(E16,Equipment!$A$2:$A$153,0)) -> 46 | AK16: =INDEX(Equipment!$F$2:$F$153,MATCH(E16,Equipment!$A$2:$A$153,0)) -> 6 | AL16: =INDEX(Equipment!$D$2:$D$153,MATCH(G16,Equipment!$A$2:$A$153,0)) -> 74 | AM16: =INDEX(Equipment!$E$2:$E$153,MATCH(G16,Equipment!$A$2:$A$153,0)) -> 60 | AN16: =INDEX(Equipment!$F$2:$F$153,MATCH(G16,Equipment!$A$2:$A$153,0)) -> 4.5 | AO16: =IF(INDEX(Raceways!$D$2:$D$18,MATCH(L16,Raceways!$A$2:$A$18,0))="",0,INDEX(Raceways!$D$2:$D$18,MATCH(L16,Raceways!$A$2:$A$18,0))) -> 4 | AP16: =IF(INDEX(Raceways!$I$2:$I$18,MATCH(L16,Raceways!$A$2:$A$18,0))="","",INDEX(Raceways!$I$2:$I$18,MATCH(L16,Raceways!$A$2:$A$18,0))) -> 1 | AQ16: =INDEX('Cable Types'!$D$2:$D$45,MATCH(I16,'Cable Types'!$A$2:$A$45,0)) -> 3 | AR16: =IF(INDEX('Cable Types'!$E$2:$E$45,MATCH(I16,'Cable Types'!$A$2:$A$45,0))="","",INDEX('Cable Types'!$E$2:$E$45,MATCH(I16,'Cable Types'!$A$2:$A$45,0))) | AS16: =IF(INDEX('Cable Types'!$F$2:$F$45,MATCH(I16,'Cable Types'!$A$2:$A$45,0))="","",INDEX('Cable Types'!$F$2:$F$45,MATCH(I16,'Cable Types'!$A$2:$A$45,0))) -> 7000 | AT16: =IF(INDEX('Cable Types'!$G$2:$G$45,MATCH(I16,'Cable Types'!$A$2:$A$45,0))="","",INDEX('Cable Types'!$G$2:$G$45,MATCH(I16,'Cable Types'!$A$2:$A$45,0)))
